<?xml version='1.0' encoding='utf-8'?>
<mujoco model="smplx_mapped_s29">
  <compiler coordinate="local" />
  <default>
    <joint damping="0.0" armature="0.01" stiffness="0.0" limited="true" />
    <geom conaffinity="1" condim="3" contype="7" margin="0.001" rgba="0.8 0.6 .4 1" />
  </default>
  <asset>
    <texture type="skybox" builtin="gradient" rgb1=".4 .5 .6" rgb2="0 0 0" width="100" height="100" />
    <texture builtin="flat" height="1278" mark="cross" markrgb="1 1 1" name="texgeom" random="0.01" rgb1="0.8 0.6 0.4" rgb2="0.8 0.6 0.4" type="cube" width="127" />
    <texture builtin="checker" height="100" name="texplane" rgb1="0 0 0" rgb2="0.8 0.8 0.8" type="2d" width="100" />
    <material name="MatPlane" reflectance="0.5" shininess="1" specular="1" texrepeat="60 60" texture="texplane" />
    <material name="geom" texture="texgeom" texuniform="true" />
  </asset>
  <worldbody>
    <light cutoff="100" diffuse="1 1 1" dir="-0 0 -1.3" directional="true" exponent="1" pos="0 0 1.3" specular=".1 .1 .1" />
    <geom conaffinity="1" condim="3" name="floor" pos="0 0 0" rgba="0.8 0.9 0.8 1" size="100 100 .2" type="plane" material="MatPlane" />
    <body name="Pelvis" pos="0.0010 -0.3891 0.0087">
      <freejoint name="Pelvis" />
      <geom type="sphere" contype="1" conaffinity="1" density="4629.6296296296305" size="0.09" pos="0.0000 0.0000 0.0000" name="Pelvis" />
      <body name="L_Hip" pos="0.0557 -0.0997 -0.0278">
        <joint name="L_Hip_x" type="hinge" pos="0 0 0" axis="1 0 0" stiffness="800" damping="80" armature="0.02" range="-180.00 180.00" />
        <joint name="L_Hip_y" type="hinge" pos="0 0 0" axis="0 1 0" stiffness="800" damping="80" armature="0.02" range="-180.00 180.00" />
        <joint name="L_Hip_z" type="hinge" pos="0 0 0" axis="0 0 1" stiffness="800" damping="80" armature="0.02" range="-180.00 180.00" />
        <geom type="capsule" contype="1" conaffinity="1" density="2040.816327" fromto="0.0138 -0.0760 -0.0005 0.0552 -0.3040 -0.0019" size="0.059" />
        <body name="L_Knee" pos="0.0691 -0.3799 -0.0024">
          <joint name="L_Knee_x" type="hinge" pos="0 0 0" axis="1 0 0" stiffness="800" damping="80" armature="0.02" range="-180.00 180.00" />
          <joint name="L_Knee_y" type="hinge" pos="0 0 0" axis="0 1 0" stiffness="800" damping="80" armature="0.02" range="-180.00 180.00" />
          <joint name="L_Knee_z" type="hinge" pos="0 0 0" axis="0 0 1" stiffness="800" damping="80" armature="0.02" range="-180.00 180.00" />
          <geom type="capsule" contype="1" conaffinity="1" density="1234.567901" fromto="-0.0095 -0.0774 -0.0084 -0.0382 -0.3098 -0.0334" size="0.0564" />
          <body name="L_Ankle" pos="-0.0477 -0.3872 -0.0418">
            <joint name="L_Ankle_x" type="hinge" pos="0 0 0" axis="1 0 0" stiffness="800" damping="80" armature="0.02" range="-180.00 180.00" />
            <joint name="L_Ankle_y" type="hinge" pos="0 0 0" axis="0 1 0" stiffness="800" damping="80" armature="0.02" range="-180.00 180.00" />
            <joint name="L_Ankle_z" type="hinge" pos="0 0 0" axis="0 0 1" stiffness="800" damping="80" armature="0.02" range="-180.00 180.00" />
            <geom type="box" contype="1" conaffinity="1" density="1000" pos="0.0115 -0.0234 0.0566" size="0.0502 0.0216 0.0909" quat="1.0000 0.0000 0.0000 0.0000" />
            <body name="L_Toe" pos="0.0443 -0.0546 0.1327">
              <joint name="L_Toe_x" type="hinge" pos="0 0 0" axis="1 0 0" stiffness="500" damping="50" armature="0.02" range="-180.00 180.00" />
              <joint name="L_Toe_y" type="hinge" pos="0 0 0" axis="0 1 0" stiffness="500" damping="50" armature="0.02" range="-180.00 180.00" />
              <joint name="L_Toe_z" type="hinge" pos="0 0 0" axis="0 0 1" stiffness="500" damping="50" armature="0.02" range="-180.00 180.00" />
              <geom type="box" contype="1" conaffinity="1" density="1000" pos="-0.0115 0.0227 0.0576" size="0.0493 0.0209 0.0194" quat="1.0000 0.0000 0.0000 0.0000" />
            </body>
          </body>
        </body>
      </body>
      <body name="R_Hip" pos="-0.0572 -0.1105 -0.0211">
        <joint name="R_Hip_x" type="hinge" pos="0 0 0" axis="1 0 0" stiffness="800" damping="80" armature="0.02" range="-180.00 180.00" />
        <joint name="R_Hip_y" type="hinge" pos="0 0 0" axis="0 1 0" stiffness="800" damping="80" armature="0.02" range="-180.00 180.00" />
        <joint name="R_Hip_z" type="hinge" pos="0 0 0" axis="0 0 1" stiffness="800" damping="80" armature="0.02" range="-180.00 180.00" />
        <geom type="capsule" contype="1" conaffinity="1" density="2040.816327" fromto="-0.0105 -0.0727 -0.0020 -0.0421 -0.2908 -0.0082" size="0.0588" />
        <body name="R_Knee" pos="-0.0526 -0.3635 -0.0102">
          <joint name="R_Knee_x" type="hinge" pos="0 0 0" axis="1 0 0" stiffness="800" damping="80" armature="0.02" range="-180.00 180.00" />
          <joint name="R_Knee_y" type="hinge" pos="0 0 0" axis="0 1 0" stiffness="800" damping="80" armature="0.02" range="-180.00 180.00" />
          <joint name="R_Knee_z" type="hinge" pos="0 0 0" axis="0 0 1" stiffness="800" damping="80" armature="0.02" range="-180.00 180.00" />
          <geom type="capsule" contype="1" conaffinity="1" density="1234.567901" fromto="0.0038 -0.0799 -0.0081 0.0153 -0.3197 -0.0322" size="0.0564" />
          <body name="R_Ankle" pos="0.0192 -0.3997 -0.0403">
            <joint name="R_Ankle_x" type="hinge" pos="0 0 0" axis="1 0 0" stiffness="800" damping="80" armature="0.02" range="-180.00 180.00" />
            <joint name="R_Ankle_y" type="hinge" pos="0 0 0" axis="0 1 0" stiffness="800" damping="80" armature="0.02" range="-180.00 180.00" />
            <joint name="R_Ankle_z" type="hinge" pos="0 0 0" axis="0 0 1" stiffness="800" damping="80" armature="0.02" range="-180.00 180.00" />
            <geom type="box" contype="1" conaffinity="1" density="1000" pos="-0.0091 -0.0250 0.0535" size="0.0502 0.0216 0.0909" quat="1.0000 0.0000 0.0000 0.0000" />
            <body name="R_Toe" pos="-0.0351 -0.0542 0.1391">
              <joint name="R_Toe_x" type="hinge" pos="0 0 0" axis="1 0 0" stiffness="500" damping="50" armature="0.02" range="-180.00 180.00" />
              <joint name="R_Toe_y" type="hinge" pos="0 0 0" axis="0 1 0" stiffness="500" damping="50" armature="0.02" range="-180.00 180.00" />
              <joint name="R_Toe_z" type="hinge" pos="0 0 0" axis="0 0 1" stiffness="500" damping="50" armature="0.02" range="-180.00 180.00" />
              <geom type="box" contype="1" conaffinity="1" density="1000" pos="0.0091 0.0243 0.0545" size="0.0493 0.0209 0.0194" quat="1.0000 0.0000 0.0000 0.0000" />
            </body>
          </body>
        </body>
      </body>
      <body name="Torso" pos="-0.0019 0.1184 -0.0357">
        <joint name="Torso_x" type="hinge" pos="0 0 0" axis="1 0 0" stiffness="1000" damping="100" armature="0.02" range="-180.00 180.00" />
        <joint name="Torso_y" type="hinge" pos="0 0 0" axis="0 1 0" stiffness="1000" damping="100" armature="0.02" range="-180.00 180.00" />
        <joint name="Torso_z" type="hinge" pos="0 0 0" axis="0 0 1" stiffness="1000" damping="100" armature="0.02" range="-180.00 180.00" />
        <geom type="capsule" contype="1" conaffinity="1" density="1100" fromto="0.0038 0.0735 0.0024 0.0046 0.0899 0.0030" size="0.08" />
        <body name="Spine" pos="0.0084 0.1634 0.0054">
          <joint name="Spine_x" type="hinge" pos="0 0 0" axis="1 0 0" stiffness="1000" damping="100" armature="0.02" range="-180.00 180.00" />
          <joint name="Spine_y" type="hinge" pos="0 0 0" axis="0 1 0" stiffness="1000" damping="100" armature="0.02" range="-180.00 180.00" />
          <joint name="Spine_z" type="hinge" pos="0 0 0" axis="0 0 1" stiffness="1000" damping="100" armature="0.02" range="-180.00 180.00" />
          <geom type="capsule" contype="1" conaffinity="1" density="1100" fromto="-0.0032 0.0284 0.0093 -0.0039 0.0347 0.0114" size="0.06" />
          <body name="Chest" pos="-0.0071 0.0630 0.0207">
            <joint name="Chest_x" type="hinge" pos="0 0 0" axis="1 0 0" stiffness="1000" damping="100" armature="0.02" range="-180.00 180.00" />
            <joint name="Chest_y" type="hinge" pos="0 0 0" axis="0 1 0" stiffness="1000" damping="100" armature="0.02" range="-180.00 180.00" />
            <joint name="Chest_z" type="hinge" pos="0 0 0" axis="0 0 1" stiffness="1000" damping="100" armature="0.02" range="-180.00 180.00" />
            <geom type="capsule" contype="1" conaffinity="1" density="1100" fromto="-0.0007 0.0211 -0.0012 -0.0028 0.0844 -0.0049" size="0.08" />
            <body name="Neck" pos="-0.0084 0.1633 -0.0161">
              <joint name="Neck_x" type="hinge" pos="0 0 0" axis="1 0 0" stiffness="500" damping="50" armature="0.02" range="-180.00 180.00" />
              <joint name="Neck_y" type="hinge" pos="0 0 0" axis="0 1 0" stiffness="500" damping="50" armature="0.02" range="-180.00 180.00" />
              <joint name="Neck_z" type="hinge" pos="0 0 0" axis="0 0 1" stiffness="500" damping="50" armature="0.02" range="-180.00 180.00" />
              <geom type="capsule" contype="1" conaffinity="1" density="1000" fromto="0.0102 0.0732 0.0075 0.0124 0.0895 0.0091" size="0.0437" />
              <body name="Head" pos="0.0226 0.1627 0.0166">
                <joint name="Head_x" type="hinge" pos="0 0 0" axis="1 0 0" stiffness="500" damping="50" armature="0.02" range="-180.00 180.00" />
                <joint name="Head_y" type="hinge" pos="0 0 0" axis="0 1 0" stiffness="500" damping="50" armature="0.02" range="-180.00 180.00" />
                <joint name="Head_z" type="hinge" pos="0 0 0" axis="0 0 1" stiffness="500" damping="50" armature="0.02" range="-180.00 180.00" />
                <geom type="sphere" contype="1" conaffinity="1" density="1000" size="0.1054" pos="0.0000 0.0000 0.0000" name="Head" />
              </body>
            </body>
            <body name="L_Thorax" pos="0.0398 0.0763 0.0009">
              <joint name="L_Thorax_x" type="hinge" pos="0 0 0" axis="1 0 0" stiffness="500" damping="50" armature="0.02" range="-180.00 180.00" />
              <joint name="L_Thorax_y" type="hinge" pos="0 0 0" axis="0 1 0" stiffness="500" damping="50" armature="0.02" range="-180.00 180.00" />
              <joint name="L_Thorax_z" type="hinge" pos="0 0 0" axis="0 0 1" stiffness="500" damping="50" armature="0.02" range="-180.00 180.00" />
              <geom type="capsule" contype="1" conaffinity="1" density="1000" fromto="0.0264 0.0123 -0.0041 0.1056 0.0493 -0.0163" size="0.0564" />
              <body name="L_Shoulder" pos="0.1320 0.0616 -0.0204">
                <joint name="L_Shoulder_x" type="hinge" pos="0 0 0" axis="1 0 0" stiffness="500" damping="50" armature="0.02" range="-180.00 180.00" />
                <joint name="L_Shoulder_y" type="hinge" pos="0 0 0" axis="0 1 0" stiffness="500" damping="50" armature="0.02" range="-180.00 180.00" />
                <joint name="L_Shoulder_z" type="hinge" pos="0 0 0" axis="0 0 1" stiffness="500" damping="50" armature="0.02" range="-180.00 180.00" />
                <geom type="capsule" contype="1" conaffinity="1" density="1000" fromto="0.0493 -0.0153 -0.0086 0.1974 -0.0611 -0.0343" size="0.0533" />
                <body name="L_Elbow" pos="0.2467 -0.0763 -0.0429">
                  <joint name="L_Elbow_x" type="hinge" pos="0 0 0" axis="1 0 0" stiffness="500" damping="50" armature="0.02" range="-180.00 180.00" />
                  <joint name="L_Elbow_y" type="hinge" pos="0 0 0" axis="0 1 0" stiffness="500" damping="50" armature="0.02" range="-180.00 180.00" />
                  <joint name="L_Elbow_z" type="hinge" pos="0 0 0" axis="0 0 1" stiffness="500" damping="50" armature="0.02" range="-180.00 180.00" />
                  <geom type="capsule" contype="1" conaffinity="1" density="1000" fromto="0.0530 0.0049 -0.0003 0.2121 0.0195 -0.0010" size="0.0418" />
                  <body name="L_Wrist" pos="0.2651 0.0244 -0.0013">
                    <joint name="L_Wrist_x" type="hinge" pos="0 0 0" axis="1 0 0" stiffness="300" damping="30" armature="0.02" range="-180.0000 180.0000" />
                    <joint name="L_Wrist_y" type="hinge" pos="0 0 0" axis="0 1 0" stiffness="300" damping="30" armature="0.02" range="-180.0000 180.0000" />
                    <joint name="L_Wrist_z" type="hinge" pos="0 0 0" axis="0 0 1" stiffness="300" damping="30" armature="0.02" range="-180.0000 180.0000" />
                    <geom type="box" contype="1" conaffinity="1" density="1000" pos="0.0456 -0.0084 -0.0022" size="0.0444 0.0076 0.0414" quat="1.0000 0.0000 0.0000 0.0000" />
                    <body name="L_Index1" pos="0.1034 -0.0099 0.0196">
                      <joint name="L_Index1_x" type="hinge" pos="0 0 0" axis="1 0 0" stiffness="100" damping="10" armature="0.02" range="-5.6250 5.6250" />
                      <joint name="L_Index1_y" type="hinge" pos="0 0 0" axis="0 1 0" stiffness="100" damping="10" armature="0.02" range="-5.6250 5.6250" />
                      <joint name="L_Index1_z" type="hinge" pos="0 0 0" axis="0 0 1" stiffness="100" damping="10" armature="0.02" range="-55.6250 55.6250" />
                      <geom type="capsule" contype="1" conaffinity="1" density="1000" fromto="0.0065 0.0003 0.0006 0.0261 0.0012 0.0023" size="0.0065" />
                      <body name="L_Index2" pos="0.0326 0.0015 0.0029">
                        <joint name="L_Index2_x" type="hinge" pos="0 0 0" axis="1 0 0" stiffness="100" damping="10" armature="0.02" range="-5.6250 5.6250" />
                        <joint name="L_Index2_y" type="hinge" pos="0 0 0" axis="0 1 0" stiffness="100" damping="10" armature="0.02" range="-5.6250 5.6250" />
                        <joint name="L_Index2_z" type="hinge" pos="0 0 0" axis="0 0 1" stiffness="100" damping="10" armature="0.02" range="-55.6250 55.6250" />
                        <geom type="capsule" contype="1" conaffinity="1" density="1000" fromto="0.0046 -0.0006 -0.0001 0.0184 -0.0023 -0.0006" size="0.0053" />
                        <body name="L_Index3" pos="0.0230 -0.0028 -0.0007">
                          <joint name="L_Index3_x" type="hinge" pos="0 0 0" axis="1 0 0" stiffness="100" damping="10" armature="0.02" range="-5.6250 5.6250" />
                          <joint name="L_Index3_y" type="hinge" pos="0 0 0" axis="0 1 0" stiffness="100" damping="10" armature="0.02" range="-5.6250 5.6250" />
                          <joint name="L_Index3_z" type="hinge" pos="0 0 0" axis="0 0 1" stiffness="100" damping="10" armature="0.02" range="-90.0000 5.6250" />
                          <geom type="capsule" contype="1" conaffinity="1" density="1000" fromto="0.0051 -0.0006 -0.0002 0.0178 -0.0022 -0.0006" size="0.0047" />
                        </body>
                      </body>
                    </body>
                    <body name="L_Middle1" pos="0.1113 -0.0069 -0.0039">
                      <joint name="L_Middle1_x" type="hinge" pos="0 0 0" axis="1 0 0" stiffness="100" damping="10" armature="0.02" range="-5.6250 5.6250" />
                      <joint name="L_Middle1_y" type="hinge" pos="0 0 0" axis="0 1 0" stiffness="100" damping="10" armature="0.02" range="-5.6250 5.6250" />
                      <joint name="L_Middle1_z" type="hinge" pos="0 0 0" axis="0 0 1" stiffness="100" damping="10" armature="0.02" range="-55.6250 55.6250" />
                      <geom type="capsule" contype="1" conaffinity="1" density="1000" fromto="0.0062 0.0001 -0.0008 0.0248 0.0003 -0.0033" size="0.0067" />
                      <body name="L_Middle2" pos="0.0310 0.0004 -0.0041">
                        <joint name="L_Middle2_x" type="hinge" pos="0 0 0" axis="1 0 0" stiffness="100" damping="10" armature="0.02" range="-5.6250 5.6250" />
                        <joint name="L_Middle2_y" type="hinge" pos="0 0 0" axis="0 1 0" stiffness="100" damping="10" armature="0.02" range="-5.6250 5.6250" />
                        <joint name="L_Middle2_z" type="hinge" pos="0 0 0" axis="0 0 1" stiffness="100" damping="10" armature="0.02" range="-55.6250 55.6250" />
                        <geom type="capsule" contype="1" conaffinity="1" density="1000" fromto="0.0047 -0.0005 -0.0008 0.0190 -0.0019 -0.0034" size="0.0050" />
                        <body name="L_Middle3" pos="0.0237 -0.0024 -0.0042">
                          <joint name="L_Middle3_x" type="hinge" pos="0 0 0" axis="1 0 0" stiffness="100" damping="10" armature="0.02" range="-5.6250 5.6250" />
                          <joint name="L_Middle3_y" type="hinge" pos="0 0 0" axis="0 1 0" stiffness="100" damping="10" armature="0.02" range="-5.6250 5.6250" />
                          <joint name="L_Middle3_z" type="hinge" pos="0 0 0" axis="0 0 1" stiffness="100" damping="10" armature="0.02" range="-90.0000 5.6250" />
                          <geom type="capsule" contype="1" conaffinity="1" density="1000" fromto="0.0052 -0.0005 -0.0009 0.0185 -0.0019 -0.0033" size="0.0045" />
                        </body>
                      </body>
                    </body>
                    <body name="L_Pinky1" pos="0.0863 -0.0150 -0.0442">
                      <joint name="L_Pinky1_x" type="hinge" pos="0 0 0" axis="1 0 0" stiffness="100" damping="10" armature="0.02" range="-5.6250 5.6250" />
                      <joint name="L_Pinky1_y" type="hinge" pos="0 0 0" axis="0 1 0" stiffness="100" damping="10" armature="0.02" range="-5.6250 5.6250" />
                      <joint name="L_Pinky1_z" type="hinge" pos="0 0 0" axis="0 0 1" stiffness="100" damping="10" armature="0.02" range="-55.6250 55.6250" />
                      <geom type="capsule" contype="1" conaffinity="1" density="1000" fromto="0.0034 -0.0003 -0.0022 0.0135 -0.0014 -0.0089" size="0.0050" />
                      <body name="L_Pinky2" pos="0.0168 -0.0017 -0.0111">
                        <joint name="L_Pinky2_x" type="hinge" pos="0 0 0" axis="1 0 0" stiffness="100" damping="10" armature="0.02" range="-5.6250 5.6250" />
                        <joint name="L_Pinky2_y" type="hinge" pos="0 0 0" axis="0 1 0" stiffness="100" damping="10" armature="0.02" range="-5.6250 5.6250" />
                        <joint name="L_Pinky2_z" type="hinge" pos="0 0 0" axis="0 0 1" stiffness="100" damping="10" armature="0.02" range="-55.6250 55.6250" />
                        <geom type="capsule" contype="1" conaffinity="1" density="1000" fromto="0.0033 -0.0004 -0.0021 0.0132 -0.0016 -0.0084" size="0.0045" />
                        <body name="L_Pinky3" pos="0.0165 -0.0020 -0.0105">
                          <joint name="L_Pinky3_x" type="hinge" pos="0 0 0" axis="1 0 0" stiffness="100" damping="10" armature="0.02" range="-5.6250 5.6250" />
                          <joint name="L_Pinky3_y" type="hinge" pos="0 0 0" axis="0 1 0" stiffness="100" damping="10" armature="0.02" range="-5.6250 5.6250" />
                          <joint name="L_Pinky3_z" type="hinge" pos="0 0 0" axis="0 0 1" stiffness="100" damping="10" armature="0.02" range="-90.0000 5.6250" />
                          <geom type="capsule" contype="1" conaffinity="1" density="1000" fromto="0.0037 -0.0004 -0.0024 0.0127 -0.0015 -0.0081" size="0.0036" />
                        </body>
                      </body>
                    </body>
                    <body name="L_Ring1" pos="0.0995 -0.0095 -0.0274">
                      <joint name="L_Ring1_x" type="hinge" pos="0 0 0" axis="1 0 0" stiffness="100" damping="10" armature="0.02" range="-5.6250 5.6250" />
                      <joint name="L_Ring1_y" type="hinge" pos="0 0 0" axis="0 1 0" stiffness="100" damping="10" armature="0.02" range="-5.6250 5.6250" />
                      <joint name="L_Ring1_z" type="hinge" pos="0 0 0" axis="0 0 1" stiffness="100" damping="10" armature="0.02" range="-55.6250 55.6250" />
                      <geom type="capsule" contype="1" conaffinity="1" density="1000" fromto="0.0058 0.0002 -0.0009 0.0231 0.0007 -0.0038" size="0.0057" />
                      <body name="L_Ring2" pos="0.0289 0.0008 -0.0047">
                        <joint name="L_Ring2_x" type="hinge" pos="0 0 0" axis="1 0 0" stiffness="100" damping="10" armature="0.02" range="-5.6250 5.6250" />
                        <joint name="L_Ring2_y" type="hinge" pos="0 0 0" axis="0 1 0" stiffness="100" damping="10" armature="0.02" range="-5.6250 5.6250" />
                        <joint name="L_Ring2_z" type="hinge" pos="0 0 0" axis="0 0 1" stiffness="100" damping="10" armature="0.02" range="-55.6250 55.6250" />
                        <geom type="capsule" contype="1" conaffinity="1" density="1000" fromto="0.0047 -0.0004 -0.0013 0.0187 -0.0016 -0.0052" size="0.0051" />
                        <body name="L_Ring3" pos="0.0234 -0.0020 -0.0065">
                          <joint name="L_Ring3_x" type="hinge" pos="0 0 0" axis="1 0 0" stiffness="100" damping="10" armature="0.02" range="-5.6250 5.6250" />
                          <joint name="L_Ring3_y" type="hinge" pos="0 0 0" axis="0 1 0" stiffness="100" damping="10" armature="0.02" range="-5.6250 5.6250" />
                          <joint name="L_Ring3_z" type="hinge" pos="0 0 0" axis="0 0 1" stiffness="100" damping="10" armature="0.02" range="-90.0000 5.6250" />
                          <geom type="capsule" contype="1" conaffinity="1" density="1000" fromto="0.0052 -0.0005 -0.0015 0.0181 -0.0016 -0.0051" size="0.0043" />
                        </body>
                      </body>
                    </body>
                    <body name="L_Thumb1" pos="0.0412 -0.0206 0.0258">
                      <joint name="L_Thumb1_x" type="hinge" pos="0 0 0" axis="1 0 0" stiffness="100" damping="10" armature="0.02" range="-55.6250 55.6250" />
                      <joint name="L_Thumb1_y" type="hinge" pos="0 0 0" axis="0 1 0" stiffness="100" damping="10" armature="0.02" range="-55.6250 55.6250" />
                      <joint name="L_Thumb1_z" type="hinge" pos="0 0 0" axis="0 0 1" stiffness="100" damping="10" armature="0.02" range="-55.6250 55.6250" />
                      <geom type="capsule" contype="1" conaffinity="1" density="1000" fromto="0.0035 0.0004 0.0052 0.0140 0.0015 0.0207" size="0.0086" />
                      <body name="L_Thumb2" pos="0.0175 0.0018 0.0259">
                        <joint name="L_Thumb2_x" type="hinge" pos="0 0 0" axis="1 0 0" stiffness="100" damping="10" armature="0.02" range="-5.6250 5.6250" />
                        <joint name="L_Thumb2_y" type="hinge" pos="0 0 0" axis="0 1 0" stiffness="100" damping="10" armature="0.02" range="-5.6250 5.6250" />
                        <joint name="L_Thumb2_z" type="hinge" pos="0 0 0" axis="0 0 1" stiffness="100" damping="10" armature="0.02" range="-5.6250 5.6250" />
                        <geom type="capsule" contype="1" conaffinity="1" density="1000" fromto="0.0043 -0.0009 0.0032 0.0170 -0.0035 0.0128" size="0.0065" />
                        <body name="L_Thumb3" pos="0.0213 -0.0043 0.0161">
                          <joint name="L_Thumb3_x" type="hinge" pos="0 0 0" axis="1 0 0" stiffness="100" damping="10" armature="0.02" range="-5.6250 5.6250" />
                          <joint name="L_Thumb3_y" type="hinge" pos="0 0 0" axis="0 1 0" stiffness="100" damping="10" armature="0.02" range="-5.6250 5.6250" />
                          <joint name="L_Thumb3_z" type="hinge" pos="0 0 0" axis="0 0 1" stiffness="100" damping="10" armature="0.02" range="-90.0000 5.6250" />
                          <geom type="capsule" contype="1" conaffinity="1" density="1000" fromto="0.0041 -0.0008 0.0031 0.0172 -0.0035 0.0130" size="0.0062" />
                        </body>
                      </body>
                    </body>
                  </body>
                </body>
              </body>
            </body>
            <body name="R_Thorax" pos="-0.0420 0.0768 -0.0031">
              <joint name="R_Thorax_x" type="hinge" pos="0 0 0" axis="1 0 0" stiffness="500" damping="50" armature="0.02" range="-180.00 180.00" />
              <joint name="R_Thorax_y" type="hinge" pos="0 0 0" axis="0 1 0" stiffness="500" damping="50" armature="0.02" range="-180.00 180.00" />
              <joint name="R_Thorax_z" type="hinge" pos="0 0 0" axis="0 0 1" stiffness="500" damping="50" armature="0.02" range="-180.00 180.00" />
              <geom type="capsule" contype="1" conaffinity="1" density="1000" fromto="-0.0246 0.0120 -0.0031 -0.0986 0.0480 -0.0122" size="0.0576" />
              <body name="R_Shoulder" pos="-0.1232 0.0600 -0.0153">
                <joint name="R_Shoulder_x" type="hinge" pos="0 0 0" axis="1 0 0" stiffness="500" damping="50" armature="0.02" range="-180.00 180.00" />
                <joint name="R_Shoulder_y" type="hinge" pos="0 0 0" axis="0 1 0" stiffness="500" damping="50" armature="0.02" range="-180.00 180.00" />
                <joint name="R_Shoulder_z" type="hinge" pos="0 0 0" axis="0 0 1" stiffness="500" damping="50" armature="0.02" range="-180.00 180.00" />
                <geom type="capsule" contype="1" conaffinity="1" density="1000" fromto="-0.0525 -0.0095 -0.0065 -0.2099 -0.0379 -0.0261" size="0.0538" />
                <body name="R_Elbow" pos="-0.2623 -0.0474 -0.0327">
                  <joint name="R_Elbow_x" type="hinge" pos="0 0 0" axis="1 0 0" stiffness="500" damping="50" armature="0.02" range="-180.00 180.00" />
                  <joint name="R_Elbow_y" type="hinge" pos="0 0 0" axis="0 1 0" stiffness="500" damping="50" armature="0.02" range="-180.00 180.00" />
                  <joint name="R_Elbow_z" type="hinge" pos="0 0 0" axis="0 0 1" stiffness="500" damping="50" armature="0.02" range="-180.00 180.00" />
                  <geom type="capsule" contype="1" conaffinity="1" density="1000" fromto="-0.0514 0.0000 -0.0024 -0.2058 0.0001 -0.0095" size="0.042" />
                  <body name="R_Wrist" pos="-0.2572 0.0001 -0.0119">
                    <joint name="R_Wrist_x" type="hinge" pos="0 0 0" axis="1 0 0" stiffness="300" damping="30" armature="0.02" range="-180.0000 180.0000" />
                    <joint name="R_Wrist_y" type="hinge" pos="0 0 0" axis="0 1 0" stiffness="300" damping="30" armature="0.02" range="-180.0000 180.0000" />
                    <joint name="R_Wrist_z" type="hinge" pos="0 0 0" axis="0 0 1" stiffness="300" damping="30" armature="0.02" range="-180.0000 180.0000" />
                    <geom type="box" contype="1" conaffinity="1" density="1000" pos="-0.0449 -0.0080 -0.0014" size="0.0416 0.0078 0.0414" quat="1.0000 0.0000 0.0000 0.0000" />
                    <body name="R_Index1" pos="-0.1030 -0.0134 0.0187">
                      <joint name="R_Index1_x" type="hinge" pos="0 0 0" axis="1 0 0" stiffness="100" damping="10" armature="0.02" range="-5.6250 5.6250" />
                      <joint name="R_Index1_y" type="hinge" pos="0 0 0" axis="0 1 0" stiffness="100" damping="10" armature="0.02" range="-5.6250 5.6250" />
                      <joint name="R_Index1_z" type="hinge" pos="0 0 0" axis="0 0 1" stiffness="100" damping="10" armature="0.02" range="-55.6250 55.6250" />
                      <geom type="capsule" contype="1" conaffinity="1" density="1000" fromto="-0.0065 0.0003 0.0006 -0.0261 0.0012 0.0023" size="0.0065" />
                      <body name="R_Index2" pos="-0.0326 0.0015 0.0029">
                        <joint name="R_Index2_x" type="hinge" pos="0 0 0" axis="1 0 0" stiffness="100" damping="10" armature="0.02" range="-5.6250 5.6250" />
                        <joint name="R_Index2_y" type="hinge" pos="0 0 0" axis="0 1 0" stiffness="100" damping="10" armature="0.02" range="-5.6250 5.6250" />
                        <joint name="R_Index2_z" type="hinge" pos="0 0 0" axis="0 0 1" stiffness="100" damping="10" armature="0.02" range="-55.6250 55.6250" />
                        <geom type="capsule" contype="1" conaffinity="1" density="1000" fromto="-0.0046 -0.0006 -0.0001 -0.0184 -0.0023 -0.0006" size="0.0053" />
                        <body name="R_Index3" pos="-0.0230 -0.0028 -0.0007">
                          <joint name="R_Index3_x" type="hinge" pos="0 0 0" axis="1 0 0" stiffness="100" damping="10" armature="0.02" range="-5.6250 5.6250" />
                          <joint name="R_Index3_y" type="hinge" pos="0 0 0" axis="0 1 0" stiffness="100" damping="10" armature="0.02" range="-5.6250 5.6250" />
                          <joint name="R_Index3_z" type="hinge" pos="0 0 0" axis="0 0 1" stiffness="100" damping="10" armature="0.02" range="-5.6250 90.0000" />
                          <geom type="capsule" contype="1" conaffinity="1" density="1000" fromto="-0.0056 -0.0007 -0.0002 -0.0174 -0.0021 -0.0005" size="0.0048" />
                        </body>
                      </body>
                    </body>
                    <body name="R_Middle1" pos="-0.1109 -0.0105 -0.0048">
                      <joint name="R_Middle1_x" type="hinge" pos="0 0 0" axis="1 0 0" stiffness="100" damping="10" armature="0.02" range="-5.6250 5.6250" />
                      <joint name="R_Middle1_y" type="hinge" pos="0 0 0" axis="0 1 0" stiffness="100" damping="10" armature="0.02" range="-5.6250 5.6250" />
                      <joint name="R_Middle1_z" type="hinge" pos="0 0 0" axis="0 0 1" stiffness="100" damping="10" armature="0.02" range="-55.6250 55.6250" />
                      <geom type="capsule" contype="1" conaffinity="1" density="1000" fromto="-0.0062 0.0001 -0.0008 -0.0248 0.0003 -0.0033" size="0.0067" />
                      <body name="R_Middle2" pos="-0.0310 0.0004 -0.0041">
                        <joint name="R_Middle2_x" type="hinge" pos="0 0 0" axis="1 0 0" stiffness="100" damping="10" armature="0.02" range="-5.6250 5.6250" />
                        <joint name="R_Middle2_y" type="hinge" pos="0 0 0" axis="0 1 0" stiffness="100" damping="10" armature="0.02" range="-5.6250 5.6250" />
                        <joint name="R_Middle2_z" type="hinge" pos="0 0 0" axis="0 0 1" stiffness="100" damping="10" armature="0.02" range="-55.6250 55.6250" />
                        <geom type="capsule" contype="1" conaffinity="1" density="1000" fromto="-0.0047 -0.0005 -0.0008 -0.0190 -0.0019 -0.0034" size="0.0050" />
                        <body name="R_Middle3" pos="-0.0237 -0.0024 -0.0042">
                          <joint name="R_Middle3_x" type="hinge" pos="0 0 0" axis="1 0 0" stiffness="100" damping="10" armature="0.02" range="-5.6250 5.6250" />
                          <joint name="R_Middle3_y" type="hinge" pos="0 0 0" axis="0 1 0" stiffness="100" damping="10" armature="0.02" range="-5.6250 5.6250" />
                          <joint name="R_Middle3_z" type="hinge" pos="0 0 0" axis="0 0 1" stiffness="100" damping="10" armature="0.02" range="-5.6250 90.0000" />
                          <geom type="capsule" contype="1" conaffinity="1" density="1000" fromto="-0.0056 -0.0006 -0.0010 -0.0182 -0.0019 -0.0032" size="0.0045" />
                        </body>
                      </body>
                    </body>
                    <body name="R_Pinky1" pos="-0.0859 -0.0185 -0.0451">
                      <joint name="R_Pinky1_x" type="hinge" pos="0 0 0" axis="1 0 0" stiffness="100" damping="10" armature="0.02" range="-5.6250 5.6250" />
                      <joint name="R_Pinky1_y" type="hinge" pos="0 0 0" axis="0 1 0" stiffness="100" damping="10" armature="0.02" range="-5.6250 5.6250" />
                      <joint name="R_Pinky1_z" type="hinge" pos="0 0 0" axis="0 0 1" stiffness="100" damping="10" armature="0.02" range="-55.6250 55.6250" />
                      <geom type="capsule" contype="1" conaffinity="1" density="1000" fromto="-0.0034 -0.0003 -0.0022 -0.0135 -0.0014 -0.0089" size="0.0050" />
                      <body name="R_Pinky2" pos="-0.0168 -0.0017 -0.0111">
                        <joint name="R_Pinky2_x" type="hinge" pos="0 0 0" axis="1 0 0" stiffness="100" damping="10" armature="0.02" range="-5.6250 5.6250" />
                        <joint name="R_Pinky2_y" type="hinge" pos="0 0 0" axis="0 1 0" stiffness="100" damping="10" armature="0.02" range="-5.6250 5.6250" />
                        <joint name="R_Pinky2_z" type="hinge" pos="0 0 0" axis="0 0 1" stiffness="100" damping="10" armature="0.02" range="-55.6250 55.6250" />
                        <geom type="capsule" contype="1" conaffinity="1" density="1000" fromto="-0.0033 -0.0004 -0.0021 -0.0132 -0.0016 -0.0084" size="0.0045" />
                        <body name="R_Pinky3" pos="-0.0165 -0.0020 -0.0105">
                          <joint name="R_Pinky3_x" type="hinge" pos="0 0 0" axis="1 0 0" stiffness="100" damping="10" armature="0.02" range="-5.6250 5.6250" />
                          <joint name="R_Pinky3_y" type="hinge" pos="0 0 0" axis="0 1 0" stiffness="100" damping="10" armature="0.02" range="-5.6250 5.6250" />
                          <joint name="R_Pinky3_z" type="hinge" pos="0 0 0" axis="0 0 1" stiffness="100" damping="10" armature="0.02" range="-5.6250 90.0000" />
                          <geom type="capsule" contype="1" conaffinity="1" density="1000" fromto="-0.0040 -0.0005 -0.0026 -0.0125 -0.0015 -0.0080" size="0.0036" />
                        </body>
                      </body>
                    </body>
                    <body name="R_Ring1" pos="-0.0991 -0.0130 -0.0283">
                      <joint name="R_Ring1_x" type="hinge" pos="0 0 0" axis="1 0 0" stiffness="100" damping="10" armature="0.02" range="-5.6250 5.6250" />
                      <joint name="R_Ring1_y" type="hinge" pos="0 0 0" axis="0 1 0" stiffness="100" damping="10" armature="0.02" range="-5.6250 5.6250" />
                      <joint name="R_Ring1_z" type="hinge" pos="0 0 0" axis="0 0 1" stiffness="100" damping="10" armature="0.02" range="-55.6250 55.6250" />
                      <geom type="capsule" contype="1" conaffinity="1" density="1000" fromto="-0.0058 0.0002 -0.0009 -0.0231 0.0007 -0.0038" size="0.0057" />
                      <body name="R_Ring2" pos="-0.0289 0.0008 -0.0047">
                        <joint name="R_Ring2_x" type="hinge" pos="0 0 0" axis="1 0 0" stiffness="100" damping="10" armature="0.02" range="-5.6250 5.6250" />
                        <joint name="R_Ring2_y" type="hinge" pos="0 0 0" axis="0 1 0" stiffness="100" damping="10" armature="0.02" range="-5.6250 5.6250" />
                        <joint name="R_Ring2_z" type="hinge" pos="0 0 0" axis="0 0 1" stiffness="100" damping="10" armature="0.02" range="-55.6250 55.6250" />
                        <geom type="capsule" contype="1" conaffinity="1" density="1000" fromto="-0.0047 -0.0004 -0.0013 -0.0187 -0.0016 -0.0052" size="0.0051" />
                        <body name="R_Ring3" pos="-0.0234 -0.0020 -0.0065">
                          <joint name="R_Ring3_x" type="hinge" pos="0 0 0" axis="1 0 0" stiffness="100" damping="10" armature="0.02" range="-5.6250 5.6250" />
                          <joint name="R_Ring3_y" type="hinge" pos="0 0 0" axis="0 1 0" stiffness="100" damping="10" armature="0.02" range="-5.6250 5.6250" />
                          <joint name="R_Ring3_z" type="hinge" pos="0 0 0" axis="0 0 1" stiffness="100" damping="10" armature="0.02" range="-5.6250 90.0000" />
                          <geom type="capsule" contype="1" conaffinity="1" density="1000" fromto="-0.0055 -0.0005 -0.0015 -0.0179 -0.0016 -0.0050" size="0.0043" />
                        </body>
                      </body>
                    </body>
                    <body name="R_Thumb1" pos="-0.0408 -0.0241 0.0250">
                      <joint name="R_Thumb1_x" type="hinge" pos="0 0 0" axis="1 0 0" stiffness="100" damping="10" armature="0.02" range="-55.6250 55.6250" />
                      <joint name="R_Thumb1_y" type="hinge" pos="0 0 0" axis="0 1 0" stiffness="100" damping="10" armature="0.02" range="-55.6250 55.6250" />
                      <joint name="R_Thumb1_z" type="hinge" pos="0 0 0" axis="0 0 1" stiffness="100" damping="10" armature="0.02" range="-55.6250 55.6250" />
                      <geom type="capsule" contype="1" conaffinity="1" density="1000" fromto="-0.0035 0.0004 0.0052 -0.0140 0.0015 0.0207" size="0.0086" />
                      <body name="R_Thumb2" pos="-0.0175 0.0018 0.0259">
                        <joint name="R_Thumb2_x" type="hinge" pos="0 0 0" axis="1 0 0" stiffness="100" damping="10" armature="0.02" range="-5.6250 5.6250" />
                        <joint name="R_Thumb2_y" type="hinge" pos="0 0 0" axis="0 1 0" stiffness="100" damping="10" armature="0.02" range="-5.6250 5.6250" />
                        <joint name="R_Thumb2_z" type="hinge" pos="0 0 0" axis="0 0 1" stiffness="100" damping="10" armature="0.02" range="-5.6250 5.6250" />
                        <geom type="capsule" contype="1" conaffinity="1" density="1000" fromto="-0.0043 -0.0009 0.0032 -0.0170 -0.0035 0.0128" size="0.0065" />
                        <body name="R_Thumb3" pos="-0.0213 -0.0043 0.0161">
                          <joint name="R_Thumb3_x" type="hinge" pos="0 0 0" axis="1 0 0" stiffness="100" damping="10" armature="0.02" range="-5.6250 5.6250" />
                          <joint name="R_Thumb3_y" type="hinge" pos="0 0 0" axis="0 1 0" stiffness="100" damping="10" armature="0.02" range="-5.6250 5.6250" />
                          <joint name="R_Thumb3_z" type="hinge" pos="0 0 0" axis="0 0 1" stiffness="100" damping="10" armature="0.02" range="-5.6250 90.0000" />
                          <geom type="capsule" contype="1" conaffinity="1" density="1000" fromto="-0.0050 -0.0010 0.0037 -0.0163 -0.0033 0.0123" size="0.0064" />
                        </body>
                      </body>
                    </body>
                  </body>
                </body>
              </body>
            </body>
          </body>
        </body>
      </body>
    </body>
  </worldbody>
  <actuator>
    <motor name="L_Hip_x" joint="L_Hip_x" gear="1" />
    <motor name="L_Hip_y" joint="L_Hip_y" gear="1" />
    <motor name="L_Hip_z" joint="L_Hip_z" gear="1" />
    <motor name="L_Knee_x" joint="L_Knee_x" gear="1" />
    <motor name="L_Knee_y" joint="L_Knee_y" gear="1" />
    <motor name="L_Knee_z" joint="L_Knee_z" gear="1" />
    <motor name="L_Ankle_x" joint="L_Ankle_x" gear="1" />
    <motor name="L_Ankle_y" joint="L_Ankle_y" gear="1" />
    <motor name="L_Ankle_z" joint="L_Ankle_z" gear="1" />
    <motor name="L_Toe_x" joint="L_Toe_x" gear="1" />
    <motor name="L_Toe_y" joint="L_Toe_y" gear="1" />
    <motor name="L_Toe_z" joint="L_Toe_z" gear="1" />
    <motor name="R_Hip_x" joint="R_Hip_x" gear="1" />
    <motor name="R_Hip_y" joint="R_Hip_y" gear="1" />
    <motor name="R_Hip_z" joint="R_Hip_z" gear="1" />
    <motor name="R_Knee_x" joint="R_Knee_x" gear="1" />
    <motor name="R_Knee_y" joint="R_Knee_y" gear="1" />
    <motor name="R_Knee_z" joint="R_Knee_z" gear="1" />
    <motor name="R_Ankle_x" joint="R_Ankle_x" gear="1" />
    <motor name="R_Ankle_y" joint="R_Ankle_y" gear="1" />
    <motor name="R_Ankle_z" joint="R_Ankle_z" gear="1" />
    <motor name="R_Toe_x" joint="R_Toe_x" gear="1" />
    <motor name="R_Toe_y" joint="R_Toe_y" gear="1" />
    <motor name="R_Toe_z" joint="R_Toe_z" gear="1" />
    <motor name="Torso_x" joint="Torso_x" gear="1" />
    <motor name="Torso_y" joint="Torso_y" gear="1" />
    <motor name="Torso_z" joint="Torso_z" gear="1" />
    <motor name="Spine_x" joint="Spine_x" gear="1" />
    <motor name="Spine_y" joint="Spine_y" gear="1" />
    <motor name="Spine_z" joint="Spine_z" gear="1" />
    <motor name="Chest_x" joint="Chest_x" gear="1" />
    <motor name="Chest_y" joint="Chest_y" gear="1" />
    <motor name="Chest_z" joint="Chest_z" gear="1" />
    <motor name="Neck_x" joint="Neck_x" gear="1" />
    <motor name="Neck_y" joint="Neck_y" gear="1" />
    <motor name="Neck_z" joint="Neck_z" gear="1" />
    <motor name="Head_x" joint="Head_x" gear="1" />
    <motor name="Head_y" joint="Head_y" gear="1" />
    <motor name="Head_z" joint="Head_z" gear="1" />
    <motor name="L_Thorax_x" joint="L_Thorax_x" gear="1" />
    <motor name="L_Thorax_y" joint="L_Thorax_y" gear="1" />
    <motor name="L_Thorax_z" joint="L_Thorax_z" gear="1" />
    <motor name="L_Shoulder_x" joint="L_Shoulder_x" gear="1" />
    <motor name="L_Shoulder_y" joint="L_Shoulder_y" gear="1" />
    <motor name="L_Shoulder_z" joint="L_Shoulder_z" gear="1" />
    <motor name="L_Elbow_x" joint="L_Elbow_x" gear="1" />
    <motor name="L_Elbow_y" joint="L_Elbow_y" gear="1" />
    <motor name="L_Elbow_z" joint="L_Elbow_z" gear="1" />
    <motor name="L_Wrist_x" joint="L_Wrist_x" gear="1" />
    <motor name="L_Wrist_y" joint="L_Wrist_y" gear="1" />
    <motor name="L_Wrist_z" joint="L_Wrist_z" gear="1" />
    <motor name="L_Index1_x" joint="L_Index1_x" gear="1" />
    <motor name="L_Index1_y" joint="L_Index1_y" gear="1" />
    <motor name="L_Index1_z" joint="L_Index1_z" gear="1" />
    <motor name="L_Index2_x" joint="L_Index2_x" gear="1" />
    <motor name="L_Index2_y" joint="L_Index2_y" gear="1" />
    <motor name="L_Index2_z" joint="L_Index2_z" gear="1" />
    <motor name="L_Index3_x" joint="L_Index3_x" gear="1" />
    <motor name="L_Index3_y" joint="L_Index3_y" gear="1" />
    <motor name="L_Index3_z" joint="L_Index3_z" gear="1" />
    <motor name="L_Middle1_x" joint="L_Middle1_x" gear="1" />
    <motor name="L_Middle1_y" joint="L_Middle1_y" gear="1" />
    <motor name="L_Middle1_z" joint="L_Middle1_z" gear="1" />
    <motor name="L_Middle2_x" joint="L_Middle2_x" gear="1" />
    <motor name="L_Middle2_y" joint="L_Middle2_y" gear="1" />
    <motor name="L_Middle2_z" joint="L_Middle2_z" gear="1" />
    <motor name="L_Middle3_x" joint="L_Middle3_x" gear="1" />
    <motor name="L_Middle3_y" joint="L_Middle3_y" gear="1" />
    <motor name="L_Middle3_z" joint="L_Middle3_z" gear="1" />
    <motor name="L_Pinky1_x" joint="L_Pinky1_x" gear="1" />
    <motor name="L_Pinky1_y" joint="L_Pinky1_y" gear="1" />
    <motor name="L_Pinky1_z" joint="L_Pinky1_z" gear="1" />
    <motor name="L_Pinky2_x" joint="L_Pinky2_x" gear="1" />
    <motor name="L_Pinky2_y" joint="L_Pinky2_y" gear="1" />
    <motor name="L_Pinky2_z" joint="L_Pinky2_z" gear="1" />
    <motor name="L_Pinky3_x" joint="L_Pinky3_x" gear="1" />
    <motor name="L_Pinky3_y" joint="L_Pinky3_y" gear="1" />
    <motor name="L_Pinky3_z" joint="L_Pinky3_z" gear="1" />
    <motor name="L_Ring1_x" joint="L_Ring1_x" gear="1" />
    <motor name="L_Ring1_y" joint="L_Ring1_y" gear="1" />
    <motor name="L_Ring1_z" joint="L_Ring1_z" gear="1" />
    <motor name="L_Ring2_x" joint="L_Ring2_x" gear="1" />
    <motor name="L_Ring2_y" joint="L_Ring2_y" gear="1" />
    <motor name="L_Ring2_z" joint="L_Ring2_z" gear="1" />
    <motor name="L_Ring3_x" joint="L_Ring3_x" gear="1" />
    <motor name="L_Ring3_y" joint="L_Ring3_y" gear="1" />
    <motor name="L_Ring3_z" joint="L_Ring3_z" gear="1" />
    <motor name="L_Thumb1_x" joint="L_Thumb1_x" gear="1" />
    <motor name="L_Thumb1_y" joint="L_Thumb1_y" gear="1" />
    <motor name="L_Thumb1_z" joint="L_Thumb1_z" gear="1" />
    <motor name="L_Thumb2_x" joint="L_Thumb2_x" gear="1" />
    <motor name="L_Thumb2_y" joint="L_Thumb2_y" gear="1" />
    <motor name="L_Thumb2_z" joint="L_Thumb2_z" gear="1" />
    <motor name="L_Thumb3_x" joint="L_Thumb3_x" gear="1" />
    <motor name="L_Thumb3_y" joint="L_Thumb3_y" gear="1" />
    <motor name="L_Thumb3_z" joint="L_Thumb3_z" gear="1" />
    <motor name="R_Thorax_x" joint="R_Thorax_x" gear="1" />
    <motor name="R_Thorax_y" joint="R_Thorax_y" gear="1" />
    <motor name="R_Thorax_z" joint="R_Thorax_z" gear="1" />
    <motor name="R_Shoulder_x" joint="R_Shoulder_x" gear="1" />
    <motor name="R_Shoulder_y" joint="R_Shoulder_y" gear="1" />
    <motor name="R_Shoulder_z" joint="R_Shoulder_z" gear="1" />
    <motor name="R_Elbow_x" joint="R_Elbow_x" gear="1" />
    <motor name="R_Elbow_y" joint="R_Elbow_y" gear="1" />
    <motor name="R_Elbow_z" joint="R_Elbow_z" gear="1" />
    <motor name="R_Wrist_x" joint="R_Wrist_x" gear="1" />
    <motor name="R_Wrist_y" joint="R_Wrist_y" gear="1" />
    <motor name="R_Wrist_z" joint="R_Wrist_z" gear="1" />
    <motor name="R_Index1_x" joint="R_Index1_x" gear="1" />
    <motor name="R_Index1_y" joint="R_Index1_y" gear="1" />
    <motor name="R_Index1_z" joint="R_Index1_z" gear="1" />
    <motor name="R_Index2_x" joint="R_Index2_x" gear="1" />
    <motor name="R_Index2_y" joint="R_Index2_y" gear="1" />
    <motor name="R_Index2_z" joint="R_Index2_z" gear="1" />
    <motor name="R_Index3_x" joint="R_Index3_x" gear="1" />
    <motor name="R_Index3_y" joint="R_Index3_y" gear="1" />
    <motor name="R_Index3_z" joint="R_Index3_z" gear="1" />
    <motor name="R_Middle1_x" joint="R_Middle1_x" gear="1" />
    <motor name="R_Middle1_y" joint="R_Middle1_y" gear="1" />
    <motor name="R_Middle1_z" joint="R_Middle1_z" gear="1" />
    <motor name="R_Middle2_x" joint="R_Middle2_x" gear="1" />
    <motor name="R_Middle2_y" joint="R_Middle2_y" gear="1" />
    <motor name="R_Middle2_z" joint="R_Middle2_z" gear="1" />
    <motor name="R_Middle3_x" joint="R_Middle3_x" gear="1" />
    <motor name="R_Middle3_y" joint="R_Middle3_y" gear="1" />
    <motor name="R_Middle3_z" joint="R_Middle3_z" gear="1" />
    <motor name="R_Pinky1_x" joint="R_Pinky1_x" gear="1" />
    <motor name="R_Pinky1_y" joint="R_Pinky1_y" gear="1" />
    <motor name="R_Pinky1_z" joint="R_Pinky1_z" gear="1" />
    <motor name="R_Pinky2_x" joint="R_Pinky2_x" gear="1" />
    <motor name="R_Pinky2_y" joint="R_Pinky2_y" gear="1" />
    <motor name="R_Pinky2_z" joint="R_Pinky2_z" gear="1" />
    <motor name="R_Pinky3_x" joint="R_Pinky3_x" gear="1" />
    <motor name="R_Pinky3_y" joint="R_Pinky3_y" gear="1" />
    <motor name="R_Pinky3_z" joint="R_Pinky3_z" gear="1" />
    <motor name="R_Ring1_x" joint="R_Ring1_x" gear="1" />
    <motor name="R_Ring1_y" joint="R_Ring1_y" gear="1" />
    <motor name="R_Ring1_z" joint="R_Ring1_z" gear="1" />
    <motor name="R_Ring2_x" joint="R_Ring2_x" gear="1" />
    <motor name="R_Ring2_y" joint="R_Ring2_y" gear="1" />
    <motor name="R_Ring2_z" joint="R_Ring2_z" gear="1" />
    <motor name="R_Ring3_x" joint="R_Ring3_x" gear="1" />
    <motor name="R_Ring3_y" joint="R_Ring3_y" gear="1" />
    <motor name="R_Ring3_z" joint="R_Ring3_z" gear="1" />
    <motor name="R_Thumb1_x" joint="R_Thumb1_x" gear="1" />
    <motor name="R_Thumb1_y" joint="R_Thumb1_y" gear="1" />
    <motor name="R_Thumb1_z" joint="R_Thumb1_z" gear="1" />
    <motor name="R_Thumb2_x" joint="R_Thumb2_x" gear="1" />
    <motor name="R_Thumb2_y" joint="R_Thumb2_y" gear="1" />
    <motor name="R_Thumb2_z" joint="R_Thumb2_z" gear="1" />
    <motor name="R_Thumb3_x" joint="R_Thumb3_x" gear="1" />
    <motor name="R_Thumb3_y" joint="R_Thumb3_y" gear="1" />
    <motor name="R_Thumb3_z" joint="R_Thumb3_z" gear="1" />
  </actuator>
  <contact />
  <sensor />
  <size njmax="700" nconmax="700" />
</mujoco>
