<?xml version='1.0' encoding='utf-8'?>
<mujoco model="smplx_mapped_s99">
  <compiler coordinate="local" />
  <default>
    <joint damping="0.0" armature="0.01" stiffness="0.0" limited="true" />
    <geom conaffinity="1" condim="3" contype="7" margin="0.001" rgba="0.8 0.6 .4 1" />
  </default>
  <asset>
    <texture type="skybox" builtin="gradient" rgb1=".4 .5 .6" rgb2="0 0 0" width="100" height="100" />
    <texture builtin="flat" height="1278" mark="cross" markrgb="1 1 1" name="texgeom" random="0.01" rgb1="0.8 0.6 0.4" rgb2="0.8 0.6 0.4" type="cube" width="127" />
    <texture builtin="checker" height="100" name="texplane" rgb1="0 0 0" rgb2="0.8 0.8 0.8" type="2d" width="100" />
    <material name="MatPlane" reflectance="0.5" shininess="1" specular="1" texrepeat="60 60" texture="texplane" />
    <material name="geom" texture="texgeom" texuniform="true" />
  </asset>
  <worldbody>
    <light cutoff="100" diffuse="1 1 1" dir="-0 0 -1.3" directional="true" exponent="1" pos="0 0 1.3" specular=".1 .1 .1" />
    <geom conaffinity="1" condim="3" name="floor" pos="0 0 0" rgba="0.8 0.9 0.8 1" size="100 100 .2" type="plane" material="MatPlane" />
    <body name="Pelvis" pos="0.0006 -0.3238 0.0058">
      <freejoint name="Pelvis" />
      <geom type="sphere" contype="1" conaffinity="1" density="4629.6296296296305" size="0.09" pos="0.0000 0.0000 0.0000" name="Pelvis" />
      <body name="L_Hip" pos="0.0700 -0.0824 -0.0157">
        <joint name="L_Hip_x" type="hinge" pos="0 0 0" axis="1 0 0" stiffness="800" damping="80" armature="0.02" range="-180.00 180.00" />
        <joint name="L_Hip_y" type="hinge" pos="0 0 0" axis="0 1 0" stiffness="800" damping="80" armature="0.02" range="-180.00 180.00" />
        <joint name="L_Hip_z" type="hinge" pos="0 0 0" axis="0 0 1" stiffness="800" damping="80" armature="0.02" range="-180.00 180.00" />
        <geom type="capsule" contype="1" conaffinity="1" density="2040.816327" fromto="0.0066 -0.0704 -0.0027 0.0264 -0.2815 -0.0106" size="0.059" />
        <body name="L_Knee" pos="0.0331 -0.3518 -0.0133">
          <joint name="L_Knee_x" type="hinge" pos="0 0 0" axis="1 0 0" stiffness="800" damping="80" armature="0.02" range="-180.00 180.00" />
          <joint name="L_Knee_y" type="hinge" pos="0 0 0" axis="0 1 0" stiffness="800" damping="80" armature="0.02" range="-180.00 180.00" />
          <joint name="L_Knee_z" type="hinge" pos="0 0 0" axis="0 0 1" stiffness="800" damping="80" armature="0.02" range="-180.00 180.00" />
          <geom type="capsule" contype="1" conaffinity="1" density="1234.567901" fromto="-0.0017 -0.0721 -0.0032 -0.0069 -0.2885 -0.0129" size="0.0564" />
          <body name="L_Ankle" pos="-0.0086 -0.3606 -0.0161">
            <joint name="L_Ankle_x" type="hinge" pos="0 0 0" axis="1 0 0" stiffness="800" damping="80" armature="0.02" range="-180.00 180.00" />
            <joint name="L_Ankle_y" type="hinge" pos="0 0 0" axis="0 1 0" stiffness="800" damping="80" armature="0.02" range="-180.00 180.00" />
            <joint name="L_Ankle_z" type="hinge" pos="0 0 0" axis="0 0 1" stiffness="800" damping="80" armature="0.02" range="-180.00 180.00" />
            <geom type="box" contype="1" conaffinity="1" density="1000" pos="0.0115 -0.0234 0.0566" size="0.0502 0.0216 0.0909" quat="1.0000 0.0000 0.0000 0.0000" />
            <body name="L_Toe" pos="0.0203 -0.0424 0.1048">
              <joint name="L_Toe_x" type="hinge" pos="0 0 0" axis="1 0 0" stiffness="500" damping="50" armature="0.02" range="-180.00 180.00" />
              <joint name="L_Toe_y" type="hinge" pos="0 0 0" axis="0 1 0" stiffness="500" damping="50" armature="0.02" range="-180.00 180.00" />
              <joint name="L_Toe_z" type="hinge" pos="0 0 0" axis="0 0 1" stiffness="500" damping="50" armature="0.02" range="-180.00 180.00" />
              <geom type="box" contype="1" conaffinity="1" density="1000" pos="-0.0115 0.0227 0.0576" size="0.0493 0.0209 0.0194" quat="1.0000 0.0000 0.0000 0.0000" />
            </body>
          </body>
        </body>
      </body>
      <body name="R_Hip" pos="-0.0690 -0.0889 -0.0164">
        <joint name="R_Hip_x" type="hinge" pos="0 0 0" axis="1 0 0" stiffness="800" damping="80" armature="0.02" range="-180.00 180.00" />
        <joint name="R_Hip_y" type="hinge" pos="0 0 0" axis="0 1 0" stiffness="800" damping="80" armature="0.02" range="-180.00 180.00" />
        <joint name="R_Hip_z" type="hinge" pos="0 0 0" axis="0 0 1" stiffness="800" damping="80" armature="0.02" range="-180.00 180.00" />
        <geom type="capsule" contype="1" conaffinity="1" density="2040.816327" fromto="-0.0075 -0.0695 -0.0016 -0.0301 -0.2780 -0.0063" size="0.0588" />
        <body name="R_Knee" pos="-0.0376 -0.3476 -0.0079">
          <joint name="R_Knee_x" type="hinge" pos="0 0 0" axis="1 0 0" stiffness="800" damping="80" armature="0.02" range="-180.00 180.00" />
          <joint name="R_Knee_y" type="hinge" pos="0 0 0" axis="0 1 0" stiffness="800" damping="80" armature="0.02" range="-180.00 180.00" />
          <joint name="R_Knee_z" type="hinge" pos="0 0 0" axis="0 0 1" stiffness="800" damping="80" armature="0.02" range="-180.00 180.00" />
          <geom type="capsule" contype="1" conaffinity="1" density="1234.567901" fromto="0.0008 -0.0705 -0.0024 0.0032 -0.2818 -0.0097" size="0.0564" />
          <body name="R_Ankle" pos="0.0040 -0.3523 -0.0121">
            <joint name="R_Ankle_x" type="hinge" pos="0 0 0" axis="1 0 0" stiffness="800" damping="80" armature="0.02" range="-180.00 180.00" />
            <joint name="R_Ankle_y" type="hinge" pos="0 0 0" axis="0 1 0" stiffness="800" damping="80" armature="0.02" range="-180.00 180.00" />
            <joint name="R_Ankle_z" type="hinge" pos="0 0 0" axis="0 0 1" stiffness="800" damping="80" armature="0.02" range="-180.00 180.00" />
            <geom type="box" contype="1" conaffinity="1" density="1000" pos="-0.0091 -0.0250 0.0535" size="0.0502 0.0216 0.0909" quat="1.0000 0.0000 0.0000 0.0000" />
            <body name="R_Toe" pos="-0.0161 -0.0458 0.0984">
              <joint name="R_Toe_x" type="hinge" pos="0 0 0" axis="1 0 0" stiffness="500" damping="50" armature="0.02" range="-180.00 180.00" />
              <joint name="R_Toe_y" type="hinge" pos="0 0 0" axis="0 1 0" stiffness="500" damping="50" armature="0.02" range="-180.00 180.00" />
              <joint name="R_Toe_z" type="hinge" pos="0 0 0" axis="0 0 1" stiffness="500" damping="50" armature="0.02" range="-180.00 180.00" />
              <geom type="box" contype="1" conaffinity="1" density="1000" pos="0.0091 0.0243 0.0545" size="0.0493 0.0209 0.0194" quat="1.0000 0.0000 0.0000 0.0000" />
            </body>
          </body>
        </body>
      </body>
      <body name="Torso" pos="-0.0055 0.0941 -0.0224">
        <joint name="Torso_x" type="hinge" pos="0 0 0" axis="1 0 0" stiffness="1000" damping="100" armature="0.02" range="-180.00 180.00" />
        <joint name="Torso_y" type="hinge" pos="0 0 0" axis="0 1 0" stiffness="1000" damping="100" armature="0.02" range="-180.00 180.00" />
        <joint name="Torso_z" type="hinge" pos="0 0 0" axis="0 0 1" stiffness="1000" damping="100" armature="0.02" range="-180.00 180.00" />
        <geom type="capsule" contype="1" conaffinity="1" density="1100" fromto="0.0044 0.0500 -0.0038 0.0054 0.0611 -0.0047" size="0.08" />
        <body name="Spine" pos="0.0097 0.1112 -0.0085">
          <joint name="Spine_x" type="hinge" pos="0 0 0" axis="1 0 0" stiffness="1000" damping="100" armature="0.02" range="-180.00 180.00" />
          <joint name="Spine_y" type="hinge" pos="0 0 0" axis="0 1 0" stiffness="1000" damping="100" armature="0.02" range="-180.00 180.00" />
          <joint name="Spine_z" type="hinge" pos="0 0 0" axis="0 0 1" stiffness="1000" damping="100" armature="0.02" range="-180.00 180.00" />
          <geom type="capsule" contype="1" conaffinity="1" density="1100" fromto="-0.0022 0.0197 0.0113 -0.0027 0.0241 0.0139" size="0.06" />
          <body name="Chest" pos="-0.0048 0.0438 0.0252">
            <joint name="Chest_x" type="hinge" pos="0 0 0" axis="1 0 0" stiffness="1000" damping="100" armature="0.02" range="-180.00 180.00" />
            <joint name="Chest_y" type="hinge" pos="0 0 0" axis="0 1 0" stiffness="1000" damping="100" armature="0.02" range="-180.00 180.00" />
            <joint name="Chest_z" type="hinge" pos="0 0 0" axis="0 0 1" stiffness="1000" damping="100" armature="0.02" range="-180.00 180.00" />
            <geom type="capsule" contype="1" conaffinity="1" density="1100" fromto="-0.0007 0.0265 -0.0037 -0.0026 0.1060 -0.0148" size="0.08" />
            <body name="Neck" pos="-0.0063 0.1840 -0.0296">
              <joint name="Neck_x" type="hinge" pos="0 0 0" axis="1 0 0" stiffness="500" damping="50" armature="0.02" range="-180.00 180.00" />
              <joint name="Neck_y" type="hinge" pos="0 0 0" axis="0 1 0" stiffness="500" damping="50" armature="0.02" range="-180.00 180.00" />
              <joint name="Neck_z" type="hinge" pos="0 0 0" axis="0 0 1" stiffness="500" damping="50" armature="0.02" range="-180.00 180.00" />
              <geom type="capsule" contype="1" conaffinity="1" density="1000" fromto="0.0041 0.0659 0.0083 0.0050 0.0805 0.0101" size="0.0437" />
              <body name="Head" pos="0.0091 0.1464 0.0184">
                <joint name="Head_x" type="hinge" pos="0 0 0" axis="1 0 0" stiffness="500" damping="50" armature="0.02" range="-180.00 180.00" />
                <joint name="Head_y" type="hinge" pos="0 0 0" axis="0 1 0" stiffness="500" damping="50" armature="0.02" range="-180.00 180.00" />
                <joint name="Head_z" type="hinge" pos="0 0 0" axis="0 0 1" stiffness="500" damping="50" armature="0.02" range="-180.00 180.00" />
                <geom type="sphere" contype="1" conaffinity="1" density="1000" size="0.1054" pos="0.0000 0.0000 0.0000" name="Head" />
              </body>
            </body>
            <body name="L_Thorax" pos="0.0539 0.1087 -0.0100">
              <joint name="L_Thorax_x" type="hinge" pos="0 0 0" axis="1 0 0" stiffness="500" damping="50" armature="0.02" range="-180.00 180.00" />
              <joint name="L_Thorax_y" type="hinge" pos="0 0 0" axis="0 1 0" stiffness="500" damping="50" armature="0.02" range="-180.00 180.00" />
              <joint name="L_Thorax_z" type="hinge" pos="0 0 0" axis="0 0 1" stiffness="500" damping="50" armature="0.02" range="-180.00 180.00" />
              <geom type="capsule" contype="1" conaffinity="1" density="1000" fromto="0.0200 0.0084 -0.0056 0.0800 0.0338 -0.0223" size="0.0564" />
              <body name="L_Shoulder" pos="0.1000 0.0422 -0.0278">
                <joint name="L_Shoulder_x" type="hinge" pos="0 0 0" axis="1 0 0" stiffness="500" damping="50" armature="0.02" range="-180.00 180.00" />
                <joint name="L_Shoulder_y" type="hinge" pos="0 0 0" axis="0 1 0" stiffness="500" damping="50" armature="0.02" range="-180.00 180.00" />
                <joint name="L_Shoulder_z" type="hinge" pos="0 0 0" axis="0 0 1" stiffness="500" damping="50" armature="0.02" range="-180.00 180.00" />
                <geom type="capsule" contype="1" conaffinity="1" density="1000" fromto="0.0547 -0.0112 -0.0056 0.2187 -0.0447 -0.0224" size="0.0533" />
                <body name="L_Elbow" pos="0.2734 -0.0559 -0.0280">
                  <joint name="L_Elbow_x" type="hinge" pos="0 0 0" axis="1 0 0" stiffness="500" damping="50" armature="0.02" range="-180.00 180.00" />
                  <joint name="L_Elbow_y" type="hinge" pos="0 0 0" axis="0 1 0" stiffness="500" damping="50" armature="0.02" range="-180.00 180.00" />
                  <joint name="L_Elbow_z" type="hinge" pos="0 0 0" axis="0 0 1" stiffness="500" damping="50" armature="0.02" range="-180.00 180.00" />
                  <geom type="capsule" contype="1" conaffinity="1" density="1000" fromto="0.0445 0.0014 0.0011 0.1778 0.0056 0.0043" size="0.0418" />
                  <body name="L_Wrist" pos="0.2223 0.0070 0.0053">
                    <joint name="L_Wrist_x" type="hinge" pos="0 0 0" axis="1 0 0" stiffness="300" damping="30" armature="0.02" range="-180.0000 180.0000" />
                    <joint name="L_Wrist_y" type="hinge" pos="0 0 0" axis="0 1 0" stiffness="300" damping="30" armature="0.02" range="-180.0000 180.0000" />
                    <joint name="L_Wrist_z" type="hinge" pos="0 0 0" axis="0 0 1" stiffness="300" damping="30" armature="0.02" range="-180.0000 180.0000" />
                    <geom type="box" contype="1" conaffinity="1" density="1000" pos="0.0456 -0.0084 -0.0022" size="0.0444 0.0076 0.0414" quat="1.0000 0.0000 0.0000 0.0000" />
                    <body name="L_Index1" pos="0.0982 -0.0148 0.0204">
                      <joint name="L_Index1_x" type="hinge" pos="0 0 0" axis="1 0 0" stiffness="100" damping="10" armature="0.02" range="-5.6250 5.6250" />
                      <joint name="L_Index1_y" type="hinge" pos="0 0 0" axis="0 1 0" stiffness="100" damping="10" armature="0.02" range="-5.6250 5.6250" />
                      <joint name="L_Index1_z" type="hinge" pos="0 0 0" axis="0 0 1" stiffness="100" damping="10" armature="0.02" range="-55.6250 55.6250" />
                      <geom type="capsule" contype="1" conaffinity="1" density="1000" fromto="0.0062 0.0006 0.0006 0.0247 0.0022 0.0022" size="0.0065" />
                      <body name="L_Index2" pos="0.0308 0.0028 0.0028">
                        <joint name="L_Index2_x" type="hinge" pos="0 0 0" axis="1 0 0" stiffness="100" damping="10" armature="0.02" range="-5.6250 5.6250" />
                        <joint name="L_Index2_y" type="hinge" pos="0 0 0" axis="0 1 0" stiffness="100" damping="10" armature="0.02" range="-5.6250 5.6250" />
                        <joint name="L_Index2_z" type="hinge" pos="0 0 0" axis="0 0 1" stiffness="100" damping="10" armature="0.02" range="-55.6250 55.6250" />
                        <geom type="capsule" contype="1" conaffinity="1" density="1000" fromto="0.0044 -0.0003 0.0001 0.0174 -0.0011 0.0004" size="0.0053" />
                        <body name="L_Index3" pos="0.0218 -0.0014 0.0005">
                          <joint name="L_Index3_x" type="hinge" pos="0 0 0" axis="1 0 0" stiffness="100" damping="10" armature="0.02" range="-5.6250 5.6250" />
                          <joint name="L_Index3_y" type="hinge" pos="0 0 0" axis="0 1 0" stiffness="100" damping="10" armature="0.02" range="-5.6250 5.6250" />
                          <joint name="L_Index3_z" type="hinge" pos="0 0 0" axis="0 0 1" stiffness="100" damping="10" armature="0.02" range="-90.0000 5.6250" />
                          <geom type="capsule" contype="1" conaffinity="1" density="1000" fromto="0.0045 -0.0003 0.0001 0.0173 -0.0011 0.0004" size="0.0047" />
                        </body>
                      </body>
                    </body>
                    <body name="L_Middle1" pos="0.1049 -0.0122 -0.0016">
                      <joint name="L_Middle1_x" type="hinge" pos="0 0 0" axis="1 0 0" stiffness="100" damping="10" armature="0.02" range="-5.6250 5.6250" />
                      <joint name="L_Middle1_y" type="hinge" pos="0 0 0" axis="0 1 0" stiffness="100" damping="10" armature="0.02" range="-5.6250 5.6250" />
                      <joint name="L_Middle1_z" type="hinge" pos="0 0 0" axis="0 0 1" stiffness="100" damping="10" armature="0.02" range="-55.6250 55.6250" />
                      <geom type="capsule" contype="1" conaffinity="1" density="1000" fromto="0.0059 0.0003 -0.0007 0.0234 0.0011 -0.0028" size="0.0067" />
                      <body name="L_Middle2" pos="0.0293 0.0014 -0.0036">
                        <joint name="L_Middle2_x" type="hinge" pos="0 0 0" axis="1 0 0" stiffness="100" damping="10" armature="0.02" range="-5.6250 5.6250" />
                        <joint name="L_Middle2_y" type="hinge" pos="0 0 0" axis="0 1 0" stiffness="100" damping="10" armature="0.02" range="-5.6250 5.6250" />
                        <joint name="L_Middle2_z" type="hinge" pos="0 0 0" axis="0 0 1" stiffness="100" damping="10" armature="0.02" range="-55.6250 55.6250" />
                        <geom type="capsule" contype="1" conaffinity="1" density="1000" fromto="0.0046 -0.0001 -0.0007 0.0182 -0.0005 -0.0028" size="0.0050" />
                        <body name="L_Middle3" pos="0.0228 -0.0006 -0.0035">
                          <joint name="L_Middle3_x" type="hinge" pos="0 0 0" axis="1 0 0" stiffness="100" damping="10" armature="0.02" range="-5.6250 5.6250" />
                          <joint name="L_Middle3_y" type="hinge" pos="0 0 0" axis="0 1 0" stiffness="100" damping="10" armature="0.02" range="-5.6250 5.6250" />
                          <joint name="L_Middle3_z" type="hinge" pos="0 0 0" axis="0 0 1" stiffness="100" damping="10" armature="0.02" range="-90.0000 5.6250" />
                          <geom type="capsule" contype="1" conaffinity="1" density="1000" fromto="0.0047 -0.0001 -0.0007 0.0181 -0.0005 -0.0028" size="0.0045" />
                        </body>
                      </body>
                    </body>
                    <body name="L_Pinky1" pos="0.0800 -0.0195 -0.0401">
                      <joint name="L_Pinky1_x" type="hinge" pos="0 0 0" axis="1 0 0" stiffness="100" damping="10" armature="0.02" range="-5.6250 5.6250" />
                      <joint name="L_Pinky1_y" type="hinge" pos="0 0 0" axis="0 1 0" stiffness="100" damping="10" armature="0.02" range="-5.6250 5.6250" />
                      <joint name="L_Pinky1_z" type="hinge" pos="0 0 0" axis="0 0 1" stiffness="100" damping="10" armature="0.02" range="-55.6250 55.6250" />
                      <geom type="capsule" contype="1" conaffinity="1" density="1000" fromto="0.0029 -0.0001 -0.0024 0.0115 -0.0004 -0.0095" size="0.0050" />
                      <body name="L_Pinky2" pos="0.0143 -0.0005 -0.0119">
                        <joint name="L_Pinky2_x" type="hinge" pos="0 0 0" axis="1 0 0" stiffness="100" damping="10" armature="0.02" range="-5.6250 5.6250" />
                        <joint name="L_Pinky2_y" type="hinge" pos="0 0 0" axis="0 1 0" stiffness="100" damping="10" armature="0.02" range="-5.6250 5.6250" />
                        <joint name="L_Pinky2_z" type="hinge" pos="0 0 0" axis="0 0 1" stiffness="100" damping="10" armature="0.02" range="-55.6250 55.6250" />
                        <geom type="capsule" contype="1" conaffinity="1" density="1000" fromto="0.0029 -0.0002 -0.0023 0.0116 -0.0007 -0.0093" size="0.0045" />
                        <body name="L_Pinky3" pos="0.0145 -0.0009 -0.0116">
                          <joint name="L_Pinky3_x" type="hinge" pos="0 0 0" axis="1 0 0" stiffness="100" damping="10" armature="0.02" range="-5.6250 5.6250" />
                          <joint name="L_Pinky3_y" type="hinge" pos="0 0 0" axis="0 1 0" stiffness="100" damping="10" armature="0.02" range="-5.6250 5.6250" />
                          <joint name="L_Pinky3_z" type="hinge" pos="0 0 0" axis="0 0 1" stiffness="100" damping="10" armature="0.02" range="-90.0000 5.6250" />
                          <geom type="capsule" contype="1" conaffinity="1" density="1000" fromto="0.0031 -0.0002 -0.0025 0.0114 -0.0007 -0.0091" size="0.0036" />
                        </body>
                      </body>
                    </body>
                    <body name="L_Ring1" pos="0.0931 -0.0147 -0.0242">
                      <joint name="L_Ring1_x" type="hinge" pos="0 0 0" axis="1 0 0" stiffness="100" damping="10" armature="0.02" range="-5.6250 5.6250" />
                      <joint name="L_Ring1_y" type="hinge" pos="0 0 0" axis="0 1 0" stiffness="100" damping="10" armature="0.02" range="-5.6250 5.6250" />
                      <joint name="L_Ring1_z" type="hinge" pos="0 0 0" axis="0 0 1" stiffness="100" damping="10" armature="0.02" range="-55.6250 55.6250" />
                      <geom type="capsule" contype="1" conaffinity="1" density="1000" fromto="0.0054 0.0003 -0.0010 0.0215 0.0013 -0.0041" size="0.0057" />
                      <body name="L_Ring2" pos="0.0268 0.0016 -0.0052">
                        <joint name="L_Ring2_x" type="hinge" pos="0 0 0" axis="1 0 0" stiffness="100" damping="10" armature="0.02" range="-5.6250 5.6250" />
                        <joint name="L_Ring2_y" type="hinge" pos="0 0 0" axis="0 1 0" stiffness="100" damping="10" armature="0.02" range="-5.6250 5.6250" />
                        <joint name="L_Ring2_z" type="hinge" pos="0 0 0" axis="0 0 1" stiffness="100" damping="10" armature="0.02" range="-55.6250 55.6250" />
                        <geom type="capsule" contype="1" conaffinity="1" density="1000" fromto="0.0044 -0.0002 -0.0014 0.0176 -0.0008 -0.0056" size="0.0051" />
                        <body name="L_Ring3" pos="0.0219 -0.0010 -0.0070">
                          <joint name="L_Ring3_x" type="hinge" pos="0 0 0" axis="1 0 0" stiffness="100" damping="10" armature="0.02" range="-5.6250 5.6250" />
                          <joint name="L_Ring3_y" type="hinge" pos="0 0 0" axis="0 1 0" stiffness="100" damping="10" armature="0.02" range="-5.6250 5.6250" />
                          <joint name="L_Ring3_z" type="hinge" pos="0 0 0" axis="0 0 1" stiffness="100" damping="10" armature="0.02" range="-90.0000 5.6250" />
                          <geom type="capsule" contype="1" conaffinity="1" density="1000" fromto="0.0046 -0.0002 -0.0015 0.0174 -0.0008 -0.0056" size="0.0043" />
                        </body>
                      </body>
                    </body>
                    <body name="L_Thumb1" pos="0.0405 -0.0226 0.0263">
                      <joint name="L_Thumb1_x" type="hinge" pos="0 0 0" axis="1 0 0" stiffness="100" damping="10" armature="0.02" range="-55.6250 55.6250" />
                      <joint name="L_Thumb1_y" type="hinge" pos="0 0 0" axis="0 1 0" stiffness="100" damping="10" armature="0.02" range="-55.6250 55.6250" />
                      <joint name="L_Thumb1_z" type="hinge" pos="0 0 0" axis="0 0 1" stiffness="100" damping="10" armature="0.02" range="-55.6250 55.6250" />
                      <geom type="capsule" contype="1" conaffinity="1" density="1000" fromto="0.0033 0.0002 0.0047 0.0133 0.0008 0.0188" size="0.0086" />
                      <body name="L_Thumb2" pos="0.0166 0.0010 0.0235">
                        <joint name="L_Thumb2_x" type="hinge" pos="0 0 0" axis="1 0 0" stiffness="100" damping="10" armature="0.02" range="-5.6250 5.6250" />
                        <joint name="L_Thumb2_y" type="hinge" pos="0 0 0" axis="0 1 0" stiffness="100" damping="10" armature="0.02" range="-5.6250 5.6250" />
                        <joint name="L_Thumb2_z" type="hinge" pos="0 0 0" axis="0 0 1" stiffness="100" damping="10" armature="0.02" range="-5.6250 5.6250" />
                        <geom type="capsule" contype="1" conaffinity="1" density="1000" fromto="0.0039 -0.0011 0.0028 0.0157 -0.0046 0.0112" size="0.0065" />
                        <body name="L_Thumb3" pos="0.0196 -0.0057 0.0141">
                          <joint name="L_Thumb3_x" type="hinge" pos="0 0 0" axis="1 0 0" stiffness="100" damping="10" armature="0.02" range="-5.6250 5.6250" />
                          <joint name="L_Thumb3_y" type="hinge" pos="0 0 0" axis="0 1 0" stiffness="100" damping="10" armature="0.02" range="-5.6250 5.6250" />
                          <joint name="L_Thumb3_z" type="hinge" pos="0 0 0" axis="0 0 1" stiffness="100" damping="10" armature="0.02" range="-90.0000 5.6250" />
                          <geom type="capsule" contype="1" conaffinity="1" density="1000" fromto="0.0032 -0.0009 0.0023 0.0164 -0.0048 0.0117" size="0.0062" />
                        </body>
                      </body>
                    </body>
                  </body>
                </body>
              </body>
            </body>
            <body name="R_Thorax" pos="-0.0576 0.1049 -0.0160">
              <joint name="R_Thorax_x" type="hinge" pos="0 0 0" axis="1 0 0" stiffness="500" damping="50" armature="0.02" range="-180.00 180.00" />
              <joint name="R_Thorax_y" type="hinge" pos="0 0 0" axis="0 1 0" stiffness="500" damping="50" armature="0.02" range="-180.00 180.00" />
              <joint name="R_Thorax_z" type="hinge" pos="0 0 0" axis="0 0 1" stiffness="500" damping="50" armature="0.02" range="-180.00 180.00" />
              <geom type="capsule" contype="1" conaffinity="1" density="1000" fromto="-0.0217 0.0090 -0.0043 -0.0866 0.0359 -0.0170" size="0.0576" />
              <body name="R_Shoulder" pos="-0.1083 0.0449 -0.0213">
                <joint name="R_Shoulder_x" type="hinge" pos="0 0 0" axis="1 0 0" stiffness="500" damping="50" armature="0.02" range="-180.00 180.00" />
                <joint name="R_Shoulder_y" type="hinge" pos="0 0 0" axis="0 1 0" stiffness="500" damping="50" armature="0.02" range="-180.00 180.00" />
                <joint name="R_Shoulder_z" type="hinge" pos="0 0 0" axis="0 0 1" stiffness="500" damping="50" armature="0.02" range="-180.00 180.00" />
                <geom type="capsule" contype="1" conaffinity="1" density="1000" fromto="-0.0524 -0.0103 -0.0042 -0.2096 -0.0410 -0.0167" size="0.0538" />
                <body name="R_Elbow" pos="-0.2620 -0.0513 -0.0209">
                  <joint name="R_Elbow_x" type="hinge" pos="0 0 0" axis="1 0 0" stiffness="500" damping="50" armature="0.02" range="-180.00 180.00" />
                  <joint name="R_Elbow_y" type="hinge" pos="0 0 0" axis="0 1 0" stiffness="500" damping="50" armature="0.02" range="-180.00 180.00" />
                  <joint name="R_Elbow_z" type="hinge" pos="0 0 0" axis="0 0 1" stiffness="500" damping="50" armature="0.02" range="-180.00 180.00" />
                  <geom type="capsule" contype="1" conaffinity="1" density="1000" fromto="-0.0446 0.0005 -0.0007 -0.1784 0.0022 -0.0030" size="0.042" />
                  <body name="R_Wrist" pos="-0.2230 0.0027 -0.0037">
                    <joint name="R_Wrist_x" type="hinge" pos="0 0 0" axis="1 0 0" stiffness="300" damping="30" armature="0.02" range="-180.0000 180.0000" />
                    <joint name="R_Wrist_y" type="hinge" pos="0 0 0" axis="0 1 0" stiffness="300" damping="30" armature="0.02" range="-180.0000 180.0000" />
                    <joint name="R_Wrist_z" type="hinge" pos="0 0 0" axis="0 0 1" stiffness="300" damping="30" armature="0.02" range="-180.0000 180.0000" />
                    <geom type="box" contype="1" conaffinity="1" density="1000" pos="-0.0449 -0.0080 -0.0014" size="0.0416 0.0078 0.0414" quat="1.0000 0.0000 0.0000 0.0000" />
                    <body name="R_Index1" pos="-0.0971 -0.0139 0.0219">
                      <joint name="R_Index1_x" type="hinge" pos="0 0 0" axis="1 0 0" stiffness="100" damping="10" armature="0.02" range="-5.6250 5.6250" />
                      <joint name="R_Index1_y" type="hinge" pos="0 0 0" axis="0 1 0" stiffness="100" damping="10" armature="0.02" range="-5.6250 5.6250" />
                      <joint name="R_Index1_z" type="hinge" pos="0 0 0" axis="0 0 1" stiffness="100" damping="10" armature="0.02" range="-55.6250 55.6250" />
                      <geom type="capsule" contype="1" conaffinity="1" density="1000" fromto="-0.0062 0.0006 0.0006 -0.0247 0.0022 0.0022" size="0.0065" />
                      <body name="R_Index2" pos="-0.0308 0.0028 0.0028">
                        <joint name="R_Index2_x" type="hinge" pos="0 0 0" axis="1 0 0" stiffness="100" damping="10" armature="0.02" range="-5.6250 5.6250" />
                        <joint name="R_Index2_y" type="hinge" pos="0 0 0" axis="0 1 0" stiffness="100" damping="10" armature="0.02" range="-5.6250 5.6250" />
                        <joint name="R_Index2_z" type="hinge" pos="0 0 0" axis="0 0 1" stiffness="100" damping="10" armature="0.02" range="-55.6250 55.6250" />
                        <geom type="capsule" contype="1" conaffinity="1" density="1000" fromto="-0.0044 -0.0003 0.0001 -0.0174 -0.0011 0.0004" size="0.0053" />
                        <body name="R_Index3" pos="-0.0218 -0.0014 0.0005">
                          <joint name="R_Index3_x" type="hinge" pos="0 0 0" axis="1 0 0" stiffness="100" damping="10" armature="0.02" range="-5.6250 5.6250" />
                          <joint name="R_Index3_y" type="hinge" pos="0 0 0" axis="0 1 0" stiffness="100" damping="10" armature="0.02" range="-5.6250 5.6250" />
                          <joint name="R_Index3_z" type="hinge" pos="0 0 0" axis="0 0 1" stiffness="100" damping="10" armature="0.02" range="-5.6250 90.0000" />
                          <geom type="capsule" contype="1" conaffinity="1" density="1000" fromto="-0.0049 -0.0003 0.0001 -0.0169 -0.0011 0.0004" size="0.0048" />
                        </body>
                      </body>
                    </body>
                    <body name="R_Middle1" pos="-0.1038 -0.0114 -0.0001">
                      <joint name="R_Middle1_x" type="hinge" pos="0 0 0" axis="1 0 0" stiffness="100" damping="10" armature="0.02" range="-5.6250 5.6250" />
                      <joint name="R_Middle1_y" type="hinge" pos="0 0 0" axis="0 1 0" stiffness="100" damping="10" armature="0.02" range="-5.6250 5.6250" />
                      <joint name="R_Middle1_z" type="hinge" pos="0 0 0" axis="0 0 1" stiffness="100" damping="10" armature="0.02" range="-55.6250 55.6250" />
                      <geom type="capsule" contype="1" conaffinity="1" density="1000" fromto="-0.0059 0.0003 -0.0007 -0.0234 0.0011 -0.0028" size="0.0067" />
                      <body name="R_Middle2" pos="-0.0293 0.0014 -0.0036">
                        <joint name="R_Middle2_x" type="hinge" pos="0 0 0" axis="1 0 0" stiffness="100" damping="10" armature="0.02" range="-5.6250 5.6250" />
                        <joint name="R_Middle2_y" type="hinge" pos="0 0 0" axis="0 1 0" stiffness="100" damping="10" armature="0.02" range="-5.6250 5.6250" />
                        <joint name="R_Middle2_z" type="hinge" pos="0 0 0" axis="0 0 1" stiffness="100" damping="10" armature="0.02" range="-55.6250 55.6250" />
                        <geom type="capsule" contype="1" conaffinity="1" density="1000" fromto="-0.0046 -0.0001 -0.0007 -0.0182 -0.0005 -0.0028" size="0.0050" />
                        <body name="R_Middle3" pos="-0.0228 -0.0006 -0.0035">
                          <joint name="R_Middle3_x" type="hinge" pos="0 0 0" axis="1 0 0" stiffness="100" damping="10" armature="0.02" range="-5.6250 5.6250" />
                          <joint name="R_Middle3_y" type="hinge" pos="0 0 0" axis="0 1 0" stiffness="100" damping="10" armature="0.02" range="-5.6250 5.6250" />
                          <joint name="R_Middle3_z" type="hinge" pos="0 0 0" axis="0 0 1" stiffness="100" damping="10" armature="0.02" range="-5.6250 90.0000" />
                          <geom type="capsule" contype="1" conaffinity="1" density="1000" fromto="-0.0050 -0.0001 -0.0008 -0.0177 -0.0005 -0.0027" size="0.0045" />
                        </body>
                      </body>
                    </body>
                    <body name="R_Pinky1" pos="-0.0789 -0.0187 -0.0386">
                      <joint name="R_Pinky1_x" type="hinge" pos="0 0 0" axis="1 0 0" stiffness="100" damping="10" armature="0.02" range="-5.6250 5.6250" />
                      <joint name="R_Pinky1_y" type="hinge" pos="0 0 0" axis="0 1 0" stiffness="100" damping="10" armature="0.02" range="-5.6250 5.6250" />
                      <joint name="R_Pinky1_z" type="hinge" pos="0 0 0" axis="0 0 1" stiffness="100" damping="10" armature="0.02" range="-55.6250 55.6250" />
                      <geom type="capsule" contype="1" conaffinity="1" density="1000" fromto="-0.0029 -0.0001 -0.0024 -0.0115 -0.0004 -0.0095" size="0.0050" />
                      <body name="R_Pinky2" pos="-0.0143 -0.0005 -0.0119">
                        <joint name="R_Pinky2_x" type="hinge" pos="0 0 0" axis="1 0 0" stiffness="100" damping="10" armature="0.02" range="-5.6250 5.6250" />
                        <joint name="R_Pinky2_y" type="hinge" pos="0 0 0" axis="0 1 0" stiffness="100" damping="10" armature="0.02" range="-5.6250 5.6250" />
                        <joint name="R_Pinky2_z" type="hinge" pos="0 0 0" axis="0 0 1" stiffness="100" damping="10" armature="0.02" range="-55.6250 55.6250" />
                        <geom type="capsule" contype="1" conaffinity="1" density="1000" fromto="-0.0029 -0.0002 -0.0023 -0.0116 -0.0007 -0.0093" size="0.0045" />
                        <body name="R_Pinky3" pos="-0.0145 -0.0009 -0.0116">
                          <joint name="R_Pinky3_x" type="hinge" pos="0 0 0" axis="1 0 0" stiffness="100" damping="10" armature="0.02" range="-5.6250 5.6250" />
                          <joint name="R_Pinky3_y" type="hinge" pos="0 0 0" axis="0 1 0" stiffness="100" damping="10" armature="0.02" range="-5.6250 5.6250" />
                          <joint name="R_Pinky3_z" type="hinge" pos="0 0 0" axis="0 0 1" stiffness="100" damping="10" armature="0.02" range="-5.6250 90.0000" />
                          <geom type="capsule" contype="1" conaffinity="1" density="1000" fromto="-0.0033 -0.0002 -0.0026 -0.0112 -0.0007 -0.0089" size="0.0036" />
                        </body>
                      </body>
                    </body>
                    <body name="R_Ring1" pos="-0.0920 -0.0138 -0.0227">
                      <joint name="R_Ring1_x" type="hinge" pos="0 0 0" axis="1 0 0" stiffness="100" damping="10" armature="0.02" range="-5.6250 5.6250" />
                      <joint name="R_Ring1_y" type="hinge" pos="0 0 0" axis="0 1 0" stiffness="100" damping="10" armature="0.02" range="-5.6250 5.6250" />
                      <joint name="R_Ring1_z" type="hinge" pos="0 0 0" axis="0 0 1" stiffness="100" damping="10" armature="0.02" range="-55.6250 55.6250" />
                      <geom type="capsule" contype="1" conaffinity="1" density="1000" fromto="-0.0054 0.0003 -0.0010 -0.0215 0.0013 -0.0041" size="0.0057" />
                      <body name="R_Ring2" pos="-0.0268 0.0016 -0.0052">
                        <joint name="R_Ring2_x" type="hinge" pos="0 0 0" axis="1 0 0" stiffness="100" damping="10" armature="0.02" range="-5.6250 5.6250" />
                        <joint name="R_Ring2_y" type="hinge" pos="0 0 0" axis="0 1 0" stiffness="100" damping="10" armature="0.02" range="-5.6250 5.6250" />
                        <joint name="R_Ring2_z" type="hinge" pos="0 0 0" axis="0 0 1" stiffness="100" damping="10" armature="0.02" range="-55.6250 55.6250" />
                        <geom type="capsule" contype="1" conaffinity="1" density="1000" fromto="-0.0044 -0.0002 -0.0014 -0.0176 -0.0008 -0.0056" size="0.0051" />
                        <body name="R_Ring3" pos="-0.0219 -0.0010 -0.0070">
                          <joint name="R_Ring3_x" type="hinge" pos="0 0 0" axis="1 0 0" stiffness="100" damping="10" armature="0.02" range="-5.6250 5.6250" />
                          <joint name="R_Ring3_y" type="hinge" pos="0 0 0" axis="0 1 0" stiffness="100" damping="10" armature="0.02" range="-5.6250 5.6250" />
                          <joint name="R_Ring3_z" type="hinge" pos="0 0 0" axis="0 0 1" stiffness="100" damping="10" armature="0.02" range="-5.6250 90.0000" />
                          <geom type="capsule" contype="1" conaffinity="1" density="1000" fromto="-0.0048 -0.0002 -0.0015 -0.0171 -0.0008 -0.0055" size="0.0043" />
                        </body>
                      </body>
                    </body>
                    <body name="R_Thumb1" pos="-0.0394 -0.0217 0.0278">
                      <joint name="R_Thumb1_x" type="hinge" pos="0 0 0" axis="1 0 0" stiffness="100" damping="10" armature="0.02" range="-55.6250 55.6250" />
                      <joint name="R_Thumb1_y" type="hinge" pos="0 0 0" axis="0 1 0" stiffness="100" damping="10" armature="0.02" range="-55.6250 55.6250" />
                      <joint name="R_Thumb1_z" type="hinge" pos="0 0 0" axis="0 0 1" stiffness="100" damping="10" armature="0.02" range="-55.6250 55.6250" />
                      <geom type="capsule" contype="1" conaffinity="1" density="1000" fromto="-0.0033 0.0002 0.0047 -0.0133 0.0008 0.0188" size="0.0086" />
                      <body name="R_Thumb2" pos="-0.0166 0.0010 0.0235">
                        <joint name="R_Thumb2_x" type="hinge" pos="0 0 0" axis="1 0 0" stiffness="100" damping="10" armature="0.02" range="-5.6250 5.6250" />
                        <joint name="R_Thumb2_y" type="hinge" pos="0 0 0" axis="0 1 0" stiffness="100" damping="10" armature="0.02" range="-5.6250 5.6250" />
                        <joint name="R_Thumb2_z" type="hinge" pos="0 0 0" axis="0 0 1" stiffness="100" damping="10" armature="0.02" range="-5.6250 5.6250" />
                        <geom type="capsule" contype="1" conaffinity="1" density="1000" fromto="-0.0039 -0.0011 0.0028 -0.0157 -0.0046 0.0112" size="0.0065" />
                        <body name="R_Thumb3" pos="-0.0196 -0.0057 0.0141">
                          <joint name="R_Thumb3_x" type="hinge" pos="0 0 0" axis="1 0 0" stiffness="100" damping="10" armature="0.02" range="-5.6250 5.6250" />
                          <joint name="R_Thumb3_y" type="hinge" pos="0 0 0" axis="0 1 0" stiffness="100" damping="10" armature="0.02" range="-5.6250 5.6250" />
                          <joint name="R_Thumb3_z" type="hinge" pos="0 0 0" axis="0 0 1" stiffness="100" damping="10" armature="0.02" range="-5.6250 90.0000" />
                          <geom type="capsule" contype="1" conaffinity="1" density="1000" fromto="-0.0041 -0.0012 0.0029 -0.0155 -0.0045 0.0111" size="0.0064" />
                        </body>
                      </body>
                    </body>
                  </body>
                </body>
              </body>
            </body>
          </body>
        </body>
      </body>
    </body>
  </worldbody>
  <actuator>
    <motor name="L_Hip_x" joint="L_Hip_x" gear="1" />
    <motor name="L_Hip_y" joint="L_Hip_y" gear="1" />
    <motor name="L_Hip_z" joint="L_Hip_z" gear="1" />
    <motor name="L_Knee_x" joint="L_Knee_x" gear="1" />
    <motor name="L_Knee_y" joint="L_Knee_y" gear="1" />
    <motor name="L_Knee_z" joint="L_Knee_z" gear="1" />
    <motor name="L_Ankle_x" joint="L_Ankle_x" gear="1" />
    <motor name="L_Ankle_y" joint="L_Ankle_y" gear="1" />
    <motor name="L_Ankle_z" joint="L_Ankle_z" gear="1" />
    <motor name="L_Toe_x" joint="L_Toe_x" gear="1" />
    <motor name="L_Toe_y" joint="L_Toe_y" gear="1" />
    <motor name="L_Toe_z" joint="L_Toe_z" gear="1" />
    <motor name="R_Hip_x" joint="R_Hip_x" gear="1" />
    <motor name="R_Hip_y" joint="R_Hip_y" gear="1" />
    <motor name="R_Hip_z" joint="R_Hip_z" gear="1" />
    <motor name="R_Knee_x" joint="R_Knee_x" gear="1" />
    <motor name="R_Knee_y" joint="R_Knee_y" gear="1" />
    <motor name="R_Knee_z" joint="R_Knee_z" gear="1" />
    <motor name="R_Ankle_x" joint="R_Ankle_x" gear="1" />
    <motor name="R_Ankle_y" joint="R_Ankle_y" gear="1" />
    <motor name="R_Ankle_z" joint="R_Ankle_z" gear="1" />
    <motor name="R_Toe_x" joint="R_Toe_x" gear="1" />
    <motor name="R_Toe_y" joint="R_Toe_y" gear="1" />
    <motor name="R_Toe_z" joint="R_Toe_z" gear="1" />
    <motor name="Torso_x" joint="Torso_x" gear="1" />
    <motor name="Torso_y" joint="Torso_y" gear="1" />
    <motor name="Torso_z" joint="Torso_z" gear="1" />
    <motor name="Spine_x" joint="Spine_x" gear="1" />
    <motor name="Spine_y" joint="Spine_y" gear="1" />
    <motor name="Spine_z" joint="Spine_z" gear="1" />
    <motor name="Chest_x" joint="Chest_x" gear="1" />
    <motor name="Chest_y" joint="Chest_y" gear="1" />
    <motor name="Chest_z" joint="Chest_z" gear="1" />
    <motor name="Neck_x" joint="Neck_x" gear="1" />
    <motor name="Neck_y" joint="Neck_y" gear="1" />
    <motor name="Neck_z" joint="Neck_z" gear="1" />
    <motor name="Head_x" joint="Head_x" gear="1" />
    <motor name="Head_y" joint="Head_y" gear="1" />
    <motor name="Head_z" joint="Head_z" gear="1" />
    <motor name="L_Thorax_x" joint="L_Thorax_x" gear="1" />
    <motor name="L_Thorax_y" joint="L_Thorax_y" gear="1" />
    <motor name="L_Thorax_z" joint="L_Thorax_z" gear="1" />
    <motor name="L_Shoulder_x" joint="L_Shoulder_x" gear="1" />
    <motor name="L_Shoulder_y" joint="L_Shoulder_y" gear="1" />
    <motor name="L_Shoulder_z" joint="L_Shoulder_z" gear="1" />
    <motor name="L_Elbow_x" joint="L_Elbow_x" gear="1" />
    <motor name="L_Elbow_y" joint="L_Elbow_y" gear="1" />
    <motor name="L_Elbow_z" joint="L_Elbow_z" gear="1" />
    <motor name="L_Wrist_x" joint="L_Wrist_x" gear="1" />
    <motor name="L_Wrist_y" joint="L_Wrist_y" gear="1" />
    <motor name="L_Wrist_z" joint="L_Wrist_z" gear="1" />
    <motor name="L_Index1_x" joint="L_Index1_x" gear="1" />
    <motor name="L_Index1_y" joint="L_Index1_y" gear="1" />
    <motor name="L_Index1_z" joint="L_Index1_z" gear="1" />
    <motor name="L_Index2_x" joint="L_Index2_x" gear="1" />
    <motor name="L_Index2_y" joint="L_Index2_y" gear="1" />
    <motor name="L_Index2_z" joint="L_Index2_z" gear="1" />
    <motor name="L_Index3_x" joint="L_Index3_x" gear="1" />
    <motor name="L_Index3_y" joint="L_Index3_y" gear="1" />
    <motor name="L_Index3_z" joint="L_Index3_z" gear="1" />
    <motor name="L_Middle1_x" joint="L_Middle1_x" gear="1" />
    <motor name="L_Middle1_y" joint="L_Middle1_y" gear="1" />
    <motor name="L_Middle1_z" joint="L_Middle1_z" gear="1" />
    <motor name="L_Middle2_x" joint="L_Middle2_x" gear="1" />
    <motor name="L_Middle2_y" joint="L_Middle2_y" gear="1" />
    <motor name="L_Middle2_z" joint="L_Middle2_z" gear="1" />
    <motor name="L_Middle3_x" joint="L_Middle3_x" gear="1" />
    <motor name="L_Middle3_y" joint="L_Middle3_y" gear="1" />
    <motor name="L_Middle3_z" joint="L_Middle3_z" gear="1" />
    <motor name="L_Pinky1_x" joint="L_Pinky1_x" gear="1" />
    <motor name="L_Pinky1_y" joint="L_Pinky1_y" gear="1" />
    <motor name="L_Pinky1_z" joint="L_Pinky1_z" gear="1" />
    <motor name="L_Pinky2_x" joint="L_Pinky2_x" gear="1" />
    <motor name="L_Pinky2_y" joint="L_Pinky2_y" gear="1" />
    <motor name="L_Pinky2_z" joint="L_Pinky2_z" gear="1" />
    <motor name="L_Pinky3_x" joint="L_Pinky3_x" gear="1" />
    <motor name="L_Pinky3_y" joint="L_Pinky3_y" gear="1" />
    <motor name="L_Pinky3_z" joint="L_Pinky3_z" gear="1" />
    <motor name="L_Ring1_x" joint="L_Ring1_x" gear="1" />
    <motor name="L_Ring1_y" joint="L_Ring1_y" gear="1" />
    <motor name="L_Ring1_z" joint="L_Ring1_z" gear="1" />
    <motor name="L_Ring2_x" joint="L_Ring2_x" gear="1" />
    <motor name="L_Ring2_y" joint="L_Ring2_y" gear="1" />
    <motor name="L_Ring2_z" joint="L_Ring2_z" gear="1" />
    <motor name="L_Ring3_x" joint="L_Ring3_x" gear="1" />
    <motor name="L_Ring3_y" joint="L_Ring3_y" gear="1" />
    <motor name="L_Ring3_z" joint="L_Ring3_z" gear="1" />
    <motor name="L_Thumb1_x" joint="L_Thumb1_x" gear="1" />
    <motor name="L_Thumb1_y" joint="L_Thumb1_y" gear="1" />
    <motor name="L_Thumb1_z" joint="L_Thumb1_z" gear="1" />
    <motor name="L_Thumb2_x" joint="L_Thumb2_x" gear="1" />
    <motor name="L_Thumb2_y" joint="L_Thumb2_y" gear="1" />
    <motor name="L_Thumb2_z" joint="L_Thumb2_z" gear="1" />
    <motor name="L_Thumb3_x" joint="L_Thumb3_x" gear="1" />
    <motor name="L_Thumb3_y" joint="L_Thumb3_y" gear="1" />
    <motor name="L_Thumb3_z" joint="L_Thumb3_z" gear="1" />
    <motor name="R_Thorax_x" joint="R_Thorax_x" gear="1" />
    <motor name="R_Thorax_y" joint="R_Thorax_y" gear="1" />
    <motor name="R_Thorax_z" joint="R_Thorax_z" gear="1" />
    <motor name="R_Shoulder_x" joint="R_Shoulder_x" gear="1" />
    <motor name="R_Shoulder_y" joint="R_Shoulder_y" gear="1" />
    <motor name="R_Shoulder_z" joint="R_Shoulder_z" gear="1" />
    <motor name="R_Elbow_x" joint="R_Elbow_x" gear="1" />
    <motor name="R_Elbow_y" joint="R_Elbow_y" gear="1" />
    <motor name="R_Elbow_z" joint="R_Elbow_z" gear="1" />
    <motor name="R_Wrist_x" joint="R_Wrist_x" gear="1" />
    <motor name="R_Wrist_y" joint="R_Wrist_y" gear="1" />
    <motor name="R_Wrist_z" joint="R_Wrist_z" gear="1" />
    <motor name="R_Index1_x" joint="R_Index1_x" gear="1" />
    <motor name="R_Index1_y" joint="R_Index1_y" gear="1" />
    <motor name="R_Index1_z" joint="R_Index1_z" gear="1" />
    <motor name="R_Index2_x" joint="R_Index2_x" gear="1" />
    <motor name="R_Index2_y" joint="R_Index2_y" gear="1" />
    <motor name="R_Index2_z" joint="R_Index2_z" gear="1" />
    <motor name="R_Index3_x" joint="R_Index3_x" gear="1" />
    <motor name="R_Index3_y" joint="R_Index3_y" gear="1" />
    <motor name="R_Index3_z" joint="R_Index3_z" gear="1" />
    <motor name="R_Middle1_x" joint="R_Middle1_x" gear="1" />
    <motor name="R_Middle1_y" joint="R_Middle1_y" gear="1" />
    <motor name="R_Middle1_z" joint="R_Middle1_z" gear="1" />
    <motor name="R_Middle2_x" joint="R_Middle2_x" gear="1" />
    <motor name="R_Middle2_y" joint="R_Middle2_y" gear="1" />
    <motor name="R_Middle2_z" joint="R_Middle2_z" gear="1" />
    <motor name="R_Middle3_x" joint="R_Middle3_x" gear="1" />
    <motor name="R_Middle3_y" joint="R_Middle3_y" gear="1" />
    <motor name="R_Middle3_z" joint="R_Middle3_z" gear="1" />
    <motor name="R_Pinky1_x" joint="R_Pinky1_x" gear="1" />
    <motor name="R_Pinky1_y" joint="R_Pinky1_y" gear="1" />
    <motor name="R_Pinky1_z" joint="R_Pinky1_z" gear="1" />
    <motor name="R_Pinky2_x" joint="R_Pinky2_x" gear="1" />
    <motor name="R_Pinky2_y" joint="R_Pinky2_y" gear="1" />
    <motor name="R_Pinky2_z" joint="R_Pinky2_z" gear="1" />
    <motor name="R_Pinky3_x" joint="R_Pinky3_x" gear="1" />
    <motor name="R_Pinky3_y" joint="R_Pinky3_y" gear="1" />
    <motor name="R_Pinky3_z" joint="R_Pinky3_z" gear="1" />
    <motor name="R_Ring1_x" joint="R_Ring1_x" gear="1" />
    <motor name="R_Ring1_y" joint="R_Ring1_y" gear="1" />
    <motor name="R_Ring1_z" joint="R_Ring1_z" gear="1" />
    <motor name="R_Ring2_x" joint="R_Ring2_x" gear="1" />
    <motor name="R_Ring2_y" joint="R_Ring2_y" gear="1" />
    <motor name="R_Ring2_z" joint="R_Ring2_z" gear="1" />
    <motor name="R_Ring3_x" joint="R_Ring3_x" gear="1" />
    <motor name="R_Ring3_y" joint="R_Ring3_y" gear="1" />
    <motor name="R_Ring3_z" joint="R_Ring3_z" gear="1" />
    <motor name="R_Thumb1_x" joint="R_Thumb1_x" gear="1" />
    <motor name="R_Thumb1_y" joint="R_Thumb1_y" gear="1" />
    <motor name="R_Thumb1_z" joint="R_Thumb1_z" gear="1" />
    <motor name="R_Thumb2_x" joint="R_Thumb2_x" gear="1" />
    <motor name="R_Thumb2_y" joint="R_Thumb2_y" gear="1" />
    <motor name="R_Thumb2_z" joint="R_Thumb2_z" gear="1" />
    <motor name="R_Thumb3_x" joint="R_Thumb3_x" gear="1" />
    <motor name="R_Thumb3_y" joint="R_Thumb3_y" gear="1" />
    <motor name="R_Thumb3_z" joint="R_Thumb3_z" gear="1" />
  </actuator>
  <contact />
  <sensor />
  <size njmax="700" nconmax="700" />
</mujoco>
