<?xml version='1.0' encoding='utf-8'?>
<mujoco model="smplx_mapped_s110">
  <compiler coordinate="local" />
  <default>
    <joint damping="0.0" armature="0.01" stiffness="0.0" limited="true" />
    <geom conaffinity="1" condim="3" contype="7" margin="0.001" rgba="0.8 0.6 .4 1" />
  </default>
  <asset>
    <texture type="skybox" builtin="gradient" rgb1=".4 .5 .6" rgb2="0 0 0" width="100" height="100" />
    <texture builtin="flat" height="1278" mark="cross" markrgb="1 1 1" name="texgeom" random="0.01" rgb1="0.8 0.6 0.4" rgb2="0.8 0.6 0.4" type="cube" width="127" />
    <texture builtin="checker" height="100" name="texplane" rgb1="0 0 0" rgb2="0.8 0.8 0.8" type="2d" width="100" />
    <material name="MatPlane" reflectance="0.5" shininess="1" specular="1" texrepeat="60 60" texture="texplane" />
    <material name="geom" texture="texgeom" texuniform="true" />
  </asset>
  <worldbody>
    <light cutoff="100" diffuse="1 1 1" dir="-0 0 -1.3" directional="true" exponent="1" pos="0 0 1.3" specular=".1 .1 .1" />
    <geom conaffinity="1" condim="3" name="floor" pos="0 0 0" rgba="0.8 0.9 0.8 1" size="100 100 .2" type="plane" material="MatPlane" />
    <body name="Pelvis" pos="0.0006 -0.3115 0.0031">
      <freejoint name="Pelvis" />
      <geom type="sphere" contype="1" conaffinity="1" density="4629.6296296296305" size="0.09" pos="0.0000 0.0000 0.0000" name="Pelvis" />
      <body name="L_Hip" pos="0.0666 -0.0820 -0.0142">
        <joint name="L_Hip_x" type="hinge" pos="0 0 0" axis="1 0 0" stiffness="800" damping="80" armature="0.02" range="-180.00 180.00" />
        <joint name="L_Hip_y" type="hinge" pos="0 0 0" axis="0 1 0" stiffness="800" damping="80" armature="0.02" range="-180.00 180.00" />
        <joint name="L_Hip_z" type="hinge" pos="0 0 0" axis="0 0 1" stiffness="800" damping="80" armature="0.02" range="-180.00 180.00" />
        <geom type="capsule" contype="1" conaffinity="1" density="2040.816327" fromto="0.0071 -0.0730 -0.0027 0.0285 -0.2921 -0.0109" size="0.059" />
        <body name="L_Knee" pos="0.0357 -0.3652 -0.0136">
          <joint name="L_Knee_x" type="hinge" pos="0 0 0" axis="1 0 0" stiffness="800" damping="80" armature="0.02" range="-180.00 180.00" />
          <joint name="L_Knee_y" type="hinge" pos="0 0 0" axis="0 1 0" stiffness="800" damping="80" armature="0.02" range="-180.00 180.00" />
          <joint name="L_Knee_z" type="hinge" pos="0 0 0" axis="0 0 1" stiffness="800" damping="80" armature="0.02" range="-180.00 180.00" />
          <geom type="capsule" contype="1" conaffinity="1" density="1234.567901" fromto="-0.0013 -0.0767 -0.0036 -0.0051 -0.3068 -0.0144" size="0.0564" />
          <body name="L_Ankle" pos="-0.0064 -0.3835 -0.0180">
            <joint name="L_Ankle_x" type="hinge" pos="0 0 0" axis="1 0 0" stiffness="800" damping="80" armature="0.02" range="-180.00 180.00" />
            <joint name="L_Ankle_y" type="hinge" pos="0 0 0" axis="0 1 0" stiffness="800" damping="80" armature="0.02" range="-180.00 180.00" />
            <joint name="L_Ankle_z" type="hinge" pos="0 0 0" axis="0 0 1" stiffness="800" damping="80" armature="0.02" range="-180.00 180.00" />
            <geom type="box" contype="1" conaffinity="1" density="1000" pos="0.0115 -0.0234 0.0566" size="0.0502 0.0216 0.0909" quat="1.0000 0.0000 0.0000 0.0000" />
            <body name="L_Toe" pos="0.0201 -0.0445 0.1067">
              <joint name="L_Toe_x" type="hinge" pos="0 0 0" axis="1 0 0" stiffness="500" damping="50" armature="0.02" range="-180.00 180.00" />
              <joint name="L_Toe_y" type="hinge" pos="0 0 0" axis="0 1 0" stiffness="500" damping="50" armature="0.02" range="-180.00 180.00" />
              <joint name="L_Toe_z" type="hinge" pos="0 0 0" axis="0 0 1" stiffness="500" damping="50" armature="0.02" range="-180.00 180.00" />
              <geom type="box" contype="1" conaffinity="1" density="1000" pos="-0.0115 0.0227 0.0576" size="0.0493 0.0209 0.0194" quat="1.0000 0.0000 0.0000 0.0000" />
            </body>
          </body>
        </body>
      </body>
      <body name="R_Hip" pos="-0.0659 -0.0882 -0.0152">
        <joint name="R_Hip_x" type="hinge" pos="0 0 0" axis="1 0 0" stiffness="800" damping="80" armature="0.02" range="-180.00 180.00" />
        <joint name="R_Hip_y" type="hinge" pos="0 0 0" axis="0 1 0" stiffness="800" damping="80" armature="0.02" range="-180.00 180.00" />
        <joint name="R_Hip_z" type="hinge" pos="0 0 0" axis="0 0 1" stiffness="800" damping="80" armature="0.02" range="-180.00 180.00" />
        <geom type="capsule" contype="1" conaffinity="1" density="2040.816327" fromto="-0.0079 -0.0722 -0.0017 -0.0318 -0.2889 -0.0066" size="0.0588" />
        <body name="R_Knee" pos="-0.0397 -0.3611 -0.0083">
          <joint name="R_Knee_x" type="hinge" pos="0 0 0" axis="1 0 0" stiffness="800" damping="80" armature="0.02" range="-180.00 180.00" />
          <joint name="R_Knee_y" type="hinge" pos="0 0 0" axis="0 1 0" stiffness="800" damping="80" armature="0.02" range="-180.00 180.00" />
          <joint name="R_Knee_z" type="hinge" pos="0 0 0" axis="0 0 1" stiffness="800" damping="80" armature="0.02" range="-180.00 180.00" />
          <geom type="capsule" contype="1" conaffinity="1" density="1234.567901" fromto="0.0004 -0.0750 -0.0027 0.0015 -0.3001 -0.0110" size="0.0564" />
          <body name="R_Ankle" pos="0.0019 -0.3752 -0.0137">
            <joint name="R_Ankle_x" type="hinge" pos="0 0 0" axis="1 0 0" stiffness="800" damping="80" armature="0.02" range="-180.00 180.00" />
            <joint name="R_Ankle_y" type="hinge" pos="0 0 0" axis="0 1 0" stiffness="800" damping="80" armature="0.02" range="-180.00 180.00" />
            <joint name="R_Ankle_z" type="hinge" pos="0 0 0" axis="0 0 1" stiffness="800" damping="80" armature="0.02" range="-180.00 180.00" />
            <geom type="box" contype="1" conaffinity="1" density="1000" pos="-0.0091 -0.0250 0.0535" size="0.0502 0.0216 0.0909" quat="1.0000 0.0000 0.0000 0.0000" />
            <body name="R_Toe" pos="-0.0161 -0.0479 0.1003">
              <joint name="R_Toe_x" type="hinge" pos="0 0 0" axis="1 0 0" stiffness="500" damping="50" armature="0.02" range="-180.00 180.00" />
              <joint name="R_Toe_y" type="hinge" pos="0 0 0" axis="0 1 0" stiffness="500" damping="50" armature="0.02" range="-180.00 180.00" />
              <joint name="R_Toe_z" type="hinge" pos="0 0 0" axis="0 0 1" stiffness="500" damping="50" armature="0.02" range="-180.00 180.00" />
              <geom type="box" contype="1" conaffinity="1" density="1000" pos="0.0091 0.0243 0.0545" size="0.0493 0.0209 0.0194" quat="1.0000 0.0000 0.0000 0.0000" />
            </body>
          </body>
        </body>
      </body>
      <body name="Torso" pos="-0.0053 0.0938 -0.0223">
        <joint name="Torso_x" type="hinge" pos="0 0 0" axis="1 0 0" stiffness="1000" damping="100" armature="0.02" range="-180.00 180.00" />
        <joint name="Torso_y" type="hinge" pos="0 0 0" axis="0 1 0" stiffness="1000" damping="100" armature="0.02" range="-180.00 180.00" />
        <joint name="Torso_z" type="hinge" pos="0 0 0" axis="0 0 1" stiffness="1000" damping="100" armature="0.02" range="-180.00 180.00" />
        <geom type="capsule" contype="1" conaffinity="1" density="1100" fromto="0.0041 0.0518 -0.0026 0.0050 0.0634 -0.0032" size="0.08" />
        <body name="Spine" pos="0.0091 0.1152 -0.0058">
          <joint name="Spine_x" type="hinge" pos="0 0 0" axis="1 0 0" stiffness="1000" damping="100" armature="0.02" range="-180.00 180.00" />
          <joint name="Spine_y" type="hinge" pos="0 0 0" axis="0 1 0" stiffness="1000" damping="100" armature="0.02" range="-180.00 180.00" />
          <joint name="Spine_z" type="hinge" pos="0 0 0" axis="0 0 1" stiffness="1000" damping="100" armature="0.02" range="-180.00 180.00" />
          <geom type="capsule" contype="1" conaffinity="1" density="1100" fromto="-0.0021 0.0197 0.0128 -0.0026 0.0240 0.0156" size="0.06" />
          <body name="Chest" pos="-0.0046 0.0437 0.0284">
            <joint name="Chest_x" type="hinge" pos="0 0 0" axis="1 0 0" stiffness="1000" damping="100" armature="0.02" range="-180.00 180.00" />
            <joint name="Chest_y" type="hinge" pos="0 0 0" axis="0 1 0" stiffness="1000" damping="100" armature="0.02" range="-180.00 180.00" />
            <joint name="Chest_z" type="hinge" pos="0 0 0" axis="0 0 1" stiffness="1000" damping="100" armature="0.02" range="-180.00 180.00" />
            <geom type="capsule" contype="1" conaffinity="1" density="1100" fromto="-0.0006 0.0256 -0.0038 -0.0023 0.1026 -0.0153" size="0.08" />
            <body name="Neck" pos="-0.0058 0.1764 -0.0304">
              <joint name="Neck_x" type="hinge" pos="0 0 0" axis="1 0 0" stiffness="500" damping="50" armature="0.02" range="-180.00 180.00" />
              <joint name="Neck_y" type="hinge" pos="0 0 0" axis="0 1 0" stiffness="500" damping="50" armature="0.02" range="-180.00 180.00" />
              <joint name="Neck_z" type="hinge" pos="0 0 0" axis="0 0 1" stiffness="500" damping="50" armature="0.02" range="-180.00 180.00" />
              <geom type="capsule" contype="1" conaffinity="1" density="1000" fromto="0.0040 0.0577 0.0061 0.0049 0.0705 0.0075" size="0.0437" />
              <body name="Head" pos="0.0089 0.1281 0.0136">
                <joint name="Head_x" type="hinge" pos="0 0 0" axis="1 0 0" stiffness="500" damping="50" armature="0.02" range="-180.00 180.00" />
                <joint name="Head_y" type="hinge" pos="0 0 0" axis="0 1 0" stiffness="500" damping="50" armature="0.02" range="-180.00 180.00" />
                <joint name="Head_z" type="hinge" pos="0 0 0" axis="0 0 1" stiffness="500" damping="50" armature="0.02" range="-180.00 180.00" />
                <geom type="sphere" contype="1" conaffinity="1" density="1000" size="0.1054" pos="0.0000 0.0000 0.0000" name="Head" />
              </body>
            </body>
            <body name="L_Thorax" pos="0.0512 0.1059 -0.0103">
              <joint name="L_Thorax_x" type="hinge" pos="0 0 0" axis="1 0 0" stiffness="500" damping="50" armature="0.02" range="-180.00 180.00" />
              <joint name="L_Thorax_y" type="hinge" pos="0 0 0" axis="0 1 0" stiffness="500" damping="50" armature="0.02" range="-180.00 180.00" />
              <joint name="L_Thorax_z" type="hinge" pos="0 0 0" axis="0 0 1" stiffness="500" damping="50" armature="0.02" range="-180.00 180.00" />
              <geom type="capsule" contype="1" conaffinity="1" density="1000" fromto="0.0179 0.0081 -0.0053 0.0718 0.0322 -0.0212" size="0.0564" />
              <body name="L_Shoulder" pos="0.0897 0.0403 -0.0265">
                <joint name="L_Shoulder_x" type="hinge" pos="0 0 0" axis="1 0 0" stiffness="500" damping="50" armature="0.02" range="-180.00 180.00" />
                <joint name="L_Shoulder_y" type="hinge" pos="0 0 0" axis="0 1 0" stiffness="500" damping="50" armature="0.02" range="-180.00 180.00" />
                <joint name="L_Shoulder_z" type="hinge" pos="0 0 0" axis="0 0 1" stiffness="500" damping="50" armature="0.02" range="-180.00 180.00" />
                <geom type="capsule" contype="1" conaffinity="1" density="1000" fromto="0.0542 -0.0110 -0.0058 0.2169 -0.0441 -0.0231" size="0.0533" />
                <body name="L_Elbow" pos="0.2711 -0.0552 -0.0289">
                  <joint name="L_Elbow_x" type="hinge" pos="0 0 0" axis="1 0 0" stiffness="500" damping="50" armature="0.02" range="-180.00 180.00" />
                  <joint name="L_Elbow_y" type="hinge" pos="0 0 0" axis="0 1 0" stiffness="500" damping="50" armature="0.02" range="-180.00 180.00" />
                  <joint name="L_Elbow_z" type="hinge" pos="0 0 0" axis="0 0 1" stiffness="500" damping="50" armature="0.02" range="-180.00 180.00" />
                  <geom type="capsule" contype="1" conaffinity="1" density="1000" fromto="0.0457 0.0016 0.0011 0.1827 0.0062 0.0042" size="0.0418" />
                  <body name="L_Wrist" pos="0.2283 0.0078 0.0053">
                    <joint name="L_Wrist_x" type="hinge" pos="0 0 0" axis="1 0 0" stiffness="300" damping="30" armature="0.02" range="-180.00 180.00" />
                    <joint name="L_Wrist_y" type="hinge" pos="0 0 0" axis="0 1 0" stiffness="300" damping="30" armature="0.02" range="-180.00 180.00" />
                    <joint name="L_Wrist_z" type="hinge" pos="0 0 0" axis="0 0 1" stiffness="300" damping="30" armature="0.02" range="-180.00 180.00" />
                    <geom type="box" contype="1" conaffinity="1" density="1000" pos="0.0456 -0.0084 -0.0022" size="0.0444 0.0076 0.0414" quat="1.0000 0.0000 0.0000 0.0000" />
                    <body name="L_Index1" pos="0.1014 -0.0138 0.0212">
                      <joint name="L_Index1_x" type="hinge" pos="0 0 0" axis="1 0 0" stiffness="100" damping="10" armature="0.02" range="-26.43 15.87" />
                      <joint name="L_Index1_y" type="hinge" pos="0 0 0" axis="0 1 0" stiffness="100" damping="10" armature="0.02" range="-10.11 45.81" />
                      <joint name="L_Index1_z" type="hinge" pos="0 0 0" axis="0 0 1" stiffness="100" damping="10" armature="0.02" range="-102.47 24.92" />
                      <geom type="capsule" contype="1" conaffinity="1" density="1000" fromto="0.0062 0.0005 0.0006 0.0249 0.0022 0.0023" size="0.0065" />
                      <body name="L_Index2" pos="0.0312 0.0027 0.0028">
                        <joint name="L_Index2_x" type="hinge" pos="0 0 0" axis="1 0 0" stiffness="100" damping="10" armature="0.02" range="-19.26 13.31" />
                        <joint name="L_Index2_y" type="hinge" pos="0 0 0" axis="0 1 0" stiffness="100" damping="10" armature="0.02" range="-11.86 16.86" />
                        <joint name="L_Index2_z" type="hinge" pos="0 0 0" axis="0 0 1" stiffness="100" damping="10" armature="0.02" range="-118.52 10.65" />
                        <geom type="capsule" contype="1" conaffinity="1" density="1000" fromto="0.0044 -0.0003 0.0001 0.0177 -0.0011 0.0004" size="0.0053" />
                        <body name="L_Index3" pos="0.0221 -0.0014 0.0005">
                          <joint name="L_Index3_x" type="hinge" pos="0 0 0" axis="1 0 0" stiffness="100" damping="10" armature="0.02" range="-20.20 16.66" />
                          <joint name="L_Index3_y" type="hinge" pos="0 0 0" axis="0 1 0" stiffness="100" damping="10" armature="0.02" range="-13.83 17.70" />
                          <joint name="L_Index3_z" type="hinge" pos="0 0 0" axis="0 0 1" stiffness="100" damping="10" armature="0.02" range="-77.62 46.42" />
                          <geom type="capsule" contype="1" conaffinity="1" density="1000" fromto="0.0047 -0.0003 0.0001 0.0174 -0.0011 0.0004" size="0.0047" />
                        </body>
                      </body>
                    </body>
                    <body name="L_Middle1" pos="0.1083 -0.0114 -0.0012">
                      <joint name="L_Middle1_x" type="hinge" pos="0 0 0" axis="1 0 0" stiffness="100" damping="10" armature="0.02" range="-66.16 21.01" />
                      <joint name="L_Middle1_y" type="hinge" pos="0 0 0" axis="0 1 0" stiffness="100" damping="10" armature="0.02" range="-122.07 55.56" />
                      <joint name="L_Middle1_z" type="hinge" pos="0 0 0" axis="0 0 1" stiffness="100" damping="10" armature="0.02" range="-105.63 35.41" />
                      <geom type="capsule" contype="1" conaffinity="1" density="1000" fromto="0.0060 0.0003 -0.0007 0.0239 0.0010 -0.0030" size="0.0067" />
                      <body name="L_Middle2" pos="0.0298 0.0013 -0.0037">
                        <joint name="L_Middle2_x" type="hinge" pos="0 0 0" axis="1 0 0" stiffness="100" damping="10" armature="0.02" range="-18.32 32.55" />
                        <joint name="L_Middle2_y" type="hinge" pos="0 0 0" axis="0 1 0" stiffness="100" damping="10" armature="0.02" range="-119.36 20.27" />
                        <joint name="L_Middle2_z" type="hinge" pos="0 0 0" axis="0 0 1" stiffness="100" damping="10" armature="0.02" range="-110.05 84.93" />
                        <geom type="capsule" contype="1" conaffinity="1" density="1000" fromto="0.0046 -0.0001 -0.0007 0.0186 -0.0005 -0.0029" size="0.0050" />
                        <body name="L_Middle3" pos="0.0232 -0.0006 -0.0036">
                          <joint name="L_Middle3_x" type="hinge" pos="0 0 0" axis="1 0 0" stiffness="100" damping="10" armature="0.02" range="-21.68 17.60" />
                          <joint name="L_Middle3_y" type="hinge" pos="0 0 0" axis="0 1 0" stiffness="100" damping="10" armature="0.02" range="-16.36 21.36" />
                          <joint name="L_Middle3_z" type="hinge" pos="0 0 0" axis="0 0 1" stiffness="100" damping="10" armature="0.02" range="-74.20 59.13" />
                          <geom type="capsule" contype="1" conaffinity="1" density="1000" fromto="0.0049 -0.0001 -0.0008 0.0183 -0.0005 -0.0029" size="0.0045" />
                        </body>
                      </body>
                    </body>
                    <body name="L_Pinky1" pos="0.0829 -0.0188 -0.0401">
                      <joint name="L_Pinky1_x" type="hinge" pos="0 0 0" axis="1 0 0" stiffness="100" damping="10" armature="0.02" range="-76.15 39.92" />
                      <joint name="L_Pinky1_y" type="hinge" pos="0 0 0" axis="0 1 0" stiffness="100" damping="10" armature="0.02" range="-44.67 54.79" />
                      <joint name="L_Pinky1_z" type="hinge" pos="0 0 0" axis="0 0 1" stiffness="100" damping="10" armature="0.02" range="-129.07 40.40" />
                      <geom type="capsule" contype="1" conaffinity="1" density="1000" fromto="0.0029 -0.0001 -0.0025 0.0117 -0.0004 -0.0098" size="0.0050" />
                      <body name="L_Pinky2" pos="0.0146 -0.0004 -0.0123">
                        <joint name="L_Pinky2_x" type="hinge" pos="0 0 0" axis="1 0 0" stiffness="100" damping="10" armature="0.02" range="-19.74 16.94" />
                        <joint name="L_Pinky2_y" type="hinge" pos="0 0 0" axis="0 1 0" stiffness="100" damping="10" armature="0.02" range="-14.61 14.69" />
                        <joint name="L_Pinky2_z" type="hinge" pos="0 0 0" axis="0 0 1" stiffness="100" damping="10" armature="0.02" range="-121.53 9.94" />
                        <geom type="capsule" contype="1" conaffinity="1" density="1000" fromto="0.0030 -0.0002 -0.0024 0.0118 -0.0007 -0.0095" size="0.0045" />
                        <body name="L_Pinky3" pos="0.0148 -0.0009 -0.0118">
                          <joint name="L_Pinky3_x" type="hinge" pos="0 0 0" axis="1 0 0" stiffness="100" damping="10" armature="0.02" range="-19.05 21.74" />
                          <joint name="L_Pinky3_y" type="hinge" pos="0 0 0" axis="0 1 0" stiffness="100" damping="10" armature="0.02" range="-14.04 15.02" />
                          <joint name="L_Pinky3_z" type="hinge" pos="0 0 0" axis="0 0 1" stiffness="100" damping="10" armature="0.02" range="-80.82 10.05" />
                          <geom type="capsule" contype="1" conaffinity="1" density="1000" fromto="0.0032 -0.0002 -0.0026 0.0115 -0.0007 -0.0093" size="0.0036" />
                        </body>
                      </body>
                    </body>
                    <body name="L_Ring1" pos="0.0962 -0.0138 -0.0240">
                      <joint name="L_Ring1_x" type="hinge" pos="0 0 0" axis="1 0 0" stiffness="100" damping="10" armature="0.02" range="-43.67 1.34" />
                      <joint name="L_Ring1_y" type="hinge" pos="0 0 0" axis="0 1 0" stiffness="100" damping="10" armature="0.02" range="-28.44 41.63" />
                      <joint name="L_Ring1_z" type="hinge" pos="0 0 0" axis="0 0 1" stiffness="100" damping="10" armature="0.02" range="-117.83 14.06" />
                      <geom type="capsule" contype="1" conaffinity="1" density="1000" fromto="0.0055 0.0003 -0.0011 0.0218 0.0013 -0.0043" size="0.0057" />
                      <body name="L_Ring2" pos="0.0273 0.0016 -0.0053">
                        <joint name="L_Ring2_x" type="hinge" pos="0 0 0" axis="1 0 0" stiffness="100" damping="10" armature="0.02" range="-22.97 18.77" />
                        <joint name="L_Ring2_y" type="hinge" pos="0 0 0" axis="0 1 0" stiffness="100" damping="10" armature="0.02" range="-24.70 19.85" />
                        <joint name="L_Ring2_z" type="hinge" pos="0 0 0" axis="0 0 1" stiffness="100" damping="10" armature="0.02" range="-107.53 10.35" />
                        <geom type="capsule" contype="1" conaffinity="1" density="1000" fromto="0.0045 -0.0002 -0.0014 0.0179 -0.0008 -0.0058" size="0.0051" />
                        <body name="L_Ring3" pos="0.0223 -0.0010 -0.0072">
                          <joint name="L_Ring3_x" type="hinge" pos="0 0 0" axis="1 0 0" stiffness="100" damping="10" armature="0.02" range="-20.56 19.65" />
                          <joint name="L_Ring3_y" type="hinge" pos="0 0 0" axis="0 1 0" stiffness="100" damping="10" armature="0.02" range="-26.15 20.69" />
                          <joint name="L_Ring3_z" type="hinge" pos="0 0 0" axis="0 0 1" stiffness="100" damping="10" armature="0.02" range="-71.92 24.08" />
                          <geom type="capsule" contype="1" conaffinity="1" density="1000" fromto="0.0048 -0.0002 -0.0015 0.0176 -0.0008 -0.0057" size="0.0043" />
                        </body>
                      </body>
                    </body>
                    <body name="L_Thumb1" pos="0.0423 -0.0217 0.0268">
                      <joint name="L_Thumb1_x" type="hinge" pos="0 0 0" axis="1 0 0" stiffness="100" damping="10" armature="0.02" range="30.97 108.96" />
                      <joint name="L_Thumb1_y" type="hinge" pos="0 0 0" axis="0 1 0" stiffness="100" damping="10" armature="0.02" range="-37.61 36.80" />
                      <joint name="L_Thumb1_z" type="hinge" pos="0 0 0" axis="0 0 1" stiffness="100" damping="10" armature="0.02" range="-15.52 62.13" />
                      <geom type="capsule" contype="1" conaffinity="1" density="1000" fromto="0.0034 0.0001 0.0047 0.0136 0.0005 0.0188" size="0.0086" />
                      <body name="L_Thumb2" pos="0.0170 0.0006 0.0235">
                        <joint name="L_Thumb2_x" type="hinge" pos="0 0 0" axis="1 0 0" stiffness="100" damping="10" armature="0.02" range="-13.78 19.60" />
                        <joint name="L_Thumb2_y" type="hinge" pos="0 0 0" axis="0 1 0" stiffness="100" damping="10" armature="0.02" range="-13.96 9.62" />
                        <joint name="L_Thumb2_z" type="hinge" pos="0 0 0" axis="0 0 1" stiffness="100" damping="10" armature="0.02" range="-38.43 12.67" />
                        <geom type="capsule" contype="1" conaffinity="1" density="1000" fromto="0.0040 -0.0012 0.0028 0.0158 -0.0048 0.0114" size="0.0065" />
                        <body name="L_Thumb3" pos="0.0198 -0.0059 0.0142">
                          <joint name="L_Thumb3_x" type="hinge" pos="0 0 0" axis="1 0 0" stiffness="100" damping="10" armature="0.02" range="-17.79 16.56" />
                          <joint name="L_Thumb3_y" type="hinge" pos="0 0 0" axis="0 1 0" stiffness="100" damping="10" armature="0.02" range="-13.54 14.16" />
                          <joint name="L_Thumb3_z" type="hinge" pos="0 0 0" axis="0 0 1" stiffness="100" damping="10" armature="0.02" range="-30.70 60.10" />
                          <geom type="capsule" contype="1" conaffinity="1" density="1000" fromto="0.0033 -0.0010 0.0024 0.0165 -0.0049 0.0119" size="0.0062" />
                        </body>
                      </body>
                    </body>
                  </body>
                </body>
              </body>
            </body>
            <body name="R_Thorax" pos="-0.0540 0.1023 -0.0164">
              <joint name="R_Thorax_x" type="hinge" pos="0 0 0" axis="1 0 0" stiffness="500" damping="50" armature="0.02" range="-180.00 180.00" />
              <joint name="R_Thorax_y" type="hinge" pos="0 0 0" axis="0 1 0" stiffness="500" damping="50" armature="0.02" range="-180.00 180.00" />
              <joint name="R_Thorax_z" type="hinge" pos="0 0 0" axis="0 0 1" stiffness="500" damping="50" armature="0.02" range="-180.00 180.00" />
              <geom type="capsule" contype="1" conaffinity="1" density="1000" fromto="-0.0194 0.0085 -0.0039 -0.0774 0.0339 -0.0157" size="0.0576" />
              <body name="R_Shoulder" pos="-0.0968 0.0424 -0.0196">
                <joint name="R_Shoulder_x" type="hinge" pos="0 0 0" axis="1 0 0" stiffness="500" damping="50" armature="0.02" range="-180.00 180.00" />
                <joint name="R_Shoulder_y" type="hinge" pos="0 0 0" axis="0 1 0" stiffness="500" damping="50" armature="0.02" range="-180.00 180.00" />
                <joint name="R_Shoulder_z" type="hinge" pos="0 0 0" axis="0 0 1" stiffness="500" damping="50" armature="0.02" range="-180.00 180.00" />
                <geom type="capsule" contype="1" conaffinity="1" density="1000" fromto="-0.0522 -0.0100 -0.0044 -0.2090 -0.0400 -0.0178" size="0.0538" />
                <body name="R_Elbow" pos="-0.2612 -0.0500 -0.0222">
                  <joint name="R_Elbow_x" type="hinge" pos="0 0 0" axis="1 0 0" stiffness="500" damping="50" armature="0.02" range="-180.00 180.00" />
                  <joint name="R_Elbow_y" type="hinge" pos="0 0 0" axis="0 1 0" stiffness="500" damping="50" armature="0.02" range="-180.00 180.00" />
                  <joint name="R_Elbow_z" type="hinge" pos="0 0 0" axis="0 0 1" stiffness="500" damping="50" armature="0.02" range="-180.00 180.00" />
                  <geom type="capsule" contype="1" conaffinity="1" density="1000" fromto="-0.0458 0.0007 -0.0007 -0.1833 0.0026 -0.0030" size="0.042" />
                  <body name="R_Wrist" pos="-0.2291 0.0033 -0.0037">
                    <joint name="R_Wrist_x" type="hinge" pos="0 0 0" axis="1 0 0" stiffness="300" damping="30" armature="0.02" range="-180.00 180.00" />
                    <joint name="R_Wrist_y" type="hinge" pos="0 0 0" axis="0 1 0" stiffness="300" damping="30" armature="0.02" range="-180.00 180.00" />
                    <joint name="R_Wrist_z" type="hinge" pos="0 0 0" axis="0 0 1" stiffness="300" damping="30" armature="0.02" range="-180.00 180.00" />
                    <geom type="box" contype="1" conaffinity="1" density="1000" pos="-0.0449 -0.0080 -0.0014" size="0.0416 0.0078 0.0414" quat="1.0000 0.0000 0.0000 0.0000" />
                    <body name="R_Index1" pos="-0.1002 -0.0131 0.0226">
                      <joint name="R_Index1_x" type="hinge" pos="0 0 0" axis="1 0 0" stiffness="100" damping="10" armature="0.02" range="-16.50 18.82" />
                      <joint name="R_Index1_y" type="hinge" pos="0 0 0" axis="0 1 0" stiffness="100" damping="10" armature="0.02" range="-36.64 11.27" />
                      <joint name="R_Index1_z" type="hinge" pos="0 0 0" axis="0 0 1" stiffness="100" damping="10" armature="0.02" range="-63.12 81.02" />
                      <geom type="capsule" contype="1" conaffinity="1" density="1000" fromto="-0.0062 0.0005 0.0006 -0.0249 0.0022 0.0023" size="0.0065" />
                      <body name="R_Index2" pos="-0.0312 0.0027 0.0028">
                        <joint name="R_Index2_x" type="hinge" pos="0 0 0" axis="1 0 0" stiffness="100" damping="10" armature="0.02" range="-15.69 17.59" />
                        <joint name="R_Index2_y" type="hinge" pos="0 0 0" axis="0 1 0" stiffness="100" damping="10" armature="0.02" range="-15.86 16.27" />
                        <joint name="R_Index2_z" type="hinge" pos="0 0 0" axis="0 0 1" stiffness="100" damping="10" armature="0.02" range="-10.33 125.31" />
                        <geom type="capsule" contype="1" conaffinity="1" density="1000" fromto="-0.0044 -0.0003 0.0001 -0.0177 -0.0011 0.0004" size="0.0053" />
                        <body name="R_Index3" pos="-0.0221 -0.0014 0.0005">
                          <joint name="R_Index3_x" type="hinge" pos="0 0 0" axis="1 0 0" stiffness="100" damping="10" armature="0.02" range="-15.99 19.46" />
                          <joint name="R_Index3_y" type="hinge" pos="0 0 0" axis="0 1 0" stiffness="100" damping="10" armature="0.02" range="-16.86 16.82" />
                          <joint name="R_Index3_z" type="hinge" pos="0 0 0" axis="0 0 1" stiffness="100" damping="10" armature="0.02" range="-19.91 101.75" />
                          <geom type="capsule" contype="1" conaffinity="1" density="1000" fromto="-0.0051 -0.0003 0.0001 -0.0170 -0.0011 0.0004" size="0.0048" />
                        </body>
                      </body>
                    </body>
                    <body name="R_Middle1" pos="-0.1071 -0.0106 0.0003">
                      <joint name="R_Middle1_x" type="hinge" pos="0 0 0" axis="1 0 0" stiffness="100" damping="10" armature="0.02" range="-42.91 24.68" />
                      <joint name="R_Middle1_y" type="hinge" pos="0 0 0" axis="0 1 0" stiffness="100" damping="10" armature="0.02" range="-46.34 32.77" />
                      <joint name="R_Middle1_z" type="hinge" pos="0 0 0" axis="0 0 1" stiffness="100" damping="10" armature="0.02" range="-67.08 97.84" />
                      <geom type="capsule" contype="1" conaffinity="1" density="1000" fromto="-0.0060 0.0003 -0.0007 -0.0239 0.0010 -0.0030" size="0.0067" />
                      <body name="R_Middle2" pos="-0.0298 0.0013 -0.0037">
                        <joint name="R_Middle2_x" type="hinge" pos="0 0 0" axis="1 0 0" stiffness="100" damping="10" armature="0.02" range="-21.35 18.50" />
                        <joint name="R_Middle2_y" type="hinge" pos="0 0 0" axis="0 1 0" stiffness="100" damping="10" armature="0.02" range="-17.01 14.04" />
                        <joint name="R_Middle2_z" type="hinge" pos="0 0 0" axis="0 0 1" stiffness="100" damping="10" armature="0.02" range="-11.44 122.64" />
                        <geom type="capsule" contype="1" conaffinity="1" density="1000" fromto="-0.0046 -0.0001 -0.0007 -0.0186 -0.0005 -0.0029" size="0.0050" />
                        <body name="R_Middle3" pos="-0.0232 -0.0006 -0.0036">
                          <joint name="R_Middle3_x" type="hinge" pos="0 0 0" axis="1 0 0" stiffness="100" damping="10" armature="0.02" range="-18.07 19.61" />
                          <joint name="R_Middle3_y" type="hinge" pos="0 0 0" axis="0 1 0" stiffness="100" damping="10" armature="0.02" range="-16.03 14.35" />
                          <joint name="R_Middle3_z" type="hinge" pos="0 0 0" axis="0 0 1" stiffness="100" damping="10" armature="0.02" range="-39.98 93.48" />
                          <geom type="capsule" contype="1" conaffinity="1" density="1000" fromto="-0.0052 -0.0001 -0.0008 -0.0179 -0.0005 -0.0028" size="0.0045" />
                        </body>
                      </body>
                    </body>
                    <body name="R_Pinky1" pos="-0.0817 -0.0180 -0.0386">
                      <joint name="R_Pinky1_x" type="hinge" pos="0 0 0" axis="1 0 0" stiffness="100" damping="10" armature="0.02" range="-75.65 47.50" />
                      <joint name="R_Pinky1_y" type="hinge" pos="0 0 0" axis="0 1 0" stiffness="100" damping="10" armature="0.02" range="-63.50 46.64" />
                      <joint name="R_Pinky1_z" type="hinge" pos="0 0 0" axis="0 0 1" stiffness="100" damping="10" armature="0.02" range="-56.81 105.65" />
                      <geom type="capsule" contype="1" conaffinity="1" density="1000" fromto="-0.0029 -0.0001 -0.0025 -0.0117 -0.0004 -0.0098" size="0.0050" />
                      <body name="R_Pinky2" pos="-0.0146 -0.0004 -0.0123">
                        <joint name="R_Pinky2_x" type="hinge" pos="0 0 0" axis="1 0 0" stiffness="100" damping="10" armature="0.02" range="-17.78 17.10" />
                        <joint name="R_Pinky2_y" type="hinge" pos="0 0 0" axis="0 1 0" stiffness="100" damping="10" armature="0.02" range="-18.28 12.99" />
                        <joint name="R_Pinky2_z" type="hinge" pos="0 0 0" axis="0 0 1" stiffness="100" damping="10" armature="0.02" range="-10.17 122.14" />
                        <geom type="capsule" contype="1" conaffinity="1" density="1000" fromto="-0.0030 -0.0002 -0.0024 -0.0118 -0.0007 -0.0095" size="0.0045" />
                        <body name="R_Pinky3" pos="-0.0148 -0.0009 -0.0118">
                          <joint name="R_Pinky3_x" type="hinge" pos="0 0 0" axis="1 0 0" stiffness="100" damping="10" armature="0.02" range="-17.89 17.04" />
                          <joint name="R_Pinky3_y" type="hinge" pos="0 0 0" axis="0 1 0" stiffness="100" damping="10" armature="0.02" range="-17.95 12.84" />
                          <joint name="R_Pinky3_z" type="hinge" pos="0 0 0" axis="0 0 1" stiffness="100" damping="10" armature="0.02" range="-10.05 81.18" />
                          <geom type="capsule" contype="1" conaffinity="1" density="1000" fromto="-0.0034 -0.0002 -0.0028 -0.0113 -0.0007 -0.0091" size="0.0036" />
                        </body>
                      </body>
                    </body>
                    <body name="R_Ring1" pos="-0.0950 -0.0131 -0.0225">
                      <joint name="R_Ring1_x" type="hinge" pos="0 0 0" axis="1 0 0" stiffness="100" damping="10" armature="0.02" range="-57.12 27.96" />
                      <joint name="R_Ring1_y" type="hinge" pos="0 0 0" axis="0 1 0" stiffness="100" damping="10" armature="0.02" range="-52.99 30.50" />
                      <joint name="R_Ring1_z" type="hinge" pos="0 0 0" axis="0 0 1" stiffness="100" damping="10" armature="0.02" range="-51.89 94.00" />
                      <geom type="capsule" contype="1" conaffinity="1" density="1000" fromto="-0.0055 0.0003 -0.0011 -0.0218 0.0013 -0.0043" size="0.0057" />
                      <body name="R_Ring2" pos="-0.0273 0.0016 -0.0053">
                        <joint name="R_Ring2_x" type="hinge" pos="0 0 0" axis="1 0 0" stiffness="100" damping="10" armature="0.02" range="-16.34 14.03" />
                        <joint name="R_Ring2_y" type="hinge" pos="0 0 0" axis="0 1 0" stiffness="100" damping="10" armature="0.02" range="-16.39 13.33" />
                        <joint name="R_Ring2_z" type="hinge" pos="0 0 0" axis="0 0 1" stiffness="100" damping="10" armature="0.02" range="-10.77 122.70" />
                        <geom type="capsule" contype="1" conaffinity="1" density="1000" fromto="-0.0045 -0.0002 -0.0014 -0.0179 -0.0008 -0.0058" size="0.0051" />
                        <body name="R_Ring3" pos="-0.0223 -0.0010 -0.0072">
                          <joint name="R_Ring3_x" type="hinge" pos="0 0 0" axis="1 0 0" stiffness="100" damping="10" armature="0.02" range="-16.51 13.97" />
                          <joint name="R_Ring3_y" type="hinge" pos="0 0 0" axis="0 1 0" stiffness="100" damping="10" armature="0.02" range="-17.06 14.31" />
                          <joint name="R_Ring3_z" type="hinge" pos="0 0 0" axis="0 0 1" stiffness="100" damping="10" armature="0.02" range="-11.53 84.95" />
                          <geom type="capsule" contype="1" conaffinity="1" density="1000" fromto="-0.0050 -0.0002 -0.0016 -0.0173 -0.0007 -0.0056" size="0.0043" />
                        </body>
                      </body>
                    </body>
                    <body name="R_Thumb1" pos="-0.0411 -0.0209 0.0283">
                      <joint name="R_Thumb1_x" type="hinge" pos="0 0 0" axis="1 0 0" stiffness="100" damping="10" armature="0.02" range="31.06 140.36" />
                      <joint name="R_Thumb1_y" type="hinge" pos="0 0 0" axis="0 1 0" stiffness="100" damping="10" armature="0.02" range="-33.30 57.03" />
                      <joint name="R_Thumb1_z" type="hinge" pos="0 0 0" axis="0 0 1" stiffness="100" damping="10" armature="0.02" range="-75.22 10.55" />
                      <geom type="capsule" contype="1" conaffinity="1" density="1000" fromto="-0.0034 0.0001 0.0047 -0.0136 0.0005 0.0188" size="0.0086" />
                      <body name="R_Thumb2" pos="-0.0170 0.0006 0.0235">
                        <joint name="R_Thumb2_x" type="hinge" pos="0 0 0" axis="1 0 0" stiffness="100" damping="10" armature="0.02" range="-17.79 19.38" />
                        <joint name="R_Thumb2_y" type="hinge" pos="0 0 0" axis="0 1 0" stiffness="100" damping="10" armature="0.02" range="-14.76 14.39" />
                        <joint name="R_Thumb2_z" type="hinge" pos="0 0 0" axis="0 0 1" stiffness="100" damping="10" armature="0.02" range="-12.00 58.56" />
                        <geom type="capsule" contype="1" conaffinity="1" density="1000" fromto="-0.0040 -0.0012 0.0028 -0.0158 -0.0048 0.0114" size="0.0065" />
                        <body name="R_Thumb3" pos="-0.0198 -0.0059 0.0142">
                          <joint name="R_Thumb3_x" type="hinge" pos="0 0 0" axis="1 0 0" stiffness="100" damping="10" armature="0.02" range="-19.44 18.21" />
                          <joint name="R_Thumb3_y" type="hinge" pos="0 0 0" axis="0 1 0" stiffness="100" damping="10" armature="0.02" range="-41.79 12.89" />
                          <joint name="R_Thumb3_z" type="hinge" pos="0 0 0" axis="0 0 1" stiffness="100" damping="10" armature="0.02" range="-46.48 69.72" />
                          <geom type="capsule" contype="1" conaffinity="1" density="1000" fromto="-0.0042 -0.0013 0.0030 -0.0156 -0.0047 0.0112" size="0.0064" />
                        </body>
                      </body>
                    </body>
                  </body>
                </body>
              </body>
            </body>
          </body>
        </body>
      </body>
    </body>
  </worldbody>
  <actuator>
    <motor name="L_Hip_x" joint="L_Hip_x" gear="1" />
    <motor name="L_Hip_y" joint="L_Hip_y" gear="1" />
    <motor name="L_Hip_z" joint="L_Hip_z" gear="1" />
    <motor name="L_Knee_x" joint="L_Knee_x" gear="1" />
    <motor name="L_Knee_y" joint="L_Knee_y" gear="1" />
    <motor name="L_Knee_z" joint="L_Knee_z" gear="1" />
    <motor name="L_Ankle_x" joint="L_Ankle_x" gear="1" />
    <motor name="L_Ankle_y" joint="L_Ankle_y" gear="1" />
    <motor name="L_Ankle_z" joint="L_Ankle_z" gear="1" />
    <motor name="L_Toe_x" joint="L_Toe_x" gear="1" />
    <motor name="L_Toe_y" joint="L_Toe_y" gear="1" />
    <motor name="L_Toe_z" joint="L_Toe_z" gear="1" />
    <motor name="R_Hip_x" joint="R_Hip_x" gear="1" />
    <motor name="R_Hip_y" joint="R_Hip_y" gear="1" />
    <motor name="R_Hip_z" joint="R_Hip_z" gear="1" />
    <motor name="R_Knee_x" joint="R_Knee_x" gear="1" />
    <motor name="R_Knee_y" joint="R_Knee_y" gear="1" />
    <motor name="R_Knee_z" joint="R_Knee_z" gear="1" />
    <motor name="R_Ankle_x" joint="R_Ankle_x" gear="1" />
    <motor name="R_Ankle_y" joint="R_Ankle_y" gear="1" />
    <motor name="R_Ankle_z" joint="R_Ankle_z" gear="1" />
    <motor name="R_Toe_x" joint="R_Toe_x" gear="1" />
    <motor name="R_Toe_y" joint="R_Toe_y" gear="1" />
    <motor name="R_Toe_z" joint="R_Toe_z" gear="1" />
    <motor name="Torso_x" joint="Torso_x" gear="1" />
    <motor name="Torso_y" joint="Torso_y" gear="1" />
    <motor name="Torso_z" joint="Torso_z" gear="1" />
    <motor name="Spine_x" joint="Spine_x" gear="1" />
    <motor name="Spine_y" joint="Spine_y" gear="1" />
    <motor name="Spine_z" joint="Spine_z" gear="1" />
    <motor name="Chest_x" joint="Chest_x" gear="1" />
    <motor name="Chest_y" joint="Chest_y" gear="1" />
    <motor name="Chest_z" joint="Chest_z" gear="1" />
    <motor name="Neck_x" joint="Neck_x" gear="1" />
    <motor name="Neck_y" joint="Neck_y" gear="1" />
    <motor name="Neck_z" joint="Neck_z" gear="1" />
    <motor name="Head_x" joint="Head_x" gear="1" />
    <motor name="Head_y" joint="Head_y" gear="1" />
    <motor name="Head_z" joint="Head_z" gear="1" />
    <motor name="L_Thorax_x" joint="L_Thorax_x" gear="1" />
    <motor name="L_Thorax_y" joint="L_Thorax_y" gear="1" />
    <motor name="L_Thorax_z" joint="L_Thorax_z" gear="1" />
    <motor name="L_Shoulder_x" joint="L_Shoulder_x" gear="1" />
    <motor name="L_Shoulder_y" joint="L_Shoulder_y" gear="1" />
    <motor name="L_Shoulder_z" joint="L_Shoulder_z" gear="1" />
    <motor name="L_Elbow_x" joint="L_Elbow_x" gear="1" />
    <motor name="L_Elbow_y" joint="L_Elbow_y" gear="1" />
    <motor name="L_Elbow_z" joint="L_Elbow_z" gear="1" />
    <motor name="L_Wrist_x" joint="L_Wrist_x" gear="1" />
    <motor name="L_Wrist_y" joint="L_Wrist_y" gear="1" />
    <motor name="L_Wrist_z" joint="L_Wrist_z" gear="1" />
    <motor name="L_Index1_x" joint="L_Index1_x" gear="1" />
    <motor name="L_Index1_y" joint="L_Index1_y" gear="1" />
    <motor name="L_Index1_z" joint="L_Index1_z" gear="1" />
    <motor name="L_Index2_x" joint="L_Index2_x" gear="1" />
    <motor name="L_Index2_y" joint="L_Index2_y" gear="1" />
    <motor name="L_Index2_z" joint="L_Index2_z" gear="1" />
    <motor name="L_Index3_x" joint="L_Index3_x" gear="1" />
    <motor name="L_Index3_y" joint="L_Index3_y" gear="1" />
    <motor name="L_Index3_z" joint="L_Index3_z" gear="1" />
    <motor name="L_Middle1_x" joint="L_Middle1_x" gear="1" />
    <motor name="L_Middle1_y" joint="L_Middle1_y" gear="1" />
    <motor name="L_Middle1_z" joint="L_Middle1_z" gear="1" />
    <motor name="L_Middle2_x" joint="L_Middle2_x" gear="1" />
    <motor name="L_Middle2_y" joint="L_Middle2_y" gear="1" />
    <motor name="L_Middle2_z" joint="L_Middle2_z" gear="1" />
    <motor name="L_Middle3_x" joint="L_Middle3_x" gear="1" />
    <motor name="L_Middle3_y" joint="L_Middle3_y" gear="1" />
    <motor name="L_Middle3_z" joint="L_Middle3_z" gear="1" />
    <motor name="L_Pinky1_x" joint="L_Pinky1_x" gear="1" />
    <motor name="L_Pinky1_y" joint="L_Pinky1_y" gear="1" />
    <motor name="L_Pinky1_z" joint="L_Pinky1_z" gear="1" />
    <motor name="L_Pinky2_x" joint="L_Pinky2_x" gear="1" />
    <motor name="L_Pinky2_y" joint="L_Pinky2_y" gear="1" />
    <motor name="L_Pinky2_z" joint="L_Pinky2_z" gear="1" />
    <motor name="L_Pinky3_x" joint="L_Pinky3_x" gear="1" />
    <motor name="L_Pinky3_y" joint="L_Pinky3_y" gear="1" />
    <motor name="L_Pinky3_z" joint="L_Pinky3_z" gear="1" />
    <motor name="L_Ring1_x" joint="L_Ring1_x" gear="1" />
    <motor name="L_Ring1_y" joint="L_Ring1_y" gear="1" />
    <motor name="L_Ring1_z" joint="L_Ring1_z" gear="1" />
    <motor name="L_Ring2_x" joint="L_Ring2_x" gear="1" />
    <motor name="L_Ring2_y" joint="L_Ring2_y" gear="1" />
    <motor name="L_Ring2_z" joint="L_Ring2_z" gear="1" />
    <motor name="L_Ring3_x" joint="L_Ring3_x" gear="1" />
    <motor name="L_Ring3_y" joint="L_Ring3_y" gear="1" />
    <motor name="L_Ring3_z" joint="L_Ring3_z" gear="1" />
    <motor name="L_Thumb1_x" joint="L_Thumb1_x" gear="1" />
    <motor name="L_Thumb1_y" joint="L_Thumb1_y" gear="1" />
    <motor name="L_Thumb1_z" joint="L_Thumb1_z" gear="1" />
    <motor name="L_Thumb2_x" joint="L_Thumb2_x" gear="1" />
    <motor name="L_Thumb2_y" joint="L_Thumb2_y" gear="1" />
    <motor name="L_Thumb2_z" joint="L_Thumb2_z" gear="1" />
    <motor name="L_Thumb3_x" joint="L_Thumb3_x" gear="1" />
    <motor name="L_Thumb3_y" joint="L_Thumb3_y" gear="1" />
    <motor name="L_Thumb3_z" joint="L_Thumb3_z" gear="1" />
    <motor name="R_Thorax_x" joint="R_Thorax_x" gear="1" />
    <motor name="R_Thorax_y" joint="R_Thorax_y" gear="1" />
    <motor name="R_Thorax_z" joint="R_Thorax_z" gear="1" />
    <motor name="R_Shoulder_x" joint="R_Shoulder_x" gear="1" />
    <motor name="R_Shoulder_y" joint="R_Shoulder_y" gear="1" />
    <motor name="R_Shoulder_z" joint="R_Shoulder_z" gear="1" />
    <motor name="R_Elbow_x" joint="R_Elbow_x" gear="1" />
    <motor name="R_Elbow_y" joint="R_Elbow_y" gear="1" />
    <motor name="R_Elbow_z" joint="R_Elbow_z" gear="1" />
    <motor name="R_Wrist_x" joint="R_Wrist_x" gear="1" />
    <motor name="R_Wrist_y" joint="R_Wrist_y" gear="1" />
    <motor name="R_Wrist_z" joint="R_Wrist_z" gear="1" />
    <motor name="R_Index1_x" joint="R_Index1_x" gear="1" />
    <motor name="R_Index1_y" joint="R_Index1_y" gear="1" />
    <motor name="R_Index1_z" joint="R_Index1_z" gear="1" />
    <motor name="R_Index2_x" joint="R_Index2_x" gear="1" />
    <motor name="R_Index2_y" joint="R_Index2_y" gear="1" />
    <motor name="R_Index2_z" joint="R_Index2_z" gear="1" />
    <motor name="R_Index3_x" joint="R_Index3_x" gear="1" />
    <motor name="R_Index3_y" joint="R_Index3_y" gear="1" />
    <motor name="R_Index3_z" joint="R_Index3_z" gear="1" />
    <motor name="R_Middle1_x" joint="R_Middle1_x" gear="1" />
    <motor name="R_Middle1_y" joint="R_Middle1_y" gear="1" />
    <motor name="R_Middle1_z" joint="R_Middle1_z" gear="1" />
    <motor name="R_Middle2_x" joint="R_Middle2_x" gear="1" />
    <motor name="R_Middle2_y" joint="R_Middle2_y" gear="1" />
    <motor name="R_Middle2_z" joint="R_Middle2_z" gear="1" />
    <motor name="R_Middle3_x" joint="R_Middle3_x" gear="1" />
    <motor name="R_Middle3_y" joint="R_Middle3_y" gear="1" />
    <motor name="R_Middle3_z" joint="R_Middle3_z" gear="1" />
    <motor name="R_Pinky1_x" joint="R_Pinky1_x" gear="1" />
    <motor name="R_Pinky1_y" joint="R_Pinky1_y" gear="1" />
    <motor name="R_Pinky1_z" joint="R_Pinky1_z" gear="1" />
    <motor name="R_Pinky2_x" joint="R_Pinky2_x" gear="1" />
    <motor name="R_Pinky2_y" joint="R_Pinky2_y" gear="1" />
    <motor name="R_Pinky2_z" joint="R_Pinky2_z" gear="1" />
    <motor name="R_Pinky3_x" joint="R_Pinky3_x" gear="1" />
    <motor name="R_Pinky3_y" joint="R_Pinky3_y" gear="1" />
    <motor name="R_Pinky3_z" joint="R_Pinky3_z" gear="1" />
    <motor name="R_Ring1_x" joint="R_Ring1_x" gear="1" />
    <motor name="R_Ring1_y" joint="R_Ring1_y" gear="1" />
    <motor name="R_Ring1_z" joint="R_Ring1_z" gear="1" />
    <motor name="R_Ring2_x" joint="R_Ring2_x" gear="1" />
    <motor name="R_Ring2_y" joint="R_Ring2_y" gear="1" />
    <motor name="R_Ring2_z" joint="R_Ring2_z" gear="1" />
    <motor name="R_Ring3_x" joint="R_Ring3_x" gear="1" />
    <motor name="R_Ring3_y" joint="R_Ring3_y" gear="1" />
    <motor name="R_Ring3_z" joint="R_Ring3_z" gear="1" />
    <motor name="R_Thumb1_x" joint="R_Thumb1_x" gear="1" />
    <motor name="R_Thumb1_y" joint="R_Thumb1_y" gear="1" />
    <motor name="R_Thumb1_z" joint="R_Thumb1_z" gear="1" />
    <motor name="R_Thumb2_x" joint="R_Thumb2_x" gear="1" />
    <motor name="R_Thumb2_y" joint="R_Thumb2_y" gear="1" />
    <motor name="R_Thumb2_z" joint="R_Thumb2_z" gear="1" />
    <motor name="R_Thumb3_x" joint="R_Thumb3_x" gear="1" />
    <motor name="R_Thumb3_y" joint="R_Thumb3_y" gear="1" />
    <motor name="R_Thumb3_z" joint="R_Thumb3_z" gear="1" />
  </actuator>
  <contact />
  <sensor />
  <size njmax="700" nconmax="700" />
</mujoco>
