<?xml version='1.0' encoding='utf-8'?>
<mujoco model="smplx_mapped_s117">
  <compiler coordinate="local" />
  <default>
    <joint damping="0.0" armature="0.01" stiffness="0.0" limited="true" />
    <geom conaffinity="1" condim="3" contype="7" margin="0.001" rgba="0.8 0.6 .4 1" />
  </default>
  <asset>
    <texture type="skybox" builtin="gradient" rgb1=".4 .5 .6" rgb2="0 0 0" width="100" height="100" />
    <texture builtin="flat" height="1278" mark="cross" markrgb="1 1 1" name="texgeom" random="0.01" rgb1="0.8 0.6 0.4" rgb2="0.8 0.6 0.4" type="cube" width="127" />
    <texture builtin="checker" height="100" name="texplane" rgb1="0 0 0" rgb2="0.8 0.8 0.8" type="2d" width="100" />
    <material name="MatPlane" reflectance="0.5" shininess="1" specular="1" texrepeat="60 60" texture="texplane" />
    <material name="geom" texture="texgeom" texuniform="true" />
  </asset>
  <worldbody>
    <light cutoff="100" diffuse="1 1 1" dir="-0 0 -1.3" directional="true" exponent="1" pos="0 0 1.3" specular=".1 .1 .1" />
    <geom conaffinity="1" condim="3" name="floor" pos="0 0 0" rgba="0.8 0.9 0.8 1" size="100 100 .2" type="plane" material="MatPlane" />
    <body name="Pelvis" pos="0.0010 -0.3579 0.0050">
      <freejoint name="Pelvis" />
      <geom type="sphere" contype="1" conaffinity="1" density="4629.6296296296305" size="0.09" pos="0.0000 0.0000 0.0000" name="Pelvis" />
      <body name="L_Hip" pos="0.0547 -0.0920 -0.0241">
        <joint name="L_Hip_x" type="hinge" pos="0 0 0" axis="1 0 0" stiffness="800" damping="80" armature="0.02" range="-150.00 150.00" />
        <joint name="L_Hip_y" type="hinge" pos="0 0 0" axis="0 1 0" stiffness="800" damping="80" armature="0.02" range="-150.00 150.00" />
        <joint name="L_Hip_z" type="hinge" pos="0 0 0" axis="0 0 1" stiffness="800" damping="80" armature="0.02" range="-150.00 150.00" />
        <geom type="capsule" contype="1" conaffinity="1" density="2040.816327" fromto="0.0133 -0.0716 -0.0004 0.0531 -0.2863 -0.0018" size="0.059" />
        <body name="L_Knee" pos="0.0663 -0.3579 -0.0022">
          <joint name="L_Knee_x" type="hinge" pos="0 0 0" axis="1 0 0" stiffness="800" damping="80" armature="0.02" range="-150.00 150.00" />
          <joint name="L_Knee_y" type="hinge" pos="0 0 0" axis="0 1 0" stiffness="800" damping="80" armature="0.02" range="-150.00 150.00" />
          <joint name="L_Knee_z" type="hinge" pos="0 0 0" axis="0 0 1" stiffness="800" damping="80" armature="0.02" range="-150.00 150.00" />
          <geom type="capsule" contype="1" conaffinity="1" density="1234.567901" fromto="-0.0094 -0.0753 -0.0076 -0.0375 -0.3010 -0.0306" size="0.0564" />
          <body name="L_Ankle" pos="-0.0469 -0.3763 -0.0382">
            <joint name="L_Ankle_x" type="hinge" pos="0 0 0" axis="1 0 0" stiffness="800" damping="80" armature="0.02" range="-150.00 150.00" />
            <joint name="L_Ankle_y" type="hinge" pos="0 0 0" axis="0 1 0" stiffness="800" damping="80" armature="0.02" range="-150.00 150.00" />
            <joint name="L_Ankle_z" type="hinge" pos="0 0 0" axis="0 0 1" stiffness="800" damping="80" armature="0.02" range="-150.00 150.00" />
            <geom type="box" contype="1" conaffinity="1" density="1000" pos="0.0115 -0.0234 0.0566" size="0.0502 0.0216 0.0909" quat="1.0000 0.0000 0.0000 0.0000" />
            <body name="L_Toe" pos="0.0427 -0.0539 0.1276">
              <joint name="L_Toe_x" type="hinge" pos="0 0 0" axis="1 0 0" stiffness="500" damping="50" armature="0.02" range="-150.00 150.00" />
              <joint name="L_Toe_y" type="hinge" pos="0 0 0" axis="0 1 0" stiffness="500" damping="50" armature="0.02" range="-150.00 150.00" />
              <joint name="L_Toe_z" type="hinge" pos="0 0 0" axis="0 0 1" stiffness="500" damping="50" armature="0.02" range="-150.00 150.00" />
              <geom type="box" contype="1" conaffinity="1" density="1000" pos="-0.0115 0.0227 0.0576" size="0.0493 0.0209 0.0194" quat="1.0000 0.0000 0.0000 0.0000" />
            </body>
          </body>
        </body>
      </body>
      <body name="R_Hip" pos="-0.0558 -0.1025 -0.0174">
        <joint name="R_Hip_x" type="hinge" pos="0 0 0" axis="1 0 0" stiffness="800" damping="80" armature="0.02" range="-150.00 150.00" />
        <joint name="R_Hip_y" type="hinge" pos="0 0 0" axis="0 1 0" stiffness="800" damping="80" armature="0.02" range="-150.00 150.00" />
        <joint name="R_Hip_z" type="hinge" pos="0 0 0" axis="0 0 1" stiffness="800" damping="80" armature="0.02" range="-150.00 150.00" />
        <geom type="capsule" contype="1" conaffinity="1" density="2040.816327" fromto="-0.0101 -0.0684 -0.0019 -0.0403 -0.2737 -0.0078" size="0.0588" />
        <body name="R_Knee" pos="-0.0504 -0.3422 -0.0097">
          <joint name="R_Knee_x" type="hinge" pos="0 0 0" axis="1 0 0" stiffness="800" damping="80" armature="0.02" range="-150.00 150.00" />
          <joint name="R_Knee_y" type="hinge" pos="0 0 0" axis="0 1 0" stiffness="800" damping="80" armature="0.02" range="-150.00 150.00" />
          <joint name="R_Knee_z" type="hinge" pos="0 0 0" axis="0 0 1" stiffness="800" damping="80" armature="0.02" range="-150.00 150.00" />
          <geom type="capsule" contype="1" conaffinity="1" density="1234.567901" fromto="0.0037 -0.0776 -0.0074 0.0150 -0.3105 -0.0298" size="0.0564" />
          <body name="R_Ankle" pos="0.0187 -0.3882 -0.0372">
            <joint name="R_Ankle_x" type="hinge" pos="0 0 0" axis="1 0 0" stiffness="800" damping="80" armature="0.02" range="-150.00 150.00" />
            <joint name="R_Ankle_y" type="hinge" pos="0 0 0" axis="0 1 0" stiffness="800" damping="80" armature="0.02" range="-150.00 150.00" />
            <joint name="R_Ankle_z" type="hinge" pos="0 0 0" axis="0 0 1" stiffness="800" damping="80" armature="0.02" range="-150.00 150.00" />
            <geom type="box" contype="1" conaffinity="1" density="1000" pos="-0.0091 -0.0250 0.0535" size="0.0502 0.0216 0.0909" quat="1.0000 0.0000 0.0000 0.0000" />
            <body name="R_Toe" pos="-0.0338 -0.0534 0.1340">
              <joint name="R_Toe_x" type="hinge" pos="0 0 0" axis="1 0 0" stiffness="500" damping="50" armature="0.02" range="-150.00 150.00" />
              <joint name="R_Toe_y" type="hinge" pos="0 0 0" axis="0 1 0" stiffness="500" damping="50" armature="0.02" range="-150.00 150.00" />
              <joint name="R_Toe_z" type="hinge" pos="0 0 0" axis="0 0 1" stiffness="500" damping="50" armature="0.02" range="-150.00 150.00" />
              <geom type="box" contype="1" conaffinity="1" density="1000" pos="0.0091 0.0243 0.0545" size="0.0493 0.0209 0.0194" quat="1.0000 0.0000 0.0000 0.0000" />
            </body>
          </body>
        </body>
      </body>
      <body name="Torso" pos="-0.0012 0.1041 -0.0336">
        <joint name="Torso_x" type="hinge" pos="0 0 0" axis="1 0 0" stiffness="1000" damping="100" armature="0.02" range="-150.00 150.00" />
        <joint name="Torso_y" type="hinge" pos="0 0 0" axis="0 1 0" stiffness="1000" damping="100" armature="0.02" range="-150.00 150.00" />
        <joint name="Torso_z" type="hinge" pos="0 0 0" axis="0 0 1" stiffness="1000" damping="100" armature="0.02" range="-150.00 150.00" />
        <geom type="capsule" contype="1" conaffinity="1" density="1100" fromto="0.0042 0.0644 0.0032 0.0052 0.0787 0.0039" size="0.08" />
        <body name="Spine" pos="0.0094 0.1432 0.0071">
          <joint name="Spine_x" type="hinge" pos="0 0 0" axis="1 0 0" stiffness="1000" damping="100" armature="0.02" range="-150.00 150.00" />
          <joint name="Spine_y" type="hinge" pos="0 0 0" axis="0 1 0" stiffness="1000" damping="100" armature="0.02" range="-150.00 150.00" />
          <joint name="Spine_z" type="hinge" pos="0 0 0" axis="0 0 1" stiffness="1000" damping="100" armature="0.02" range="-150.00 150.00" />
          <geom type="capsule" contype="1" conaffinity="1" density="1100" fromto="-0.0035 0.0244 0.0084 -0.0043 0.0298 0.0103" size="0.06" />
          <body name="Chest" pos="-0.0078 0.0542 0.0186">
            <joint name="Chest_x" type="hinge" pos="0 0 0" axis="1 0 0" stiffness="1000" damping="100" armature="0.02" range="-150.00 150.00" />
            <joint name="Chest_y" type="hinge" pos="0 0 0" axis="0 1 0" stiffness="1000" damping="100" armature="0.02" range="-150.00 150.00" />
            <joint name="Chest_z" type="hinge" pos="0 0 0" axis="0 0 1" stiffness="1000" damping="100" armature="0.02" range="-150.00 150.00" />
            <geom type="capsule" contype="1" conaffinity="1" density="1100" fromto="-0.0010 0.0202 -0.0022 -0.0038 0.0809 -0.0088" size="0.08" />
            <body name="Neck" pos="-0.0100 0.1584 -0.0224">
              <joint name="Neck_x" type="hinge" pos="0 0 0" axis="1 0 0" stiffness="500" damping="50" armature="0.02" range="-150.00 150.00" />
              <joint name="Neck_y" type="hinge" pos="0 0 0" axis="0 1 0" stiffness="500" damping="50" armature="0.02" range="-150.00 150.00" />
              <joint name="Neck_z" type="hinge" pos="0 0 0" axis="0 0 1" stiffness="500" damping="50" armature="0.02" range="-150.00 150.00" />
              <geom type="capsule" contype="1" conaffinity="1" density="1000" fromto="0.0107 0.0737 0.0084 0.0131 0.0901 0.0102" size="0.0437" />
              <body name="Head" pos="0.0237 0.1639 0.0186">
                <joint name="Head_x" type="hinge" pos="0 0 0" axis="1 0 0" stiffness="500" damping="50" armature="0.02" range="-150.00 150.00" />
                <joint name="Head_y" type="hinge" pos="0 0 0" axis="0 1 0" stiffness="500" damping="50" armature="0.02" range="-150.00 150.00" />
                <joint name="Head_z" type="hinge" pos="0 0 0" axis="0 0 1" stiffness="500" damping="50" armature="0.02" range="-150.00 150.00" />
                <geom type="sphere" contype="1" conaffinity="1" density="1000" size="0.1054" pos="0.0000 0.0000 0.0000" name="Head" />
              </body>
            </body>
            <body name="L_Thorax" pos="0.0422 0.0724 -0.0041">
              <joint name="L_Thorax_x" type="hinge" pos="0 0 0" axis="1 0 0" stiffness="500" damping="50" armature="0.02" range="-150.00 150.00" />
              <joint name="L_Thorax_y" type="hinge" pos="0 0 0" axis="0 1 0" stiffness="500" damping="50" armature="0.02" range="-150.00 150.00" />
              <joint name="L_Thorax_z" type="hinge" pos="0 0 0" axis="0 0 1" stiffness="500" damping="50" armature="0.02" range="-150.00 150.00" />
              <geom type="capsule" contype="1" conaffinity="1" density="1000" fromto="0.0282 0.0121 -0.0020 0.1129 0.0485 -0.0080" size="0.0564" />
              <body name="L_Shoulder" pos="0.1412 0.0606 -0.0101">
                <joint name="L_Shoulder_x" type="hinge" pos="0 0 0" axis="1 0 0" stiffness="500" damping="50" armature="0.02" range="-150.00 150.00" />
                <joint name="L_Shoulder_y" type="hinge" pos="0 0 0" axis="0 1 0" stiffness="500" damping="50" armature="0.02" range="-150.00 150.00" />
                <joint name="L_Shoulder_z" type="hinge" pos="0 0 0" axis="0 0 1" stiffness="500" damping="50" armature="0.02" range="-150.00 150.00" />
                <geom type="capsule" contype="1" conaffinity="1" density="1000" fromto="0.0468 -0.0139 -0.0084 0.1871 -0.0557 -0.0335" size="0.0533" />
                <body name="L_Elbow" pos="0.2339 -0.0697 -0.0419">
                  <joint name="L_Elbow_x" type="hinge" pos="0 0 0" axis="1 0 0" stiffness="500" damping="50" armature="0.02" range="-150.00 150.00" />
                  <joint name="L_Elbow_y" type="hinge" pos="0 0 0" axis="0 1 0" stiffness="500" damping="50" armature="0.02" range="-150.00 150.00" />
                  <joint name="L_Elbow_z" type="hinge" pos="0 0 0" axis="0 0 1" stiffness="500" damping="50" armature="0.02" range="-150.00 150.00" />
                  <geom type="capsule" contype="1" conaffinity="1" density="1000" fromto="0.0500 0.0048 0.0001 0.1999 0.0193 0.0004" size="0.0418" />
                  <body name="L_Wrist" pos="0.2498 0.0241 0.0004">
                    <joint name="L_Wrist_x" type="hinge" pos="0 0 0" axis="1 0 0" stiffness="300" damping="30" armature="0.02" range="-150.00 150.00" />
                    <joint name="L_Wrist_y" type="hinge" pos="0 0 0" axis="0 1 0" stiffness="300" damping="30" armature="0.02" range="-150.00 150.00" />
                    <joint name="L_Wrist_z" type="hinge" pos="0 0 0" axis="0 0 1" stiffness="300" damping="30" armature="0.02" range="-150.00 150.00" />
                    <geom type="box" contype="1" conaffinity="1" density="1000" pos="0.0456 -0.0084 -0.0022" size="0.0444 0.0076 0.0414" quat="1.0000 0.0000 0.0000 0.0000" />
                    <body name="L_Index1" pos="0.0993 -0.0083 0.0216">
                      <joint name="L_Index1_x" type="hinge" pos="0 0 0" axis="1 0 0" stiffness="100" damping="10" armature="0.02" range="-23.24 18.56" />
                      <joint name="L_Index1_y" type="hinge" pos="0 0 0" axis="0 1 0" stiffness="100" damping="10" armature="0.02" range="-10.50 39.52" />
                      <joint name="L_Index1_z" type="hinge" pos="0 0 0" axis="0 0 1" stiffness="100" damping="10" armature="0.02" range="-102.46 24.43" />
                      <geom type="capsule" contype="1" conaffinity="1" density="1000" fromto="0.0065 0.0003 0.0007 0.0259 0.0013 0.0029" size="0.0065" />
                      <body name="L_Index2" pos="0.0324 0.0017 0.0036">
                        <joint name="L_Index2_x" type="hinge" pos="0 0 0" axis="1 0 0" stiffness="100" damping="10" armature="0.02" range="-13.56 17.83" />
                        <joint name="L_Index2_y" type="hinge" pos="0 0 0" axis="0 1 0" stiffness="100" damping="10" armature="0.02" range="-15.71 12.29" />
                        <joint name="L_Index2_z" type="hinge" pos="0 0 0" axis="0 0 1" stiffness="100" damping="10" armature="0.02" range="-115.75 13.69" />
                        <geom type="capsule" contype="1" conaffinity="1" density="1000" fromto="0.0046 -0.0006 -0.0001 0.0183 -0.0022 -0.0003" size="0.0053" />
                        <body name="L_Index3" pos="0.0229 -0.0028 -0.0003">
                          <joint name="L_Index3_x" type="hinge" pos="0 0 0" axis="1 0 0" stiffness="100" damping="10" armature="0.02" range="-15.59 17.52" />
                          <joint name="L_Index3_y" type="hinge" pos="0 0 0" axis="0 1 0" stiffness="100" damping="10" armature="0.02" range="-17.42 14.88" />
                          <joint name="L_Index3_z" type="hinge" pos="0 0 0" axis="0 0 1" stiffness="100" damping="10" armature="0.02" range="-66.73 58.07" />
                          <geom type="capsule" contype="1" conaffinity="1" density="1000" fromto="0.0051 -0.0006 -0.0001 0.0178 -0.0021 -0.0003" size="0.0047" />
                        </body>
                      </body>
                    </body>
                    <body name="L_Middle1" pos="0.1070 -0.0054 -0.0027">
                      <joint name="L_Middle1_x" type="hinge" pos="0 0 0" axis="1 0 0" stiffness="100" damping="10" armature="0.02" range="-31.66 7.71" />
                      <joint name="L_Middle1_y" type="hinge" pos="0 0 0" axis="0 1 0" stiffness="100" damping="10" armature="0.02" range="-18.43 33.63" />
                      <joint name="L_Middle1_z" type="hinge" pos="0 0 0" axis="0 0 1" stiffness="100" damping="10" armature="0.02" range="-114.52 5.28" />
                      <geom type="capsule" contype="1" conaffinity="1" density="1000" fromto="0.0062 0.0001 -0.0008 0.0248 0.0004 -0.0033" size="0.0067" />
                      <body name="L_Middle2" pos="0.0309 0.0005 -0.0041">
                        <joint name="L_Middle2_x" type="hinge" pos="0 0 0" axis="1 0 0" stiffness="100" damping="10" armature="0.02" range="-15.46 16.56" />
                        <joint name="L_Middle2_y" type="hinge" pos="0 0 0" axis="0 1 0" stiffness="100" damping="10" armature="0.02" range="-12.95 13.68" />
                        <joint name="L_Middle2_z" type="hinge" pos="0 0 0" axis="0 0 1" stiffness="100" damping="10" armature="0.02" range="-85.38 11.55" />
                        <geom type="capsule" contype="1" conaffinity="1" density="1000" fromto="0.0047 -0.0005 -0.0008 0.0189 -0.0020 -0.0034" size="0.0050" />
                        <body name="L_Middle3" pos="0.0236 -0.0024 -0.0042">
                          <joint name="L_Middle3_x" type="hinge" pos="0 0 0" axis="1 0 0" stiffness="100" damping="10" armature="0.02" range="-16.27 19.19" />
                          <joint name="L_Middle3_y" type="hinge" pos="0 0 0" axis="0 1 0" stiffness="100" damping="10" armature="0.02" range="-12.79 12.65" />
                          <joint name="L_Middle3_z" type="hinge" pos="0 0 0" axis="0 0 1" stiffness="100" damping="10" armature="0.02" range="-56.99 32.12" />
                          <geom type="capsule" contype="1" conaffinity="1" density="1000" fromto="0.0052 -0.0005 -0.0009 0.0184 -0.0019 -0.0033" size="0.0045" />
                        </body>
                      </body>
                    </body>
                    <body name="L_Pinky1" pos="0.0814 -0.0139 -0.0451">
                      <joint name="L_Pinky1_x" type="hinge" pos="0 0 0" axis="1 0 0" stiffness="100" damping="10" armature="0.02" range="-66.71 33.73" />
                      <joint name="L_Pinky1_y" type="hinge" pos="0 0 0" axis="0 1 0" stiffness="100" damping="10" armature="0.02" range="-48.87 3.93" />
                      <joint name="L_Pinky1_z" type="hinge" pos="0 0 0" axis="0 0 1" stiffness="100" damping="10" armature="0.02" range="-47.62 49.48" />
                      <geom type="capsule" contype="1" conaffinity="1" density="1000" fromto="0.0033 -0.0004 -0.0024 0.0132 -0.0016 -0.0094" size="0.0050" />
                      <body name="L_Pinky2" pos="0.0166 -0.0019 -0.0118">
                        <joint name="L_Pinky2_x" type="hinge" pos="0 0 0" axis="1 0 0" stiffness="100" damping="10" armature="0.02" range="-15.81 14.33" />
                        <joint name="L_Pinky2_y" type="hinge" pos="0 0 0" axis="0 1 0" stiffness="100" damping="10" armature="0.02" range="-15.73 13.93" />
                        <joint name="L_Pinky2_z" type="hinge" pos="0 0 0" axis="0 0 1" stiffness="100" damping="10" armature="0.02" range="-105.02 12.30" />
                        <geom type="capsule" contype="1" conaffinity="1" density="1000" fromto="0.0033 -0.0004 -0.0022 0.0131 -0.0017 -0.0088" size="0.0045" />
                        <body name="L_Pinky3" pos="0.0163 -0.0021 -0.0110">
                          <joint name="L_Pinky3_x" type="hinge" pos="0 0 0" axis="1 0 0" stiffness="100" damping="10" armature="0.02" range="-18.87 12.83" />
                          <joint name="L_Pinky3_y" type="hinge" pos="0 0 0" axis="0 1 0" stiffness="100" damping="10" armature="0.02" range="-12.54 14.17" />
                          <joint name="L_Pinky3_z" type="hinge" pos="0 0 0" axis="0 0 1" stiffness="100" damping="10" armature="0.02" range="-71.03 10.37" />
                          <geom type="capsule" contype="1" conaffinity="1" density="1000" fromto="0.0038 -0.0005 -0.0025 0.0126 -0.0016 -0.0085" size="0.0036" />
                        </body>
                      </body>
                    </body>
                    <body name="L_Ring1" pos="0.0949 -0.0081 -0.0274">
                      <joint name="L_Ring1_x" type="hinge" pos="0 0 0" axis="1 0 0" stiffness="100" damping="10" armature="0.02" range="-52.42 0.43" />
                      <joint name="L_Ring1_y" type="hinge" pos="0 0 0" axis="0 1 0" stiffness="100" damping="10" armature="0.02" range="-23.55 24.75" />
                      <joint name="L_Ring1_z" type="hinge" pos="0 0 0" axis="0 0 1" stiffness="100" damping="10" armature="0.02" range="-98.29 17.26" />
                      <geom type="capsule" contype="1" conaffinity="1" density="1000" fromto="0.0058 0.0002 -0.0009 0.0231 0.0006 -0.0037" size="0.0057" />
                      <body name="L_Ring2" pos="0.0288 0.0008 -0.0047">
                        <joint name="L_Ring2_x" type="hinge" pos="0 0 0" axis="1 0 0" stiffness="100" damping="10" armature="0.02" range="-16.29 12.37" />
                        <joint name="L_Ring2_y" type="hinge" pos="0 0 0" axis="0 1 0" stiffness="100" damping="10" armature="0.02" range="-10.64 13.91" />
                        <joint name="L_Ring2_z" type="hinge" pos="0 0 0" axis="0 0 1" stiffness="100" damping="10" armature="0.02" range="-112.46 10.73" />
                        <geom type="capsule" contype="1" conaffinity="1" density="1000" fromto="0.0047 -0.0005 -0.0013 0.0187 -0.0018 -0.0052" size="0.0051" />
                        <body name="L_Ring3" pos="0.0233 -0.0023 -0.0066">
                          <joint name="L_Ring3_x" type="hinge" pos="0 0 0" axis="1 0 0" stiffness="100" damping="10" armature="0.02" range="-16.99 13.49" />
                          <joint name="L_Ring3_y" type="hinge" pos="0 0 0" axis="0 1 0" stiffness="100" damping="10" armature="0.02" range="-10.88 13.94" />
                          <joint name="L_Ring3_z" type="hinge" pos="0 0 0" axis="0 0 1" stiffness="100" damping="10" armature="0.02" range="-76.41 10.28" />
                          <geom type="capsule" contype="1" conaffinity="1" density="1000" fromto="0.0052 -0.0005 -0.0015 0.0181 -0.0018 -0.0051" size="0.0043" />
                        </body>
                      </body>
                    </body>
                    <body name="L_Thumb1" pos="0.0380 -0.0196 0.0275">
                      <joint name="L_Thumb1_x" type="hinge" pos="0 0 0" axis="1 0 0" stiffness="100" damping="10" armature="0.02" range="48.13 131.34" />
                      <joint name="L_Thumb1_y" type="hinge" pos="0 0 0" axis="0 1 0" stiffness="100" damping="10" armature="0.02" range="-51.12 31.48" />
                      <joint name="L_Thumb1_z" type="hinge" pos="0 0 0" axis="0 0 1" stiffness="100" damping="10" armature="0.02" range="2.50 66.04" />
                      <geom type="capsule" contype="1" conaffinity="1" density="1000" fromto="0.0033 0.0004 0.0053 0.0133 0.0016 0.0212" size="0.0086" />
                      <body name="L_Thumb2" pos="0.0166 0.0020 0.0265">
                        <joint name="L_Thumb2_x" type="hinge" pos="0 0 0" axis="1 0 0" stiffness="100" damping="10" armature="0.02" range="-16.15 13.39" />
                        <joint name="L_Thumb2_y" type="hinge" pos="0 0 0" axis="0 1 0" stiffness="100" damping="10" armature="0.02" range="-13.48 20.50" />
                        <joint name="L_Thumb2_z" type="hinge" pos="0 0 0" axis="0 0 1" stiffness="100" damping="10" armature="0.02" range="-46.06 11.63" />
                        <geom type="capsule" contype="1" conaffinity="1" density="1000" fromto="0.0041 -0.0009 0.0033 0.0163 -0.0037 0.0130" size="0.0065" />
                        <body name="L_Thumb3" pos="0.0204 -0.0046 0.0163">
                          <joint name="L_Thumb3_x" type="hinge" pos="0 0 0" axis="1 0 0" stiffness="100" damping="10" armature="0.02" range="-19.62 16.75" />
                          <joint name="L_Thumb3_y" type="hinge" pos="0 0 0" axis="0 1 0" stiffness="100" damping="10" armature="0.02" range="-12.26 21.78" />
                          <joint name="L_Thumb3_z" type="hinge" pos="0 0 0" axis="0 0 1" stiffness="100" damping="10" armature="0.02" range="-46.51 47.56" />
                          <geom type="capsule" contype="1" conaffinity="1" density="1000" fromto="0.0038 -0.0009 0.0030 0.0166 -0.0037 0.0133" size="0.0062" />
                        </body>
                      </body>
                    </body>
                  </body>
                </body>
              </body>
            </body>
            <body name="R_Thorax" pos="-0.0465 0.0727 -0.0067">
              <joint name="R_Thorax_x" type="hinge" pos="0 0 0" axis="1 0 0" stiffness="500" damping="50" armature="0.02" range="-150.00 150.00" />
              <joint name="R_Thorax_y" type="hinge" pos="0 0 0" axis="0 1 0" stiffness="500" damping="50" armature="0.02" range="-150.00 150.00" />
              <joint name="R_Thorax_z" type="hinge" pos="0 0 0" axis="0 0 1" stiffness="500" damping="50" armature="0.02" range="-150.00 150.00" />
              <geom type="capsule" contype="1" conaffinity="1" density="1000" fromto="-0.0261 0.0117 -0.0017 -0.1045 0.0469 -0.0066" size="0.0576" />
              <body name="R_Shoulder" pos="-0.1306 0.0586 -0.0083">
                <joint name="R_Shoulder_x" type="hinge" pos="0 0 0" axis="1 0 0" stiffness="500" damping="50" armature="0.02" range="-150.00 150.00" />
                <joint name="R_Shoulder_y" type="hinge" pos="0 0 0" axis="0 1 0" stiffness="500" damping="50" armature="0.02" range="-150.00 150.00" />
                <joint name="R_Shoulder_z" type="hinge" pos="0 0 0" axis="0 0 1" stiffness="500" damping="50" armature="0.02" range="-150.00 150.00" />
                <geom type="capsule" contype="1" conaffinity="1" density="1000" fromto="-0.0501 -0.0078 -0.0059 -0.2003 -0.0314 -0.0238" size="0.0538" />
                <body name="R_Elbow" pos="-0.2504 -0.0392 -0.0297">
                  <joint name="R_Elbow_x" type="hinge" pos="0 0 0" axis="1 0 0" stiffness="500" damping="50" armature="0.02" range="-150.00 150.00" />
                  <joint name="R_Elbow_y" type="hinge" pos="0 0 0" axis="0 1 0" stiffness="500" damping="50" armature="0.02" range="-150.00 150.00" />
                  <joint name="R_Elbow_z" type="hinge" pos="0 0 0" axis="0 0 1" stiffness="500" damping="50" armature="0.02" range="-150.00 150.00" />
                  <geom type="capsule" contype="1" conaffinity="1" density="1000" fromto="-0.0486 -0.0002 -0.0020 -0.1942 -0.0007 -0.0079" size="0.042" />
                  <body name="R_Wrist" pos="-0.2428 -0.0009 -0.0099">
                    <joint name="R_Wrist_x" type="hinge" pos="0 0 0" axis="1 0 0" stiffness="300" damping="30" armature="0.02" range="-150.00 150.00" />
                    <joint name="R_Wrist_y" type="hinge" pos="0 0 0" axis="0 1 0" stiffness="300" damping="30" armature="0.02" range="-150.00 150.00" />
                    <joint name="R_Wrist_z" type="hinge" pos="0 0 0" axis="0 0 1" stiffness="300" damping="30" armature="0.02" range="-150.00 150.00" />
                    <geom type="box" contype="1" conaffinity="1" density="1000" pos="-0.0449 -0.0080 -0.0014" size="0.0416 0.0078 0.0414" quat="1.0000 0.0000 0.0000 0.0000" />
                    <body name="R_Index1" pos="-0.0989 -0.0119 0.0206">
                      <joint name="R_Index1_x" type="hinge" pos="0 0 0" axis="1 0 0" stiffness="100" damping="10" armature="0.02" range="-26.30 18.79" />
                      <joint name="R_Index1_y" type="hinge" pos="0 0 0" axis="0 1 0" stiffness="100" damping="10" armature="0.02" range="-34.92 12.14" />
                      <joint name="R_Index1_z" type="hinge" pos="0 0 0" axis="0 0 1" stiffness="100" damping="10" armature="0.02" range="-11.25 103.50" />
                      <geom type="capsule" contype="1" conaffinity="1" density="1000" fromto="-0.0065 0.0003 0.0007 -0.0259 0.0013 0.0029" size="0.0065" />
                      <body name="R_Index2" pos="-0.0324 0.0017 0.0036">
                        <joint name="R_Index2_x" type="hinge" pos="0 0 0" axis="1 0 0" stiffness="100" damping="10" armature="0.02" range="-15.10 16.96" />
                        <joint name="R_Index2_y" type="hinge" pos="0 0 0" axis="0 1 0" stiffness="100" damping="10" armature="0.02" range="-14.14 12.96" />
                        <joint name="R_Index2_z" type="hinge" pos="0 0 0" axis="0 0 1" stiffness="100" damping="10" armature="0.02" range="-11.74 117.30" />
                        <geom type="capsule" contype="1" conaffinity="1" density="1000" fromto="-0.0046 -0.0006 -0.0001 -0.0183 -0.0022 -0.0003" size="0.0053" />
                        <body name="R_Index3" pos="-0.0229 -0.0028 -0.0003">
                          <joint name="R_Index3_x" type="hinge" pos="0 0 0" axis="1 0 0" stiffness="100" damping="10" armature="0.02" range="-16.26 15.74" />
                          <joint name="R_Index3_y" type="hinge" pos="0 0 0" axis="0 1 0" stiffness="100" damping="10" armature="0.02" range="-14.45 16.96" />
                          <joint name="R_Index3_z" type="hinge" pos="0 0 0" axis="0 0 1" stiffness="100" damping="10" armature="0.02" range="-51.66 77.16" />
                          <geom type="capsule" contype="1" conaffinity="1" density="1000" fromto="-0.0055 -0.0007 -0.0001 -0.0174 -0.0021 -0.0003" size="0.0048" />
                        </body>
                      </body>
                    </body>
                    <body name="R_Middle1" pos="-0.1066 -0.0091 -0.0036">
                      <joint name="R_Middle1_x" type="hinge" pos="0 0 0" axis="1 0 0" stiffness="100" damping="10" armature="0.02" range="-38.73 7.19" />
                      <joint name="R_Middle1_y" type="hinge" pos="0 0 0" axis="0 1 0" stiffness="100" damping="10" armature="0.02" range="-48.29 27.77" />
                      <joint name="R_Middle1_z" type="hinge" pos="0 0 0" axis="0 0 1" stiffness="100" damping="10" armature="0.02" range="-25.12 107.75" />
                      <geom type="capsule" contype="1" conaffinity="1" density="1000" fromto="-0.0062 0.0001 -0.0008 -0.0248 0.0004 -0.0033" size="0.0067" />
                      <body name="R_Middle2" pos="-0.0309 0.0005 -0.0041">
                        <joint name="R_Middle2_x" type="hinge" pos="0 0 0" axis="1 0 0" stiffness="100" damping="10" armature="0.02" range="-17.29 15.55" />
                        <joint name="R_Middle2_y" type="hinge" pos="0 0 0" axis="0 1 0" stiffness="100" damping="10" armature="0.02" range="-14.84 11.35" />
                        <joint name="R_Middle2_z" type="hinge" pos="0 0 0" axis="0 0 1" stiffness="100" damping="10" armature="0.02" range="-11.54 120.52" />
                        <geom type="capsule" contype="1" conaffinity="1" density="1000" fromto="-0.0047 -0.0005 -0.0008 -0.0189 -0.0020 -0.0034" size="0.0050" />
                        <body name="R_Middle3" pos="-0.0236 -0.0024 -0.0042">
                          <joint name="R_Middle3_x" type="hinge" pos="0 0 0" axis="1 0 0" stiffness="100" damping="10" armature="0.02" range="-16.82 16.61" />
                          <joint name="R_Middle3_y" type="hinge" pos="0 0 0" axis="0 1 0" stiffness="100" damping="10" armature="0.02" range="-14.39 12.31" />
                          <joint name="R_Middle3_z" type="hinge" pos="0 0 0" axis="0 0 1" stiffness="100" damping="10" armature="0.02" range="-21.71 82.25" />
                          <geom type="capsule" contype="1" conaffinity="1" density="1000" fromto="-0.0055 -0.0006 -0.0010 -0.0181 -0.0019 -0.0032" size="0.0045" />
                        </body>
                      </body>
                    </body>
                    <body name="R_Pinky1" pos="-0.0810 -0.0176 -0.0461">
                      <joint name="R_Pinky1_x" type="hinge" pos="0 0 0" axis="1 0 0" stiffness="100" damping="10" armature="0.02" range="-74.32 -17.87" />
                      <joint name="R_Pinky1_y" type="hinge" pos="0 0 0" axis="0 1 0" stiffness="100" damping="10" armature="0.02" range="-69.97 59.01" />
                      <joint name="R_Pinky1_z" type="hinge" pos="0 0 0" axis="0 0 1" stiffness="100" damping="10" armature="0.02" range="-35.40 97.32" />
                      <geom type="capsule" contype="1" conaffinity="1" density="1000" fromto="-0.0033 -0.0004 -0.0024 -0.0132 -0.0016 -0.0094" size="0.0050" />
                      <body name="R_Pinky2" pos="-0.0166 -0.0019 -0.0118">
                        <joint name="R_Pinky2_x" type="hinge" pos="0 0 0" axis="1 0 0" stiffness="100" damping="10" armature="0.02" range="-19.33 13.55" />
                        <joint name="R_Pinky2_y" type="hinge" pos="0 0 0" axis="0 1 0" stiffness="100" damping="10" armature="0.02" range="-17.07 11.78" />
                        <joint name="R_Pinky2_z" type="hinge" pos="0 0 0" axis="0 0 1" stiffness="100" damping="10" armature="0.02" range="-10.52 114.99" />
                        <geom type="capsule" contype="1" conaffinity="1" density="1000" fromto="-0.0033 -0.0004 -0.0022 -0.0131 -0.0017 -0.0088" size="0.0045" />
                        <body name="R_Pinky3" pos="-0.0163 -0.0021 -0.0110">
                          <joint name="R_Pinky3_x" type="hinge" pos="0 0 0" axis="1 0 0" stiffness="100" damping="10" armature="0.02" range="-20.82 12.99" />
                          <joint name="R_Pinky3_y" type="hinge" pos="0 0 0" axis="0 1 0" stiffness="100" damping="10" armature="0.02" range="-17.69 13.09" />
                          <joint name="R_Pinky3_z" type="hinge" pos="0 0 0" axis="0 0 1" stiffness="100" damping="10" armature="0.02" range="-12.99 77.12" />
                          <geom type="capsule" contype="1" conaffinity="1" density="1000" fromto="-0.0040 -0.0005 -0.0027 -0.0123 -0.0016 -0.0083" size="0.0036" />
                        </body>
                      </body>
                    </body>
                    <body name="R_Ring1" pos="-0.0945 -0.0118 -0.0284">
                      <joint name="R_Ring1_x" type="hinge" pos="0 0 0" axis="1 0 0" stiffness="100" damping="10" armature="0.02" range="-59.88 -2.04" />
                      <joint name="R_Ring1_y" type="hinge" pos="0 0 0" axis="0 1 0" stiffness="100" damping="10" armature="0.02" range="-53.21 40.10" />
                      <joint name="R_Ring1_z" type="hinge" pos="0 0 0" axis="0 0 1" stiffness="100" damping="10" armature="0.02" range="-26.12 105.27" />
                      <geom type="capsule" contype="1" conaffinity="1" density="1000" fromto="-0.0058 0.0002 -0.0009 -0.0231 0.0006 -0.0037" size="0.0057" />
                      <body name="R_Ring2" pos="-0.0288 0.0008 -0.0047">
                        <joint name="R_Ring2_x" type="hinge" pos="0 0 0" axis="1 0 0" stiffness="100" damping="10" armature="0.02" range="-16.82 13.86" />
                        <joint name="R_Ring2_y" type="hinge" pos="0 0 0" axis="0 1 0" stiffness="100" damping="10" armature="0.02" range="-14.63 10.98" />
                        <joint name="R_Ring2_z" type="hinge" pos="0 0 0" axis="0 0 1" stiffness="100" damping="10" armature="0.02" range="-7.44 119.27" />
                        <geom type="capsule" contype="1" conaffinity="1" density="1000" fromto="-0.0047 -0.0005 -0.0013 -0.0187 -0.0018 -0.0052" size="0.0051" />
                        <body name="R_Ring3" pos="-0.0233 -0.0023 -0.0066">
                          <joint name="R_Ring3_x" type="hinge" pos="0 0 0" axis="1 0 0" stiffness="100" damping="10" armature="0.02" range="-17.01 13.83" />
                          <joint name="R_Ring3_y" type="hinge" pos="0 0 0" axis="0 1 0" stiffness="100" damping="10" armature="0.02" range="-14.26 11.70" />
                          <joint name="R_Ring3_z" type="hinge" pos="0 0 0" axis="0 0 1" stiffness="100" damping="10" armature="0.02" range="-10.98 80.97" />
                          <geom type="capsule" contype="1" conaffinity="1" density="1000" fromto="-0.0054 -0.0005 -0.0015 -0.0179 -0.0017 -0.0050" size="0.0043" />
                        </body>
                      </body>
                    </body>
                    <body name="R_Thumb1" pos="-0.0376 -0.0232 0.0265">
                      <joint name="R_Thumb1_x" type="hinge" pos="0 0 0" axis="1 0 0" stiffness="100" damping="10" armature="0.02" range="26.58 141.34" />
                      <joint name="R_Thumb1_y" type="hinge" pos="0 0 0" axis="0 1 0" stiffness="100" damping="10" armature="0.02" range="-36.03 30.28" />
                      <joint name="R_Thumb1_z" type="hinge" pos="0 0 0" axis="0 0 1" stiffness="100" damping="10" armature="0.02" range="-84.88 -5.95" />
                      <geom type="capsule" contype="1" conaffinity="1" density="1000" fromto="-0.0033 0.0004 0.0053 -0.0133 0.0016 0.0212" size="0.0086" />
                      <body name="R_Thumb2" pos="-0.0166 0.0020 0.0265">
                        <joint name="R_Thumb2_x" type="hinge" pos="0 0 0" axis="1 0 0" stiffness="100" damping="10" armature="0.02" range="-14.80 16.38" />
                        <joint name="R_Thumb2_y" type="hinge" pos="0 0 0" axis="0 1 0" stiffness="100" damping="10" armature="0.02" range="-15.79 14.10" />
                        <joint name="R_Thumb2_z" type="hinge" pos="0 0 0" axis="0 0 1" stiffness="100" damping="10" armature="0.02" range="-11.21 51.48" />
                        <geom type="capsule" contype="1" conaffinity="1" density="1000" fromto="-0.0041 -0.0009 0.0033 -0.0163 -0.0037 0.0130" size="0.0065" />
                        <body name="R_Thumb3" pos="-0.0204 -0.0046 0.0163">
                          <joint name="R_Thumb3_x" type="hinge" pos="0 0 0" axis="1 0 0" stiffness="100" damping="10" armature="0.02" range="-16.07 18.89" />
                          <joint name="R_Thumb3_y" type="hinge" pos="0 0 0" axis="0 1 0" stiffness="100" damping="10" armature="0.02" range="-18.58 12.55" />
                          <joint name="R_Thumb3_z" type="hinge" pos="0 0 0" axis="0 0 1" stiffness="100" damping="10" armature="0.02" range="-40.14 59.40" />
                          <geom type="capsule" contype="1" conaffinity="1" density="1000" fromto="-0.0046 -0.0010 0.0037 -0.0158 -0.0035 0.0126" size="0.0064" />
                        </body>
                      </body>
                    </body>
                  </body>
                </body>
              </body>
            </body>
          </body>
        </body>
      </body>
    </body>
  </worldbody>
  <actuator>
    <motor name="L_Hip_x" joint="L_Hip_x" gear="1" />
    <motor name="L_Hip_y" joint="L_Hip_y" gear="1" />
    <motor name="L_Hip_z" joint="L_Hip_z" gear="1" />
    <motor name="L_Knee_x" joint="L_Knee_x" gear="1" />
    <motor name="L_Knee_y" joint="L_Knee_y" gear="1" />
    <motor name="L_Knee_z" joint="L_Knee_z" gear="1" />
    <motor name="L_Ankle_x" joint="L_Ankle_x" gear="1" />
    <motor name="L_Ankle_y" joint="L_Ankle_y" gear="1" />
    <motor name="L_Ankle_z" joint="L_Ankle_z" gear="1" />
    <motor name="L_Toe_x" joint="L_Toe_x" gear="1" />
    <motor name="L_Toe_y" joint="L_Toe_y" gear="1" />
    <motor name="L_Toe_z" joint="L_Toe_z" gear="1" />
    <motor name="R_Hip_x" joint="R_Hip_x" gear="1" />
    <motor name="R_Hip_y" joint="R_Hip_y" gear="1" />
    <motor name="R_Hip_z" joint="R_Hip_z" gear="1" />
    <motor name="R_Knee_x" joint="R_Knee_x" gear="1" />
    <motor name="R_Knee_y" joint="R_Knee_y" gear="1" />
    <motor name="R_Knee_z" joint="R_Knee_z" gear="1" />
    <motor name="R_Ankle_x" joint="R_Ankle_x" gear="1" />
    <motor name="R_Ankle_y" joint="R_Ankle_y" gear="1" />
    <motor name="R_Ankle_z" joint="R_Ankle_z" gear="1" />
    <motor name="R_Toe_x" joint="R_Toe_x" gear="1" />
    <motor name="R_Toe_y" joint="R_Toe_y" gear="1" />
    <motor name="R_Toe_z" joint="R_Toe_z" gear="1" />
    <motor name="Torso_x" joint="Torso_x" gear="1" />
    <motor name="Torso_y" joint="Torso_y" gear="1" />
    <motor name="Torso_z" joint="Torso_z" gear="1" />
    <motor name="Spine_x" joint="Spine_x" gear="1" />
    <motor name="Spine_y" joint="Spine_y" gear="1" />
    <motor name="Spine_z" joint="Spine_z" gear="1" />
    <motor name="Chest_x" joint="Chest_x" gear="1" />
    <motor name="Chest_y" joint="Chest_y" gear="1" />
    <motor name="Chest_z" joint="Chest_z" gear="1" />
    <motor name="Neck_x" joint="Neck_x" gear="1" />
    <motor name="Neck_y" joint="Neck_y" gear="1" />
    <motor name="Neck_z" joint="Neck_z" gear="1" />
    <motor name="Head_x" joint="Head_x" gear="1" />
    <motor name="Head_y" joint="Head_y" gear="1" />
    <motor name="Head_z" joint="Head_z" gear="1" />
    <motor name="L_Thorax_x" joint="L_Thorax_x" gear="1" />
    <motor name="L_Thorax_y" joint="L_Thorax_y" gear="1" />
    <motor name="L_Thorax_z" joint="L_Thorax_z" gear="1" />
    <motor name="L_Shoulder_x" joint="L_Shoulder_x" gear="1" />
    <motor name="L_Shoulder_y" joint="L_Shoulder_y" gear="1" />
    <motor name="L_Shoulder_z" joint="L_Shoulder_z" gear="1" />
    <motor name="L_Elbow_x" joint="L_Elbow_x" gear="1" />
    <motor name="L_Elbow_y" joint="L_Elbow_y" gear="1" />
    <motor name="L_Elbow_z" joint="L_Elbow_z" gear="1" />
    <motor name="L_Wrist_x" joint="L_Wrist_x" gear="1" />
    <motor name="L_Wrist_y" joint="L_Wrist_y" gear="1" />
    <motor name="L_Wrist_z" joint="L_Wrist_z" gear="1" />
    <motor name="L_Index1_x" joint="L_Index1_x" gear="1" />
    <motor name="L_Index1_y" joint="L_Index1_y" gear="1" />
    <motor name="L_Index1_z" joint="L_Index1_z" gear="1" />
    <motor name="L_Index2_x" joint="L_Index2_x" gear="1" />
    <motor name="L_Index2_y" joint="L_Index2_y" gear="1" />
    <motor name="L_Index2_z" joint="L_Index2_z" gear="1" />
    <motor name="L_Index3_x" joint="L_Index3_x" gear="1" />
    <motor name="L_Index3_y" joint="L_Index3_y" gear="1" />
    <motor name="L_Index3_z" joint="L_Index3_z" gear="1" />
    <motor name="L_Middle1_x" joint="L_Middle1_x" gear="1" />
    <motor name="L_Middle1_y" joint="L_Middle1_y" gear="1" />
    <motor name="L_Middle1_z" joint="L_Middle1_z" gear="1" />
    <motor name="L_Middle2_x" joint="L_Middle2_x" gear="1" />
    <motor name="L_Middle2_y" joint="L_Middle2_y" gear="1" />
    <motor name="L_Middle2_z" joint="L_Middle2_z" gear="1" />
    <motor name="L_Middle3_x" joint="L_Middle3_x" gear="1" />
    <motor name="L_Middle3_y" joint="L_Middle3_y" gear="1" />
    <motor name="L_Middle3_z" joint="L_Middle3_z" gear="1" />
    <motor name="L_Pinky1_x" joint="L_Pinky1_x" gear="1" />
    <motor name="L_Pinky1_y" joint="L_Pinky1_y" gear="1" />
    <motor name="L_Pinky1_z" joint="L_Pinky1_z" gear="1" />
    <motor name="L_Pinky2_x" joint="L_Pinky2_x" gear="1" />
    <motor name="L_Pinky2_y" joint="L_Pinky2_y" gear="1" />
    <motor name="L_Pinky2_z" joint="L_Pinky2_z" gear="1" />
    <motor name="L_Pinky3_x" joint="L_Pinky3_x" gear="1" />
    <motor name="L_Pinky3_y" joint="L_Pinky3_y" gear="1" />
    <motor name="L_Pinky3_z" joint="L_Pinky3_z" gear="1" />
    <motor name="L_Ring1_x" joint="L_Ring1_x" gear="1" />
    <motor name="L_Ring1_y" joint="L_Ring1_y" gear="1" />
    <motor name="L_Ring1_z" joint="L_Ring1_z" gear="1" />
    <motor name="L_Ring2_x" joint="L_Ring2_x" gear="1" />
    <motor name="L_Ring2_y" joint="L_Ring2_y" gear="1" />
    <motor name="L_Ring2_z" joint="L_Ring2_z" gear="1" />
    <motor name="L_Ring3_x" joint="L_Ring3_x" gear="1" />
    <motor name="L_Ring3_y" joint="L_Ring3_y" gear="1" />
    <motor name="L_Ring3_z" joint="L_Ring3_z" gear="1" />
    <motor name="L_Thumb1_x" joint="L_Thumb1_x" gear="1" />
    <motor name="L_Thumb1_y" joint="L_Thumb1_y" gear="1" />
    <motor name="L_Thumb1_z" joint="L_Thumb1_z" gear="1" />
    <motor name="L_Thumb2_x" joint="L_Thumb2_x" gear="1" />
    <motor name="L_Thumb2_y" joint="L_Thumb2_y" gear="1" />
    <motor name="L_Thumb2_z" joint="L_Thumb2_z" gear="1" />
    <motor name="L_Thumb3_x" joint="L_Thumb3_x" gear="1" />
    <motor name="L_Thumb3_y" joint="L_Thumb3_y" gear="1" />
    <motor name="L_Thumb3_z" joint="L_Thumb3_z" gear="1" />
    <motor name="R_Thorax_x" joint="R_Thorax_x" gear="1" />
    <motor name="R_Thorax_y" joint="R_Thorax_y" gear="1" />
    <motor name="R_Thorax_z" joint="R_Thorax_z" gear="1" />
    <motor name="R_Shoulder_x" joint="R_Shoulder_x" gear="1" />
    <motor name="R_Shoulder_y" joint="R_Shoulder_y" gear="1" />
    <motor name="R_Shoulder_z" joint="R_Shoulder_z" gear="1" />
    <motor name="R_Elbow_x" joint="R_Elbow_x" gear="1" />
    <motor name="R_Elbow_y" joint="R_Elbow_y" gear="1" />
    <motor name="R_Elbow_z" joint="R_Elbow_z" gear="1" />
    <motor name="R_Wrist_x" joint="R_Wrist_x" gear="1" />
    <motor name="R_Wrist_y" joint="R_Wrist_y" gear="1" />
    <motor name="R_Wrist_z" joint="R_Wrist_z" gear="1" />
    <motor name="R_Index1_x" joint="R_Index1_x" gear="1" />
    <motor name="R_Index1_y" joint="R_Index1_y" gear="1" />
    <motor name="R_Index1_z" joint="R_Index1_z" gear="1" />
    <motor name="R_Index2_x" joint="R_Index2_x" gear="1" />
    <motor name="R_Index2_y" joint="R_Index2_y" gear="1" />
    <motor name="R_Index2_z" joint="R_Index2_z" gear="1" />
    <motor name="R_Index3_x" joint="R_Index3_x" gear="1" />
    <motor name="R_Index3_y" joint="R_Index3_y" gear="1" />
    <motor name="R_Index3_z" joint="R_Index3_z" gear="1" />
    <motor name="R_Middle1_x" joint="R_Middle1_x" gear="1" />
    <motor name="R_Middle1_y" joint="R_Middle1_y" gear="1" />
    <motor name="R_Middle1_z" joint="R_Middle1_z" gear="1" />
    <motor name="R_Middle2_x" joint="R_Middle2_x" gear="1" />
    <motor name="R_Middle2_y" joint="R_Middle2_y" gear="1" />
    <motor name="R_Middle2_z" joint="R_Middle2_z" gear="1" />
    <motor name="R_Middle3_x" joint="R_Middle3_x" gear="1" />
    <motor name="R_Middle3_y" joint="R_Middle3_y" gear="1" />
    <motor name="R_Middle3_z" joint="R_Middle3_z" gear="1" />
    <motor name="R_Pinky1_x" joint="R_Pinky1_x" gear="1" />
    <motor name="R_Pinky1_y" joint="R_Pinky1_y" gear="1" />
    <motor name="R_Pinky1_z" joint="R_Pinky1_z" gear="1" />
    <motor name="R_Pinky2_x" joint="R_Pinky2_x" gear="1" />
    <motor name="R_Pinky2_y" joint="R_Pinky2_y" gear="1" />
    <motor name="R_Pinky2_z" joint="R_Pinky2_z" gear="1" />
    <motor name="R_Pinky3_x" joint="R_Pinky3_x" gear="1" />
    <motor name="R_Pinky3_y" joint="R_Pinky3_y" gear="1" />
    <motor name="R_Pinky3_z" joint="R_Pinky3_z" gear="1" />
    <motor name="R_Ring1_x" joint="R_Ring1_x" gear="1" />
    <motor name="R_Ring1_y" joint="R_Ring1_y" gear="1" />
    <motor name="R_Ring1_z" joint="R_Ring1_z" gear="1" />
    <motor name="R_Ring2_x" joint="R_Ring2_x" gear="1" />
    <motor name="R_Ring2_y" joint="R_Ring2_y" gear="1" />
    <motor name="R_Ring2_z" joint="R_Ring2_z" gear="1" />
    <motor name="R_Ring3_x" joint="R_Ring3_x" gear="1" />
    <motor name="R_Ring3_y" joint="R_Ring3_y" gear="1" />
    <motor name="R_Ring3_z" joint="R_Ring3_z" gear="1" />
    <motor name="R_Thumb1_x" joint="R_Thumb1_x" gear="1" />
    <motor name="R_Thumb1_y" joint="R_Thumb1_y" gear="1" />
    <motor name="R_Thumb1_z" joint="R_Thumb1_z" gear="1" />
    <motor name="R_Thumb2_x" joint="R_Thumb2_x" gear="1" />
    <motor name="R_Thumb2_y" joint="R_Thumb2_y" gear="1" />
    <motor name="R_Thumb2_z" joint="R_Thumb2_z" gear="1" />
    <motor name="R_Thumb3_x" joint="R_Thumb3_x" gear="1" />
    <motor name="R_Thumb3_y" joint="R_Thumb3_y" gear="1" />
    <motor name="R_Thumb3_z" joint="R_Thumb3_z" gear="1" />
  </actuator>
  <contact />
  <sensor />
  <size njmax="700" nconmax="700" />
</mujoco>
