<?xml version='1.0' encoding='utf-8'?>
<mujoco model="smplx_mapped_s79">
  <compiler coordinate="local" />
  <default>
    <joint damping="0.0" armature="0.01" stiffness="0.0" limited="true" />
    <geom conaffinity="1" condim="3" contype="7" margin="0.001" rgba="0.8 0.6 .4 1" />
  </default>
  <asset>
    <texture type="skybox" builtin="gradient" rgb1=".4 .5 .6" rgb2="0 0 0" width="100" height="100" />
    <texture builtin="flat" height="1278" mark="cross" markrgb="1 1 1" name="texgeom" random="0.01" rgb1="0.8 0.6 0.4" rgb2="0.8 0.6 0.4" type="cube" width="127" />
    <texture builtin="checker" height="100" name="texplane" rgb1="0 0 0" rgb2="0.8 0.8 0.8" type="2d" width="100" />
    <material name="MatPlane" reflectance="0.5" shininess="1" specular="1" texrepeat="60 60" texture="texplane" />
    <material name="geom" texture="texgeom" texuniform="true" />
  </asset>
  <worldbody>
    <light cutoff="100" diffuse="1 1 1" dir="-0 0 -1.3" directional="true" exponent="1" pos="0 0 1.3" specular=".1 .1 .1" />
    <geom conaffinity="1" condim="3" name="floor" pos="0 0 0" rgba="0.8 0.9 0.8 1" size="100 100 .2" type="plane" material="MatPlane" />
    <body name="Pelvis" pos="0.0005 -0.3426 0.0059">
      <freejoint name="Pelvis" />
      <geom type="sphere" contype="1" conaffinity="1" density="4629.6296296296305" size="0.09" pos="0.0000 0.0000 0.0000" name="Pelvis" />
      <body name="L_Hip" pos="0.0672 -0.0860 -0.0167">
        <joint name="L_Hip_x" type="hinge" pos="0 0 0" axis="1 0 0" stiffness="800" damping="80" armature="0.02" range="-150.00 150.00" />
        <joint name="L_Hip_y" type="hinge" pos="0 0 0" axis="0 1 0" stiffness="800" damping="80" armature="0.02" range="-150.00 150.00" />
        <joint name="L_Hip_z" type="hinge" pos="0 0 0" axis="0 0 1" stiffness="800" damping="80" armature="0.02" range="-150.00 150.00" />
        <geom type="capsule" contype="1" conaffinity="1" density="2040.816327" fromto="0.0055 -0.0745 -0.0031 0.0221 -0.2980 -0.0124" size="0.059" />
        <body name="L_Knee" pos="0.0277 -0.3725 -0.0155">
          <joint name="L_Knee_x" type="hinge" pos="0 0 0" axis="1 0 0" stiffness="800" damping="80" armature="0.02" range="-150.00 150.00" />
          <joint name="L_Knee_y" type="hinge" pos="0 0 0" axis="0 1 0" stiffness="800" damping="80" armature="0.02" range="-150.00 150.00" />
          <joint name="L_Knee_z" type="hinge" pos="0 0 0" axis="0 0 1" stiffness="800" damping="80" armature="0.02" range="-150.00 150.00" />
          <geom type="capsule" contype="1" conaffinity="1" density="1234.567901" fromto="-0.0012 -0.0766 -0.0036 -0.0049 -0.3063 -0.0144" size="0.0564" />
          <body name="L_Ankle" pos="-0.0061 -0.3829 -0.0180">
            <joint name="L_Ankle_x" type="hinge" pos="0 0 0" axis="1 0 0" stiffness="800" damping="80" armature="0.02" range="-150.00 150.00" />
            <joint name="L_Ankle_y" type="hinge" pos="0 0 0" axis="0 1 0" stiffness="800" damping="80" armature="0.02" range="-150.00 150.00" />
            <joint name="L_Ankle_z" type="hinge" pos="0 0 0" axis="0 0 1" stiffness="800" damping="80" armature="0.02" range="-150.00 150.00" />
            <geom type="box" contype="1" conaffinity="1" density="1000" pos="0.0115 -0.0234 0.0566" size="0.0502 0.0216 0.0909" quat="1.0000 0.0000 0.0000 0.0000" />
            <body name="L_Toe" pos="0.0205 -0.0442 0.1058">
              <joint name="L_Toe_x" type="hinge" pos="0 0 0" axis="1 0 0" stiffness="500" damping="50" armature="0.02" range="-150.00 150.00" />
              <joint name="L_Toe_y" type="hinge" pos="0 0 0" axis="0 1 0" stiffness="500" damping="50" armature="0.02" range="-150.00 150.00" />
              <joint name="L_Toe_z" type="hinge" pos="0 0 0" axis="0 0 1" stiffness="500" damping="50" armature="0.02" range="-150.00 150.00" />
              <geom type="box" contype="1" conaffinity="1" density="1000" pos="-0.0115 0.0227 0.0576" size="0.0493 0.0209 0.0194" quat="1.0000 0.0000 0.0000 0.0000" />
            </body>
          </body>
        </body>
      </body>
      <body name="R_Hip" pos="-0.0662 -0.0927 -0.0177">
        <joint name="R_Hip_x" type="hinge" pos="0 0 0" axis="1 0 0" stiffness="800" damping="80" armature="0.02" range="-150.00 150.00" />
        <joint name="R_Hip_y" type="hinge" pos="0 0 0" axis="0 1 0" stiffness="800" damping="80" armature="0.02" range="-150.00 150.00" />
        <joint name="R_Hip_z" type="hinge" pos="0 0 0" axis="0 0 1" stiffness="800" damping="80" armature="0.02" range="-150.00 150.00" />
        <geom type="capsule" contype="1" conaffinity="1" density="2040.816327" fromto="-0.0063 -0.0736 -0.0020 -0.0253 -0.2944 -0.0081" size="0.0588" />
        <body name="R_Knee" pos="-0.0316 -0.3681 -0.0102">
          <joint name="R_Knee_x" type="hinge" pos="0 0 0" axis="1 0 0" stiffness="800" damping="80" armature="0.02" range="-150.00 150.00" />
          <joint name="R_Knee_y" type="hinge" pos="0 0 0" axis="0 1 0" stiffness="800" damping="80" armature="0.02" range="-150.00 150.00" />
          <joint name="R_Knee_z" type="hinge" pos="0 0 0" axis="0 0 1" stiffness="800" damping="80" armature="0.02" range="-150.00 150.00" />
          <geom type="capsule" contype="1" conaffinity="1" density="1234.567901" fromto="0.0003 -0.0749 -0.0028 0.0012 -0.2995 -0.0111" size="0.0564" />
          <body name="R_Ankle" pos="0.0015 -0.3744 -0.0139">
            <joint name="R_Ankle_x" type="hinge" pos="0 0 0" axis="1 0 0" stiffness="800" damping="80" armature="0.02" range="-150.00 150.00" />
            <joint name="R_Ankle_y" type="hinge" pos="0 0 0" axis="0 1 0" stiffness="800" damping="80" armature="0.02" range="-150.00 150.00" />
            <joint name="R_Ankle_z" type="hinge" pos="0 0 0" axis="0 0 1" stiffness="800" damping="80" armature="0.02" range="-150.00 150.00" />
            <geom type="box" contype="1" conaffinity="1" density="1000" pos="-0.0091 -0.0250 0.0535" size="0.0502 0.0216 0.0909" quat="1.0000 0.0000 0.0000 0.0000" />
            <body name="R_Toe" pos="-0.0164 -0.0479 0.0996">
              <joint name="R_Toe_x" type="hinge" pos="0 0 0" axis="1 0 0" stiffness="500" damping="50" armature="0.02" range="-150.00 150.00" />
              <joint name="R_Toe_y" type="hinge" pos="0 0 0" axis="0 1 0" stiffness="500" damping="50" armature="0.02" range="-150.00 150.00" />
              <joint name="R_Toe_z" type="hinge" pos="0 0 0" axis="0 0 1" stiffness="500" damping="50" armature="0.02" range="-150.00 150.00" />
              <geom type="box" contype="1" conaffinity="1" density="1000" pos="0.0091 0.0243 0.0545" size="0.0493 0.0209 0.0194" quat="1.0000 0.0000 0.0000 0.0000" />
            </body>
          </body>
        </body>
      </body>
      <body name="Torso" pos="-0.0055 0.0987 -0.0229">
        <joint name="Torso_x" type="hinge" pos="0 0 0" axis="1 0 0" stiffness="1000" damping="100" armature="0.02" range="-150.00 150.00" />
        <joint name="Torso_y" type="hinge" pos="0 0 0" axis="0 1 0" stiffness="1000" damping="100" armature="0.02" range="-150.00 150.00" />
        <joint name="Torso_z" type="hinge" pos="0 0 0" axis="0 0 1" stiffness="1000" damping="100" armature="0.02" range="-150.00 150.00" />
        <geom type="capsule" contype="1" conaffinity="1" density="1100" fromto="0.0046 0.0522 -0.0019 0.0056 0.0638 -0.0023" size="0.08" />
        <body name="Spine" pos="0.0102 0.1160 -0.0042">
          <joint name="Spine_x" type="hinge" pos="0 0 0" axis="1 0 0" stiffness="1000" damping="100" armature="0.02" range="-150.00 150.00" />
          <joint name="Spine_y" type="hinge" pos="0 0 0" axis="0 1 0" stiffness="1000" damping="100" armature="0.02" range="-150.00 150.00" />
          <joint name="Spine_z" type="hinge" pos="0 0 0" axis="0 0 1" stiffness="1000" damping="100" armature="0.02" range="-150.00 150.00" />
          <geom type="capsule" contype="1" conaffinity="1" density="1100" fromto="-0.0024 0.0203 0.0130 -0.0030 0.0248 0.0159" size="0.06" />
          <body name="Chest" pos="-0.0054 0.0451 0.0289">
            <joint name="Chest_x" type="hinge" pos="0 0 0" axis="1 0 0" stiffness="1000" damping="100" armature="0.02" range="-150.00 150.00" />
            <joint name="Chest_y" type="hinge" pos="0 0 0" axis="0 1 0" stiffness="1000" damping="100" armature="0.02" range="-150.00 150.00" />
            <joint name="Chest_z" type="hinge" pos="0 0 0" axis="0 0 1" stiffness="1000" damping="100" armature="0.02" range="-150.00 150.00" />
            <geom type="capsule" contype="1" conaffinity="1" density="1100" fromto="-0.0006 0.0281 -0.0046 -0.0025 0.1124 -0.0185" size="0.08" />
            <body name="Neck" pos="-0.0062 0.1953 -0.0366">
              <joint name="Neck_x" type="hinge" pos="0 0 0" axis="1 0 0" stiffness="500" damping="50" armature="0.02" range="-150.00 150.00" />
              <joint name="Neck_y" type="hinge" pos="0 0 0" axis="0 1 0" stiffness="500" damping="50" armature="0.02" range="-150.00 150.00" />
              <joint name="Neck_z" type="hinge" pos="0 0 0" axis="0 0 1" stiffness="500" damping="50" armature="0.02" range="-150.00 150.00" />
              <geom type="capsule" contype="1" conaffinity="1" density="1000" fromto="0.0041 0.0695 0.0090 0.0050 0.0849 0.0111" size="0.0437" />
              <body name="Head" pos="0.0092 0.1544 0.0201">
                <joint name="Head_x" type="hinge" pos="0 0 0" axis="1 0 0" stiffness="500" damping="50" armature="0.02" range="-150.00 150.00" />
                <joint name="Head_y" type="hinge" pos="0 0 0" axis="0 1 0" stiffness="500" damping="50" armature="0.02" range="-150.00 150.00" />
                <joint name="Head_z" type="hinge" pos="0 0 0" axis="0 0 1" stiffness="500" damping="50" armature="0.02" range="-150.00 150.00" />
                <geom type="sphere" contype="1" conaffinity="1" density="1000" size="0.1054" pos="0.0000 0.0000 0.0000" name="Head" />
              </body>
            </body>
            <body name="L_Thorax" pos="0.0569 0.1152 -0.0134">
              <joint name="L_Thorax_x" type="hinge" pos="0 0 0" axis="1 0 0" stiffness="500" damping="50" armature="0.02" range="-150.00 150.00" />
              <joint name="L_Thorax_y" type="hinge" pos="0 0 0" axis="0 1 0" stiffness="500" damping="50" armature="0.02" range="-150.00 150.00" />
              <joint name="L_Thorax_z" type="hinge" pos="0 0 0" axis="0 0 1" stiffness="500" damping="50" armature="0.02" range="-150.00 150.00" />
              <geom type="capsule" contype="1" conaffinity="1" density="1000" fromto="0.0199 0.0093 -0.0058 0.0798 0.0373 -0.0233" size="0.0564" />
              <body name="L_Shoulder" pos="0.0997 0.0466 -0.0291">
                <joint name="L_Shoulder_x" type="hinge" pos="0 0 0" axis="1 0 0" stiffness="500" damping="50" armature="0.02" range="-150.00 150.00" />
                <joint name="L_Shoulder_y" type="hinge" pos="0 0 0" axis="0 1 0" stiffness="500" damping="50" armature="0.02" range="-150.00 150.00" />
                <joint name="L_Shoulder_z" type="hinge" pos="0 0 0" axis="0 0 1" stiffness="500" damping="50" armature="0.02" range="-150.00 150.00" />
                <geom type="capsule" contype="1" conaffinity="1" density="1000" fromto="0.0542 -0.0105 -0.0053 0.2166 -0.0421 -0.0213" size="0.0533" />
                <body name="L_Elbow" pos="0.2708 -0.0526 -0.0266">
                  <joint name="L_Elbow_x" type="hinge" pos="0 0 0" axis="1 0 0" stiffness="500" damping="50" armature="0.02" range="-150.00 150.00" />
                  <joint name="L_Elbow_y" type="hinge" pos="0 0 0" axis="0 1 0" stiffness="500" damping="50" armature="0.02" range="-150.00 150.00" />
                  <joint name="L_Elbow_z" type="hinge" pos="0 0 0" axis="0 0 1" stiffness="500" damping="50" armature="0.02" range="-150.00 150.00" />
                  <geom type="capsule" contype="1" conaffinity="1" density="1000" fromto="0.0441 0.0016 0.0008 0.1763 0.0064 0.0033" size="0.0418" />
                  <body name="L_Wrist" pos="0.2203 0.0081 0.0041">
                    <joint name="L_Wrist_x" type="hinge" pos="0 0 0" axis="1 0 0" stiffness="300" damping="30" armature="0.02" range="-150.00 150.00" />
                    <joint name="L_Wrist_y" type="hinge" pos="0 0 0" axis="0 1 0" stiffness="300" damping="30" armature="0.02" range="-150.00 150.00" />
                    <joint name="L_Wrist_z" type="hinge" pos="0 0 0" axis="0 0 1" stiffness="300" damping="30" armature="0.02" range="-150.00 150.00" />
                    <geom type="box" contype="1" conaffinity="1" density="1000" pos="0.0456 -0.0084 -0.0022" size="0.0444 0.0076 0.0414" quat="1.0000 0.0000 0.0000 0.0000" />
                    <body name="L_Index1" pos="0.0960 -0.0143 0.0191">
                      <joint name="L_Index1_x" type="hinge" pos="0 0 0" axis="1 0 0" stiffness="100" damping="10" armature="0.02" range="-25.78 22.04" />
                      <joint name="L_Index1_y" type="hinge" pos="0 0 0" axis="0 1 0" stiffness="100" damping="10" armature="0.02" range="-11.88 38.72" />
                      <joint name="L_Index1_z" type="hinge" pos="0 0 0" axis="0 0 1" stiffness="100" damping="10" armature="0.02" range="-100.14 36.73" />
                      <geom type="capsule" contype="1" conaffinity="1" density="1000" fromto="0.0061 0.0006 0.0006 0.0245 0.0022 0.0023" size="0.0065" />
                      <body name="L_Index2" pos="0.0307 0.0028 0.0028">
                        <joint name="L_Index2_x" type="hinge" pos="0 0 0" axis="1 0 0" stiffness="100" damping="10" armature="0.02" range="-17.95 16.92" />
                        <joint name="L_Index2_y" type="hinge" pos="0 0 0" axis="0 1 0" stiffness="100" damping="10" armature="0.02" range="-14.71 13.03" />
                        <joint name="L_Index2_z" type="hinge" pos="0 0 0" axis="0 0 1" stiffness="100" damping="10" armature="0.02" range="-111.25 10.70" />
                        <geom type="capsule" contype="1" conaffinity="1" density="1000" fromto="0.0043 -0.0003 0.0001 0.0174 -0.0010 0.0006" size="0.0053" />
                        <body name="L_Index3" pos="0.0217 -0.0013 0.0007">
                          <joint name="L_Index3_x" type="hinge" pos="0 0 0" axis="1 0 0" stiffness="100" damping="10" armature="0.02" range="-19.18 20.30" />
                          <joint name="L_Index3_y" type="hinge" pos="0 0 0" axis="0 1 0" stiffness="100" damping="10" armature="0.02" range="-18.00 13.62" />
                          <joint name="L_Index3_z" type="hinge" pos="0 0 0" axis="0 0 1" stiffness="100" damping="10" armature="0.02" range="-60.19 51.54" />
                          <geom type="capsule" contype="1" conaffinity="1" density="1000" fromto="0.0045 -0.0003 0.0001 0.0172 -0.0010 0.0006" size="0.0047" />
                        </body>
                      </body>
                    </body>
                    <body name="L_Middle1" pos="0.1027 -0.0118 -0.0030">
                      <joint name="L_Middle1_x" type="hinge" pos="0 0 0" axis="1 0 0" stiffness="100" damping="10" armature="0.02" range="-37.36 22.46" />
                      <joint name="L_Middle1_y" type="hinge" pos="0 0 0" axis="0 1 0" stiffness="100" damping="10" armature="0.02" range="-42.85 37.79" />
                      <joint name="L_Middle1_z" type="hinge" pos="0 0 0" axis="0 0 1" stiffness="100" damping="10" armature="0.02" range="-119.29 43.86" />
                      <geom type="capsule" contype="1" conaffinity="1" density="1000" fromto="0.0058 0.0003 -0.0007 0.0232 0.0011 -0.0029" size="0.0067" />
                      <body name="L_Middle2" pos="0.0290 0.0014 -0.0037">
                        <joint name="L_Middle2_x" type="hinge" pos="0 0 0" axis="1 0 0" stiffness="100" damping="10" armature="0.02" range="-17.26 16.16" />
                        <joint name="L_Middle2_y" type="hinge" pos="0 0 0" axis="0 1 0" stiffness="100" damping="10" armature="0.02" range="-14.56 13.31" />
                        <joint name="L_Middle2_z" type="hinge" pos="0 0 0" axis="0 0 1" stiffness="100" damping="10" armature="0.02" range="-100.60 10.35" />
                        <geom type="capsule" contype="1" conaffinity="1" density="1000" fromto="0.0045 -0.0001 -0.0007 0.0180 -0.0004 -0.0029" size="0.0050" />
                        <body name="L_Middle3" pos="0.0225 -0.0005 -0.0036">
                          <joint name="L_Middle3_x" type="hinge" pos="0 0 0" axis="1 0 0" stiffness="100" damping="10" armature="0.02" range="-17.34 18.49" />
                          <joint name="L_Middle3_y" type="hinge" pos="0 0 0" axis="0 1 0" stiffness="100" damping="10" armature="0.02" range="-15.13 14.88" />
                          <joint name="L_Middle3_z" type="hinge" pos="0 0 0" axis="0 0 1" stiffness="100" damping="10" armature="0.02" range="-61.85 51.20" />
                          <geom type="capsule" contype="1" conaffinity="1" density="1000" fromto="0.0046 -0.0001 -0.0007 0.0180 -0.0004 -0.0028" size="0.0045" />
                        </body>
                      </body>
                    </body>
                    <body name="L_Pinky1" pos="0.0783 -0.0193 -0.0410">
                      <joint name="L_Pinky1_x" type="hinge" pos="0 0 0" axis="1 0 0" stiffness="100" damping="10" armature="0.02" range="-79.75 21.14" />
                      <joint name="L_Pinky1_y" type="hinge" pos="0 0 0" axis="0 1 0" stiffness="100" damping="10" armature="0.02" range="-41.50 45.42" />
                      <joint name="L_Pinky1_z" type="hinge" pos="0 0 0" axis="0 0 1" stiffness="100" damping="10" armature="0.02" range="-112.93 33.63" />
                      <geom type="capsule" contype="1" conaffinity="1" density="1000" fromto="0.0028 -0.0001 -0.0024 0.0112 -0.0004 -0.0094" size="0.0050" />
                      <body name="L_Pinky2" pos="0.0140 -0.0004 -0.0118">
                        <joint name="L_Pinky2_x" type="hinge" pos="0 0 0" axis="1 0 0" stiffness="100" damping="10" armature="0.02" range="-22.28 12.09" />
                        <joint name="L_Pinky2_y" type="hinge" pos="0 0 0" axis="0 1 0" stiffness="100" damping="10" armature="0.02" range="-12.50 17.79" />
                        <joint name="L_Pinky2_z" type="hinge" pos="0 0 0" axis="0 0 1" stiffness="100" damping="10" armature="0.02" range="-120.29 13.29" />
                        <geom type="capsule" contype="1" conaffinity="1" density="1000" fromto="0.0029 -0.0002 -0.0023 0.0114 -0.0006 -0.0091" size="0.0045" />
                        <body name="L_Pinky3" pos="0.0143 -0.0008 -0.0114">
                          <joint name="L_Pinky3_x" type="hinge" pos="0 0 0" axis="1 0 0" stiffness="100" damping="10" armature="0.02" range="-20.19 130.76" />
                          <joint name="L_Pinky3_y" type="hinge" pos="0 0 0" axis="0 1 0" stiffness="100" damping="10" armature="0.02" range="-13.40 104.90" />
                          <joint name="L_Pinky3_z" type="hinge" pos="0 0 0" axis="0 0 1" stiffness="100" damping="10" armature="0.02" range="-79.33 91.00" />
                          <geom type="capsule" contype="1" conaffinity="1" density="1000" fromto="0.0030 -0.0002 -0.0024 0.0113 -0.0006 -0.0090" size="0.0036" />
                        </body>
                      </body>
                    </body>
                    <body name="L_Ring1" pos="0.0911 -0.0144 -0.0254">
                      <joint name="L_Ring1_x" type="hinge" pos="0 0 0" axis="1 0 0" stiffness="100" damping="10" armature="0.02" range="-54.83 24.79" />
                      <joint name="L_Ring1_y" type="hinge" pos="0 0 0" axis="0 1 0" stiffness="100" damping="10" armature="0.02" range="-27.28 40.42" />
                      <joint name="L_Ring1_z" type="hinge" pos="0 0 0" axis="0 0 1" stiffness="100" damping="10" armature="0.02" range="-119.24 23.67" />
                      <geom type="capsule" contype="1" conaffinity="1" density="1000" fromto="0.0053 0.0003 -0.0011 0.0212 0.0013 -0.0042" size="0.0057" />
                      <body name="L_Ring2" pos="0.0265 0.0016 -0.0053">
                        <joint name="L_Ring2_x" type="hinge" pos="0 0 0" axis="1 0 0" stiffness="100" damping="10" armature="0.02" range="-19.64 14.40" />
                        <joint name="L_Ring2_y" type="hinge" pos="0 0 0" axis="0 1 0" stiffness="100" damping="10" armature="0.02" range="-16.20 15.12" />
                        <joint name="L_Ring2_z" type="hinge" pos="0 0 0" axis="0 0 1" stiffness="100" damping="10" armature="0.02" range="-113.79 10.28" />
                        <geom type="capsule" contype="1" conaffinity="1" density="1000" fromto="0.0043 -0.0002 -0.0014 0.0174 -0.0008 -0.0056" size="0.0051" />
                        <body name="L_Ring3" pos="0.0217 -0.0010 -0.0070">
                          <joint name="L_Ring3_x" type="hinge" pos="0 0 0" axis="1 0 0" stiffness="100" damping="10" armature="0.02" range="-20.00 15.88" />
                          <joint name="L_Ring3_y" type="hinge" pos="0 0 0" axis="0 1 0" stiffness="100" damping="10" armature="0.02" range="-14.38 19.35" />
                          <joint name="L_Ring3_z" type="hinge" pos="0 0 0" axis="0 0 1" stiffness="100" damping="10" armature="0.02" range="-75.78 32.31" />
                          <geom type="capsule" contype="1" conaffinity="1" density="1000" fromto="0.0045 -0.0002 -0.0014 0.0172 -0.0008 -0.0055" size="0.0043" />
                        </body>
                      </body>
                    </body>
                    <body name="L_Thumb1" pos="0.0389 -0.0217 0.0253">
                      <joint name="L_Thumb1_x" type="hinge" pos="0 0 0" axis="1 0 0" stiffness="100" damping="10" armature="0.02" range="47.61 118.01" />
                      <joint name="L_Thumb1_y" type="hinge" pos="0 0 0" axis="0 1 0" stiffness="100" damping="10" armature="0.02" range="-41.12 26.03" />
                      <joint name="L_Thumb1_z" type="hinge" pos="0 0 0" axis="0 0 1" stiffness="100" damping="10" armature="0.02" range="-19.20 46.43" />
                      <geom type="capsule" contype="1" conaffinity="1" density="1000" fromto="0.0032 0.0001 0.0047 0.0127 0.0005 0.0187" size="0.0086" />
                      <body name="L_Thumb2" pos="0.0159 0.0006 0.0234">
                        <joint name="L_Thumb2_x" type="hinge" pos="0 0 0" axis="1 0 0" stiffness="100" damping="10" armature="0.02" range="-20.06 17.26" />
                        <joint name="L_Thumb2_y" type="hinge" pos="0 0 0" axis="0 1 0" stiffness="100" damping="10" armature="0.02" range="-12.15 13.06" />
                        <joint name="L_Thumb2_z" type="hinge" pos="0 0 0" axis="0 0 1" stiffness="100" damping="10" armature="0.02" range="-29.30 11.80" />
                        <geom type="capsule" contype="1" conaffinity="1" density="1000" fromto="0.0039 -0.0011 0.0028 0.0154 -0.0045 0.0113" size="0.0065" />
                        <body name="L_Thumb3" pos="0.0193 -0.0056 0.0141">
                          <joint name="L_Thumb3_x" type="hinge" pos="0 0 0" axis="1 0 0" stiffness="100" damping="10" armature="0.02" range="-22.51 18.61" />
                          <joint name="L_Thumb3_y" type="hinge" pos="0 0 0" axis="0 1 0" stiffness="100" damping="10" armature="0.02" range="-13.06 13.86" />
                          <joint name="L_Thumb3_z" type="hinge" pos="0 0 0" axis="0 0 1" stiffness="100" damping="10" armature="0.02" range="-28.36 59.81" />
                          <geom type="capsule" contype="1" conaffinity="1" density="1000" fromto="0.0031 -0.0009 0.0023 0.0162 -0.0047 0.0118" size="0.0062" />
                        </body>
                      </body>
                    </body>
                  </body>
                </body>
              </body>
            </body>
            <body name="R_Thorax" pos="-0.0600 0.1109 -0.0195">
              <joint name="R_Thorax_x" type="hinge" pos="0 0 0" axis="1 0 0" stiffness="500" damping="50" armature="0.02" range="-150.00 150.00" />
              <joint name="R_Thorax_y" type="hinge" pos="0 0 0" axis="0 1 0" stiffness="500" damping="50" armature="0.02" range="-150.00 150.00" />
              <joint name="R_Thorax_z" type="hinge" pos="0 0 0" axis="0 0 1" stiffness="500" damping="50" armature="0.02" range="-150.00 150.00" />
              <geom type="capsule" contype="1" conaffinity="1" density="1000" fromto="-0.0216 0.0101 -0.0045 -0.0862 0.0403 -0.0181" size="0.0576" />
              <body name="R_Shoulder" pos="-0.1078 0.0504 -0.0226">
                <joint name="R_Shoulder_x" type="hinge" pos="0 0 0" axis="1 0 0" stiffness="500" damping="50" armature="0.02" range="-150.00 150.00" />
                <joint name="R_Shoulder_y" type="hinge" pos="0 0 0" axis="0 1 0" stiffness="500" damping="50" armature="0.02" range="-150.00 150.00" />
                <joint name="R_Shoulder_z" type="hinge" pos="0 0 0" axis="0 0 1" stiffness="500" damping="50" armature="0.02" range="-150.00 150.00" />
                <geom type="capsule" contype="1" conaffinity="1" density="1000" fromto="-0.0519 -0.0097 -0.0039 -0.2075 -0.0388 -0.0157" size="0.0538" />
                <body name="R_Elbow" pos="-0.2594 -0.0485 -0.0196">
                  <joint name="R_Elbow_x" type="hinge" pos="0 0 0" axis="1 0 0" stiffness="500" damping="50" armature="0.02" range="-150.00 150.00" />
                  <joint name="R_Elbow_y" type="hinge" pos="0 0 0" axis="0 1 0" stiffness="500" damping="50" armature="0.02" range="-150.00 150.00" />
                  <joint name="R_Elbow_z" type="hinge" pos="0 0 0" axis="0 0 1" stiffness="500" damping="50" armature="0.02" range="-150.00 150.00" />
                  <geom type="capsule" contype="1" conaffinity="1" density="1000" fromto="-0.0442 0.0007 -0.0010 -0.1769 0.0030 -0.0039" size="0.042" />
                  <body name="R_Wrist" pos="-0.2212 0.0037 -0.0048">
                    <joint name="R_Wrist_x" type="hinge" pos="0 0 0" axis="1 0 0" stiffness="300" damping="30" armature="0.02" range="-150.00 150.00" />
                    <joint name="R_Wrist_y" type="hinge" pos="0 0 0" axis="0 1 0" stiffness="300" damping="30" armature="0.02" range="-150.00 150.00" />
                    <joint name="R_Wrist_z" type="hinge" pos="0 0 0" axis="0 0 1" stiffness="300" damping="30" armature="0.02" range="-150.00 150.00" />
                    <geom type="box" contype="1" conaffinity="1" density="1000" pos="-0.0449 -0.0080 -0.0014" size="0.0416 0.0078 0.0414" quat="1.0000 0.0000 0.0000 0.0000" />
                    <body name="R_Index1" pos="-0.0949 -0.0135 0.0206">
                      <joint name="R_Index1_x" type="hinge" pos="0 0 0" axis="1 0 0" stiffness="100" damping="10" armature="0.02" range="-29.86 22.91" />
                      <joint name="R_Index1_y" type="hinge" pos="0 0 0" axis="0 1 0" stiffness="100" damping="10" armature="0.02" range="-45.08 23.07" />
                      <joint name="R_Index1_z" type="hinge" pos="0 0 0" axis="0 0 1" stiffness="100" damping="10" armature="0.02" range="-38.91 93.70" />
                      <geom type="capsule" contype="1" conaffinity="1" density="1000" fromto="-0.0061 0.0006 0.0006 -0.0245 0.0022 0.0023" size="0.0065" />
                      <body name="R_Index2" pos="-0.0307 0.0028 0.0028">
                        <joint name="R_Index2_x" type="hinge" pos="0 0 0" axis="1 0 0" stiffness="100" damping="10" armature="0.02" range="-20.04 16.60" />
                        <joint name="R_Index2_y" type="hinge" pos="0 0 0" axis="0 1 0" stiffness="100" damping="10" armature="0.02" range="-14.16 15.06" />
                        <joint name="R_Index2_z" type="hinge" pos="0 0 0" axis="0 0 1" stiffness="100" damping="10" armature="0.02" range="-10.85 117.32" />
                        <geom type="capsule" contype="1" conaffinity="1" density="1000" fromto="-0.0043 -0.0003 0.0001 -0.0174 -0.0010 0.0006" size="0.0053" />
                        <body name="R_Index3" pos="-0.0217 -0.0013 0.0007">
                          <joint name="R_Index3_x" type="hinge" pos="0 0 0" axis="1 0 0" stiffness="100" damping="10" armature="0.02" range="-20.36 17.03" />
                          <joint name="R_Index3_y" type="hinge" pos="0 0 0" axis="0 1 0" stiffness="100" damping="10" armature="0.02" range="-16.60 21.08" />
                          <joint name="R_Index3_z" type="hinge" pos="0 0 0" axis="0 0 1" stiffness="100" damping="10" armature="0.02" range="-61.66 81.69" />
                          <geom type="capsule" contype="1" conaffinity="1" density="1000" fromto="-0.0049 -0.0003 0.0002 -0.0168 -0.0010 0.0005" size="0.0048" />
                        </body>
                      </body>
                    </body>
                    <body name="R_Middle1" pos="-0.1017 -0.0110 -0.0015">
                      <joint name="R_Middle1_x" type="hinge" pos="0 0 0" axis="1 0 0" stiffness="100" damping="10" armature="0.02" range="-40.71 21.10" />
                      <joint name="R_Middle1_y" type="hinge" pos="0 0 0" axis="0 1 0" stiffness="100" damping="10" armature="0.02" range="-42.50 36.40" />
                      <joint name="R_Middle1_z" type="hinge" pos="0 0 0" axis="0 0 1" stiffness="100" damping="10" armature="0.02" range="-47.31 107.33" />
                      <geom type="capsule" contype="1" conaffinity="1" density="1000" fromto="-0.0058 0.0003 -0.0007 -0.0232 0.0011 -0.0029" size="0.0067" />
                      <body name="R_Middle2" pos="-0.0290 0.0014 -0.0037">
                        <joint name="R_Middle2_x" type="hinge" pos="0 0 0" axis="1 0 0" stiffness="100" damping="10" armature="0.02" range="-17.52 16.49" />
                        <joint name="R_Middle2_y" type="hinge" pos="0 0 0" axis="0 1 0" stiffness="100" damping="10" armature="0.02" range="-15.37 13.21" />
                        <joint name="R_Middle2_z" type="hinge" pos="0 0 0" axis="0 0 1" stiffness="100" damping="10" armature="0.02" range="-11.04 105.37" />
                        <geom type="capsule" contype="1" conaffinity="1" density="1000" fromto="-0.0045 -0.0001 -0.0007 -0.0180 -0.0004 -0.0029" size="0.0050" />
                        <body name="R_Middle3" pos="-0.0225 -0.0005 -0.0036">
                          <joint name="R_Middle3_x" type="hinge" pos="0 0 0" axis="1 0 0" stiffness="100" damping="10" armature="0.02" range="-17.54 18.24" />
                          <joint name="R_Middle3_y" type="hinge" pos="0 0 0" axis="0 1 0" stiffness="100" damping="10" armature="0.02" range="-15.32 13.09" />
                          <joint name="R_Middle3_z" type="hinge" pos="0 0 0" axis="0 0 1" stiffness="100" damping="10" armature="0.02" range="-56.67 67.63" />
                          <geom type="capsule" contype="1" conaffinity="1" density="1000" fromto="-0.0049 -0.0001 -0.0008 -0.0176 -0.0004 -0.0028" size="0.0045" />
                        </body>
                      </body>
                    </body>
                    <body name="R_Pinky1" pos="-0.0773 -0.0185 -0.0396">
                      <joint name="R_Pinky1_x" type="hinge" pos="0 0 0" axis="1 0 0" stiffness="100" damping="10" armature="0.02" range="-64.79 14.50" />
                      <joint name="R_Pinky1_y" type="hinge" pos="0 0 0" axis="0 1 0" stiffness="100" damping="10" armature="0.02" range="-51.84 51.07" />
                      <joint name="R_Pinky1_z" type="hinge" pos="0 0 0" axis="0 0 1" stiffness="100" damping="10" armature="0.02" range="-75.84 95.95" />
                      <geom type="capsule" contype="1" conaffinity="1" density="1000" fromto="-0.0028 -0.0001 -0.0024 -0.0112 -0.0004 -0.0094" size="0.0050" />
                      <body name="R_Pinky2" pos="-0.0140 -0.0004 -0.0118">
                        <joint name="R_Pinky2_x" type="hinge" pos="0 0 0" axis="1 0 0" stiffness="100" damping="10" armature="0.02" range="-21.09 12.11" />
                        <joint name="R_Pinky2_y" type="hinge" pos="0 0 0" axis="0 1 0" stiffness="100" damping="10" armature="0.02" range="-20.62 13.11" />
                        <joint name="R_Pinky2_z" type="hinge" pos="0 0 0" axis="0 0 1" stiffness="100" damping="10" armature="0.02" range="-10.77 120.96" />
                        <geom type="capsule" contype="1" conaffinity="1" density="1000" fromto="-0.0029 -0.0002 -0.0023 -0.0114 -0.0006 -0.0091" size="0.0045" />
                        <body name="R_Pinky3" pos="-0.0143 -0.0008 -0.0114">
                          <joint name="R_Pinky3_x" type="hinge" pos="0 0 0" axis="1 0 0" stiffness="100" damping="10" armature="0.02" range="-21.07 15.06" />
                          <joint name="R_Pinky3_y" type="hinge" pos="0 0 0" axis="0 1 0" stiffness="100" damping="10" armature="0.02" range="-20.35 13.96" />
                          <joint name="R_Pinky3_z" type="hinge" pos="0 0 0" axis="0 0 1" stiffness="100" damping="10" armature="0.02" range="-16.27 79.16" />
                          <geom type="capsule" contype="1" conaffinity="1" density="1000" fromto="-0.0032 -0.0002 -0.0025 -0.0111 -0.0006 -0.0088" size="0.0036" />
                        </body>
                      </body>
                    </body>
                    <body name="R_Ring1" pos="-0.0901 -0.0136 -0.0240">
                      <joint name="R_Ring1_x" type="hinge" pos="0 0 0" axis="1 0 0" stiffness="100" damping="10" armature="0.02" range="-43.68 20.28" />
                      <joint name="R_Ring1_y" type="hinge" pos="0 0 0" axis="0 1 0" stiffness="100" damping="10" armature="0.02" range="-41.27 33.80" />
                      <joint name="R_Ring1_z" type="hinge" pos="0 0 0" axis="0 0 1" stiffness="100" damping="10" armature="0.02" range="-40.07 112.73" />
                      <geom type="capsule" contype="1" conaffinity="1" density="1000" fromto="-0.0053 0.0003 -0.0011 -0.0212 0.0013 -0.0042" size="0.0057" />
                      <body name="R_Ring2" pos="-0.0265 0.0016 -0.0053">
                        <joint name="R_Ring2_x" type="hinge" pos="0 0 0" axis="1 0 0" stiffness="100" damping="10" armature="0.02" range="-18.42 14.08" />
                        <joint name="R_Ring2_y" type="hinge" pos="0 0 0" axis="0 1 0" stiffness="100" damping="10" armature="0.02" range="-16.11 12.81" />
                        <joint name="R_Ring2_z" type="hinge" pos="0 0 0" axis="0 0 1" stiffness="100" damping="10" armature="0.02" range="-11.56 113.77" />
                        <geom type="capsule" contype="1" conaffinity="1" density="1000" fromto="-0.0043 -0.0002 -0.0014 -0.0174 -0.0008 -0.0056" size="0.0051" />
                        <body name="R_Ring3" pos="-0.0217 -0.0010 -0.0070">
                          <joint name="R_Ring3_x" type="hinge" pos="0 0 0" axis="1 0 0" stiffness="100" damping="10" armature="0.02" range="-19.25 12.69" />
                          <joint name="R_Ring3_y" type="hinge" pos="0 0 0" axis="0 1 0" stiffness="100" damping="10" armature="0.02" range="-18.42 13.68" />
                          <joint name="R_Ring3_z" type="hinge" pos="0 0 0" axis="0 0 1" stiffness="100" damping="10" armature="0.02" range="-49.85 75.77" />
                          <geom type="capsule" contype="1" conaffinity="1" density="1000" fromto="-0.0047 -0.0002 -0.0015 -0.0170 -0.0008 -0.0055" size="0.0043" />
                        </body>
                      </body>
                    </body>
                    <body name="R_Thumb1" pos="-0.0379 -0.0209 0.0267">
                      <joint name="R_Thumb1_x" type="hinge" pos="0 0 0" axis="1 0 0" stiffness="100" damping="10" armature="0.02" range="46.78 136.18" />
                      <joint name="R_Thumb1_y" type="hinge" pos="0 0 0" axis="0 1 0" stiffness="100" damping="10" armature="0.02" range="-24.53 37.42" />
                      <joint name="R_Thumb1_z" type="hinge" pos="0 0 0" axis="0 0 1" stiffness="100" damping="10" armature="0.02" range="-59.28 11.67" />
                      <geom type="capsule" contype="1" conaffinity="1" density="1000" fromto="-0.0032 0.0001 0.0047 -0.0127 0.0005 0.0187" size="0.0086" />
                      <body name="R_Thumb2" pos="-0.0159 0.0006 0.0234">
                        <joint name="R_Thumb2_x" type="hinge" pos="0 0 0" axis="1 0 0" stiffness="100" damping="10" armature="0.02" range="-19.71 17.12" />
                        <joint name="R_Thumb2_y" type="hinge" pos="0 0 0" axis="0 1 0" stiffness="100" damping="10" armature="0.02" range="-14.27 13.65" />
                        <joint name="R_Thumb2_z" type="hinge" pos="0 0 0" axis="0 0 1" stiffness="100" damping="10" armature="0.02" range="-9.92 52.34" />
                        <geom type="capsule" contype="1" conaffinity="1" density="1000" fromto="-0.0039 -0.0011 0.0028 -0.0154 -0.0045 0.0113" size="0.0065" />
                        <body name="R_Thumb3" pos="-0.0193 -0.0056 0.0141">
                          <joint name="R_Thumb3_x" type="hinge" pos="0 0 0" axis="1 0 0" stiffness="100" damping="10" armature="0.02" range="-19.40 19.50" />
                          <joint name="R_Thumb3_y" type="hinge" pos="0 0 0" axis="0 1 0" stiffness="100" damping="10" armature="0.02" range="-19.48 11.47" />
                          <joint name="R_Thumb3_z" type="hinge" pos="0 0 0" axis="0 0 1" stiffness="100" damping="10" armature="0.02" range="-58.97 47.49" />
                          <geom type="capsule" contype="1" conaffinity="1" density="1000" fromto="-0.0040 -0.0012 0.0029 -0.0153 -0.0045 0.0112" size="0.0064" />
                        </body>
                      </body>
                    </body>
                  </body>
                </body>
              </body>
            </body>
          </body>
        </body>
      </body>
    </body>
  </worldbody>
  <actuator>
    <motor name="L_Hip_x" joint="L_Hip_x" gear="1" />
    <motor name="L_Hip_y" joint="L_Hip_y" gear="1" />
    <motor name="L_Hip_z" joint="L_Hip_z" gear="1" />
    <motor name="L_Knee_x" joint="L_Knee_x" gear="1" />
    <motor name="L_Knee_y" joint="L_Knee_y" gear="1" />
    <motor name="L_Knee_z" joint="L_Knee_z" gear="1" />
    <motor name="L_Ankle_x" joint="L_Ankle_x" gear="1" />
    <motor name="L_Ankle_y" joint="L_Ankle_y" gear="1" />
    <motor name="L_Ankle_z" joint="L_Ankle_z" gear="1" />
    <motor name="L_Toe_x" joint="L_Toe_x" gear="1" />
    <motor name="L_Toe_y" joint="L_Toe_y" gear="1" />
    <motor name="L_Toe_z" joint="L_Toe_z" gear="1" />
    <motor name="R_Hip_x" joint="R_Hip_x" gear="1" />
    <motor name="R_Hip_y" joint="R_Hip_y" gear="1" />
    <motor name="R_Hip_z" joint="R_Hip_z" gear="1" />
    <motor name="R_Knee_x" joint="R_Knee_x" gear="1" />
    <motor name="R_Knee_y" joint="R_Knee_y" gear="1" />
    <motor name="R_Knee_z" joint="R_Knee_z" gear="1" />
    <motor name="R_Ankle_x" joint="R_Ankle_x" gear="1" />
    <motor name="R_Ankle_y" joint="R_Ankle_y" gear="1" />
    <motor name="R_Ankle_z" joint="R_Ankle_z" gear="1" />
    <motor name="R_Toe_x" joint="R_Toe_x" gear="1" />
    <motor name="R_Toe_y" joint="R_Toe_y" gear="1" />
    <motor name="R_Toe_z" joint="R_Toe_z" gear="1" />
    <motor name="Torso_x" joint="Torso_x" gear="1" />
    <motor name="Torso_y" joint="Torso_y" gear="1" />
    <motor name="Torso_z" joint="Torso_z" gear="1" />
    <motor name="Spine_x" joint="Spine_x" gear="1" />
    <motor name="Spine_y" joint="Spine_y" gear="1" />
    <motor name="Spine_z" joint="Spine_z" gear="1" />
    <motor name="Chest_x" joint="Chest_x" gear="1" />
    <motor name="Chest_y" joint="Chest_y" gear="1" />
    <motor name="Chest_z" joint="Chest_z" gear="1" />
    <motor name="Neck_x" joint="Neck_x" gear="1" />
    <motor name="Neck_y" joint="Neck_y" gear="1" />
    <motor name="Neck_z" joint="Neck_z" gear="1" />
    <motor name="Head_x" joint="Head_x" gear="1" />
    <motor name="Head_y" joint="Head_y" gear="1" />
    <motor name="Head_z" joint="Head_z" gear="1" />
    <motor name="L_Thorax_x" joint="L_Thorax_x" gear="1" />
    <motor name="L_Thorax_y" joint="L_Thorax_y" gear="1" />
    <motor name="L_Thorax_z" joint="L_Thorax_z" gear="1" />
    <motor name="L_Shoulder_x" joint="L_Shoulder_x" gear="1" />
    <motor name="L_Shoulder_y" joint="L_Shoulder_y" gear="1" />
    <motor name="L_Shoulder_z" joint="L_Shoulder_z" gear="1" />
    <motor name="L_Elbow_x" joint="L_Elbow_x" gear="1" />
    <motor name="L_Elbow_y" joint="L_Elbow_y" gear="1" />
    <motor name="L_Elbow_z" joint="L_Elbow_z" gear="1" />
    <motor name="L_Wrist_x" joint="L_Wrist_x" gear="1" />
    <motor name="L_Wrist_y" joint="L_Wrist_y" gear="1" />
    <motor name="L_Wrist_z" joint="L_Wrist_z" gear="1" />
    <motor name="L_Index1_x" joint="L_Index1_x" gear="1" />
    <motor name="L_Index1_y" joint="L_Index1_y" gear="1" />
    <motor name="L_Index1_z" joint="L_Index1_z" gear="1" />
    <motor name="L_Index2_x" joint="L_Index2_x" gear="1" />
    <motor name="L_Index2_y" joint="L_Index2_y" gear="1" />
    <motor name="L_Index2_z" joint="L_Index2_z" gear="1" />
    <motor name="L_Index3_x" joint="L_Index3_x" gear="1" />
    <motor name="L_Index3_y" joint="L_Index3_y" gear="1" />
    <motor name="L_Index3_z" joint="L_Index3_z" gear="1" />
    <motor name="L_Middle1_x" joint="L_Middle1_x" gear="1" />
    <motor name="L_Middle1_y" joint="L_Middle1_y" gear="1" />
    <motor name="L_Middle1_z" joint="L_Middle1_z" gear="1" />
    <motor name="L_Middle2_x" joint="L_Middle2_x" gear="1" />
    <motor name="L_Middle2_y" joint="L_Middle2_y" gear="1" />
    <motor name="L_Middle2_z" joint="L_Middle2_z" gear="1" />
    <motor name="L_Middle3_x" joint="L_Middle3_x" gear="1" />
    <motor name="L_Middle3_y" joint="L_Middle3_y" gear="1" />
    <motor name="L_Middle3_z" joint="L_Middle3_z" gear="1" />
    <motor name="L_Pinky1_x" joint="L_Pinky1_x" gear="1" />
    <motor name="L_Pinky1_y" joint="L_Pinky1_y" gear="1" />
    <motor name="L_Pinky1_z" joint="L_Pinky1_z" gear="1" />
    <motor name="L_Pinky2_x" joint="L_Pinky2_x" gear="1" />
    <motor name="L_Pinky2_y" joint="L_Pinky2_y" gear="1" />
    <motor name="L_Pinky2_z" joint="L_Pinky2_z" gear="1" />
    <motor name="L_Pinky3_x" joint="L_Pinky3_x" gear="1" />
    <motor name="L_Pinky3_y" joint="L_Pinky3_y" gear="1" />
    <motor name="L_Pinky3_z" joint="L_Pinky3_z" gear="1" />
    <motor name="L_Ring1_x" joint="L_Ring1_x" gear="1" />
    <motor name="L_Ring1_y" joint="L_Ring1_y" gear="1" />
    <motor name="L_Ring1_z" joint="L_Ring1_z" gear="1" />
    <motor name="L_Ring2_x" joint="L_Ring2_x" gear="1" />
    <motor name="L_Ring2_y" joint="L_Ring2_y" gear="1" />
    <motor name="L_Ring2_z" joint="L_Ring2_z" gear="1" />
    <motor name="L_Ring3_x" joint="L_Ring3_x" gear="1" />
    <motor name="L_Ring3_y" joint="L_Ring3_y" gear="1" />
    <motor name="L_Ring3_z" joint="L_Ring3_z" gear="1" />
    <motor name="L_Thumb1_x" joint="L_Thumb1_x" gear="1" />
    <motor name="L_Thumb1_y" joint="L_Thumb1_y" gear="1" />
    <motor name="L_Thumb1_z" joint="L_Thumb1_z" gear="1" />
    <motor name="L_Thumb2_x" joint="L_Thumb2_x" gear="1" />
    <motor name="L_Thumb2_y" joint="L_Thumb2_y" gear="1" />
    <motor name="L_Thumb2_z" joint="L_Thumb2_z" gear="1" />
    <motor name="L_Thumb3_x" joint="L_Thumb3_x" gear="1" />
    <motor name="L_Thumb3_y" joint="L_Thumb3_y" gear="1" />
    <motor name="L_Thumb3_z" joint="L_Thumb3_z" gear="1" />
    <motor name="R_Thorax_x" joint="R_Thorax_x" gear="1" />
    <motor name="R_Thorax_y" joint="R_Thorax_y" gear="1" />
    <motor name="R_Thorax_z" joint="R_Thorax_z" gear="1" />
    <motor name="R_Shoulder_x" joint="R_Shoulder_x" gear="1" />
    <motor name="R_Shoulder_y" joint="R_Shoulder_y" gear="1" />
    <motor name="R_Shoulder_z" joint="R_Shoulder_z" gear="1" />
    <motor name="R_Elbow_x" joint="R_Elbow_x" gear="1" />
    <motor name="R_Elbow_y" joint="R_Elbow_y" gear="1" />
    <motor name="R_Elbow_z" joint="R_Elbow_z" gear="1" />
    <motor name="R_Wrist_x" joint="R_Wrist_x" gear="1" />
    <motor name="R_Wrist_y" joint="R_Wrist_y" gear="1" />
    <motor name="R_Wrist_z" joint="R_Wrist_z" gear="1" />
    <motor name="R_Index1_x" joint="R_Index1_x" gear="1" />
    <motor name="R_Index1_y" joint="R_Index1_y" gear="1" />
    <motor name="R_Index1_z" joint="R_Index1_z" gear="1" />
    <motor name="R_Index2_x" joint="R_Index2_x" gear="1" />
    <motor name="R_Index2_y" joint="R_Index2_y" gear="1" />
    <motor name="R_Index2_z" joint="R_Index2_z" gear="1" />
    <motor name="R_Index3_x" joint="R_Index3_x" gear="1" />
    <motor name="R_Index3_y" joint="R_Index3_y" gear="1" />
    <motor name="R_Index3_z" joint="R_Index3_z" gear="1" />
    <motor name="R_Middle1_x" joint="R_Middle1_x" gear="1" />
    <motor name="R_Middle1_y" joint="R_Middle1_y" gear="1" />
    <motor name="R_Middle1_z" joint="R_Middle1_z" gear="1" />
    <motor name="R_Middle2_x" joint="R_Middle2_x" gear="1" />
    <motor name="R_Middle2_y" joint="R_Middle2_y" gear="1" />
    <motor name="R_Middle2_z" joint="R_Middle2_z" gear="1" />
    <motor name="R_Middle3_x" joint="R_Middle3_x" gear="1" />
    <motor name="R_Middle3_y" joint="R_Middle3_y" gear="1" />
    <motor name="R_Middle3_z" joint="R_Middle3_z" gear="1" />
    <motor name="R_Pinky1_x" joint="R_Pinky1_x" gear="1" />
    <motor name="R_Pinky1_y" joint="R_Pinky1_y" gear="1" />
    <motor name="R_Pinky1_z" joint="R_Pinky1_z" gear="1" />
    <motor name="R_Pinky2_x" joint="R_Pinky2_x" gear="1" />
    <motor name="R_Pinky2_y" joint="R_Pinky2_y" gear="1" />
    <motor name="R_Pinky2_z" joint="R_Pinky2_z" gear="1" />
    <motor name="R_Pinky3_x" joint="R_Pinky3_x" gear="1" />
    <motor name="R_Pinky3_y" joint="R_Pinky3_y" gear="1" />
    <motor name="R_Pinky3_z" joint="R_Pinky3_z" gear="1" />
    <motor name="R_Ring1_x" joint="R_Ring1_x" gear="1" />
    <motor name="R_Ring1_y" joint="R_Ring1_y" gear="1" />
    <motor name="R_Ring1_z" joint="R_Ring1_z" gear="1" />
    <motor name="R_Ring2_x" joint="R_Ring2_x" gear="1" />
    <motor name="R_Ring2_y" joint="R_Ring2_y" gear="1" />
    <motor name="R_Ring2_z" joint="R_Ring2_z" gear="1" />
    <motor name="R_Ring3_x" joint="R_Ring3_x" gear="1" />
    <motor name="R_Ring3_y" joint="R_Ring3_y" gear="1" />
    <motor name="R_Ring3_z" joint="R_Ring3_z" gear="1" />
    <motor name="R_Thumb1_x" joint="R_Thumb1_x" gear="1" />
    <motor name="R_Thumb1_y" joint="R_Thumb1_y" gear="1" />
    <motor name="R_Thumb1_z" joint="R_Thumb1_z" gear="1" />
    <motor name="R_Thumb2_x" joint="R_Thumb2_x" gear="1" />
    <motor name="R_Thumb2_y" joint="R_Thumb2_y" gear="1" />
    <motor name="R_Thumb2_z" joint="R_Thumb2_z" gear="1" />
    <motor name="R_Thumb3_x" joint="R_Thumb3_x" gear="1" />
    <motor name="R_Thumb3_y" joint="R_Thumb3_y" gear="1" />
    <motor name="R_Thumb3_z" joint="R_Thumb3_z" gear="1" />
  </actuator>
  <contact />
  <sensor />
  <size njmax="700" nconmax="700" />
</mujoco>
